Workbook

Sheet nodes_lng_europe_2020
A1: LNG | B1: To | C1: LNG Capacity Mrd m3 [2020] | D1: Imports [2020] | E1: Share [2020] | F1: Capacity after grid connection [2020] | G1: Limitation | H1: GWh/a | I1: Limitation in TWh | N1: From | O1: To
A2: Belgium | B2: BE | C2: 11.4 | D2: 5.1 | E2: =D2/C2 -> 0.44736842 | F2: 9 | G2: =IF(C2>F2,F2,C2) -> 9 | H2: =I2*1000 -> 87930 | I2: =G2*9.77 -> 87.93 | K2: BE | L2: _LNG | N2: =_xlfn.CONCAT(K2,L2) -> BE_LNG | O2: =K2 -> BE
A3: France | B3: FR | C3: 33 | D3: 19.6 | E3: =D3/C3 -> 0.59393939 | F3: 33 | G3: =IF(C3>F3,F3,C3) -> 33 | H3: =I3*1000 -> 322410 | I3: =G3*9.77 -> 322.41 | K3: FR | L3: _LNG | N3: =_xlfn.CONCAT(K3,L3) -> FR_LNG | O3: =K3 -> FR
A4: Greece | B4: EL | C4: 7 | D4: 2.5 | E4: =D4/C4 -> 0.35714286 | F4: 7.5 | G4: =IF(C4>F4,F4,C4) -> 7 | H4: =I4*1000 -> 68390 | I4: =G4*9.77 -> 68.39 | K4: EL | L4: _LNG | N4: =_xlfn.CONCAT(K4,L4) -> EL_LNG | O4: =K4 -> EL
A5: Italy | B5: IT | C5: 15.95 | D5: 12.1 | E5: =D5/C5 -> 0.75862069 | F5: 15.8 | G5: =IF(C5>F5,F5,C5) -> 15.8 | H5: =I5*1000 -> 154366 | I5: =G5*9.77 -> 154.366 | K5: IT | L5: _LNG | N5: =_xlfn.CONCAT(K5,L5) -> IT_LNG | O5: =K5 -> IT
A6: Croatia | B6: HR | C6: 2.6 | D6: 0.4 | E6: =D6/C6 -> 0.15384615 | F6: 2.6 | G6: =IF(C6>F6,F6,C6) -> 2.6 | H6: =I6*1000 -> 25402 | I6: =G6*9.77 -> 25.402 | K6: HR | L6: _LNG | N6: =_xlfn.CONCAT(K6,L6) -> HR_LNG | O6: =K6 -> HR
A7: Lithuania | B7: LT | C7: 4 | D7: 1.6 | E7: =D7/C7 -> 0.4 | F7: 4 | G7: =IF(C7>F7,F7,C7) -> 4 | H7: =I7*1000 -> 39080 | I7: =G7*9.77 -> 39.08 | K7: LT | L7: _LNG | N7: =_xlfn.CONCAT(K7,L7) -> LT_LNG | O7: =K7 -> LT
A8: Netherlands | B8: NL | C8: 12 | D8: 8.2 | E8: =D8/C8 -> 0.68333333 | F8: 12.5 | G8: =IF(C8>F8,F8,C8) -> 12 | H8: =I8*1000 -> 117240 | I8: =G8*9.77 -> 117.24 | K8: NL | L8: _LNG | N8: =_xlfn.CONCAT(K8,L8) -> NL_LNG | O8: =K8 -> NL
A9: Poland | B9: PL | C9: 6.2 | D9: 4.1 | E9: =D9/C9 -> 0.66129032 | F9: 5.8 | G9: =IF(C9>F9,F9,C9) -> 5.8 | H9: =I9*1000 -> 56666 | I9: =G9*9.77 -> 56.666 | K9: PL | L9: _LNG | N9: =_xlfn.CONCAT(K9,L9) -> PL_LNG | O9: =K9 -> PL
A10: Portugal | B10: PT | C10: 7.6 | D10: 6.1 | E10: =D10/C10 -> 0.80263158 | F10: 7.3 | G10: =IF(C10>F10,F10,C10) -> 7.3 | H10: =I10*1000 -> 71321 | I10: =G10*9.77 -> 71.321 | K10: PT | L10: _LNG | N10: =_xlfn.CONCAT(K10,L10) -> PT_LNG | O10: =K10 -> PT
A11: Spain | B11: ES | C11: 60.1 | D11: 20.9 | E11: =D11/C11 -> 0.34775374 | F11: 67.1 | G11: =IF(C11>F11,F11,C11) -> 60.1 | H11: =I11*1000 -> 587177 | I11: =G11*9.77 -> 587.177 | K11: ES | L11: _LNG | N11: =_xlfn.CONCAT(K11,L11) -> ES_LNG | O11: =K11 -> ES
A12: Türkiye | B12: TR | C12: 43.6 | D12: 14.8 | E12: =D12/C12 -> 0.33944954 | F12: 43.6 | G12: =IF(C12>F12,F12,C12) -> 43.6 | H12: =I12*1000 -> 425972 | I12: =G12*9.77 -> 425.972 | K12: TR | L12: _LNG | N12: =_xlfn.CONCAT(K12,L12) -> TR_LNG | O12: =K12 -> TR
A13: UK | B13: UK | C13: 48.1 | D13: 18.6 | E13: =D13/C13 -> 0.38669439 | F13: 52.3 | G13: =IF(C13>F13,F13,C13) -> 48.1 | H13: =I13*1000 -> 469937 | I13: =G13*9.77 -> 469.937 | K13: UK | L13: _LNG | N13: =_xlfn.CONCAT(K13,L13) -> UK_LNG | O13: =K13 -> UK
A14: Malta | B14: - | C14: 0.7 | E14: =D14/C14 -> 0 | F14: 0.7 | G14: =IF(C14>F14,F14,C14) -> 0.7 | H14: =I14*1000 -> 6839 | I14: =G14*9.77 -> 6.839 | K14: -

Sheet nodes_lng_europe_2024
A1: LNG | B1: To | C1: LNG Capacity Mrd m3 [2020] | D1: Imports [2020] | E1: Share [2020] | F1: Capacity after grid connection [2020] | G1: Limitation | H1: GWh/a | I1: Limitation in TWh | N1: From | O1: To
A2: Belgium | B2: BE | C2: 15.3 | D2: 5.1 | E2: =D2/C2 -> 0.33333333 | F2: =C2 -> 15.3 | G2: =IF(C2>F2,F2,C2) -> 15.3 | H2: =I2*1000 -> 149481 | I2: =G2*9.77 -> 149.481 | K2: BE | L2: _LNG | N2: =_xlfn.CONCAT(K2,L2) -> BE_LNG | O2: =K2 -> BE
A3: France | B3: FR | C3: 39.5 | D3: 19.6 | E3: =D3/C3 -> 0.49620253 | F3: =C3 -> 39.5 | G3: =IF(C3>F3,F3,C3) -> 39.5 | H3: =I3*1000 -> 385915 | I3: =G3*9.77 -> 385.915 | K3: FR | L3: _LNG | N3: =_xlfn.CONCAT(K3,L3) -> FR_LNG | O3: =K3 -> FR
A4: Greece | B4: EL | C4: 12.5 | D4: 2.5 | E4: =D4/C4 -> 0.2 | F4: =C4 -> 12.5 | G4: =IF(C4>F4,F4,C4) -> 12.5 | H4: =I4*1000 -> 122125 | I4: =G4*9.77 -> 122.125 | K4: EL | L4: _LNG | N4: =_xlfn.CONCAT(K4,L4) -> EL_LNG | O4: =K4 -> EL
A5: Italy | B5: IT | C5: 25.95 | D5: 12.1 | E5: =D5/C5 -> 0.46628131 | F5: =C5 -> 25.95 | G5: =IF(C5>F5,F5,C5) -> 25.95 | H5: =I5*1000 -> 253531.5 | I5: =G5*9.77 -> 253.5315 | K5: IT | L5: _LNG | N5: =_xlfn.CONCAT(K5,L5) -> IT_LNG | O5: =K5 -> IT
A6: Croatia | B6: HR | C6: 2.6 | D6: 0.4 | E6: =D6/C6 -> 0.15384615 | F6: =C6 -> 2.6 | G6: =IF(C6>F6,F6,C6) -> 2.6 | H6: =I6*1000 -> 25402 | I6: =G6*9.77 -> 25.402 | K6: HR | L6: _LNG | N6: =_xlfn.CONCAT(K6,L6) -> HR_LNG | O6: =K6 -> HR
A7: Lithuania | B7: LT | C7: 4 | D7: 1.6 | E7: =D7/C7 -> 0.4 | F7: =C7 -> 4 | G7: =IF(C7>F7,F7,C7) -> 4 | H7: =I7*1000 -> 39080 | I7: =G7*9.77 -> 39.08 | K7: LT | L7: _LNG | N7: =_xlfn.CONCAT(K7,L7) -> LT_LNG | O7: =K7 -> LT
A8: Netherlands | B8: NL | C8: 24 | D8: 8.2 | E8: =D8/C8 -> 0.34166667 | F8: =C8 -> 24 | G8: =IF(C8>F8,F8,C8) -> 24 | H8: =I8*1000 -> 234480 | I8: =G8*9.77 -> 234.48 | K8: NL | L8: _LNG | N8: =_xlfn.CONCAT(K8,L8) -> NL_LNG | O8: =K8 -> NL
A9: Poland | B9: PL | C9: 8.3 | D9: 4.1 | E9: =D9/C9 -> 0.4939759 | F9: =C9 -> 8.3 | G9: =IF(C9>F9,F9,C9) -> 8.3 | H9: =I9*1000 -> 81091 | I9: =G9*9.77 -> 81.091 | K9: PL | L9: _LNG | N9: =_xlfn.CONCAT(K9,L9) -> PL_LNG | O9: =K9 -> PL
A10: Portugal | B10: PT | C10: 7.6 | D10: 6.1 | E10: =D10/C10 -> 0.80263158 | F10: =C10 -> 7.6 | G10: =IF(C10>F10,F10,C10) -> 7.6 | H10: =I10*1000 -> 74252 | I10: =G10*9.77 -> 74.252 | K10: PT | L10: _LNG | N10: =_xlfn.CONCAT(K10,L10) -> PT_LNG | O10: =K10 -> PT
A11: Spain | B11: ES | C11: 67.1 | D11: 20.9 | E11: =D11/C11 -> 0.31147541 | F11: =C11 -> 67.1 | G11: =IF(C11>F11,F11,C11) -> 67.1 | H11: =I11*1000 -> 655567 | I11: =G11*9.77 -> 655.567 | K11: ES | L11: _LNG | N11: =_xlfn.CONCAT(K11,L11) -> ES_LNG | O11: =K11 -> ES
A12: Türkiye | B12: TR | C12: 51.22 | D12: 14.8 | E12: =D12/C12 -> 0.28894963 | F12: =C12 -> 51.22 | G12: =IF(C12>F12,F12,C12) -> 51.22 | H12: =I12*1000 -> 500419.4 | I12: =G12*9.77 -> 500.4194 | K12: TR | L12: _LNG | N12: =_xlfn.CONCAT(K12,L12) -> TR_LNG | O12: =K12 -> TR
A13: UK | B13: UK | C13: 48.1 | D13: 18.6 | E13: =D13/C13 -> 0.38669439 | F13: =C13 -> 48.1 | G13: =IF(C13>F13,F13,C13) -> 48.1 | H13: =I13*1000 -> 469937 | I13: =G13*9.77 -> 469.937 | K13: UK | L13: _LNG | N13: =_xlfn.CONCAT(K13,L13) -> UK_LNG | O13: =K13 -> UK
A14: Estonia Planned | B14: EE | C14: 0 | E14: =D14/C14 -> #DIV/0! | F14: =C14 -> 0 | G14: =IF(C14>F14,F14,C14) -> 0 | H14: =I14*1000 -> 0 | I14: =G14*9.77 -> 0 | K14: EE | L14: _LNG | N14: =_xlfn.CONCAT(K14,L14) -> EE_LNG | O14: =K14 -> EE
A15: Finland Planned | B15: FI | C15: 4.5 | E15: =D15/C15 -> 0 | F15: =C15 -> 4.5 | G15: =IF(C15>F15,F15,C15) -> 4.5 | H15: =I15*1000 -> 43965 | I15: =G15*9.77 -> 43.965 | K15: FI | L15: _LNG | N15: =_xlfn.CONCAT(K15,L15) -> FI_LNG | O15: =K15 -> FI
A16: Germany Planned | B16: DE | C16: 18.81 | E16: =D16/C16 -> 0 | F16: =C16 -> 18.81 | G16: =IF(C16>F16,F16,C16) -> 18.81 | H16: =I16*1000 -> 183773.7 | I16: =G16*9.77 -> 183.7737 | K16: DE | L16: _LNG | N16: =_xlfn.CONCAT(K16,L16) -> DE_LNG | O16: =K16 -> DE
A17: Ireland Planned | B17: IE | C17: 0 | E17: =D17/C17 -> #DIV/0! | F17: =C17 -> 0 | G17: =IF(C17>F17,F17,C17) -> 0 | H17: =I17*1000 -> 0 | I17: =G17*9.77 -> 0 | K17: IE | L17: _LNG | N17: =_xlfn.CONCAT(K17,L17) -> IE_LNG | O17: =K17 -> IE
A18: Latvia Planned | B18: LV | C18: 1.5 | E18: =D18/C18 -> 0 | F18: =C18 -> 1.5 | G18: =IF(C18>F18,F18,C18) -> 1.5 | H18: =I18*1000 -> 14655 | I18: =G18*9.77 -> 14.655 | K18: LV | L18: _LNG | N18: =_xlfn.CONCAT(K18,L18) -> LV_LNG | O18: =K18 -> LV
A19: Malta | B19: - | C19: 0.7 | E19: =D19/C19 -> 0 | F19: =C19 -> 0.7 | G19: =IF(C19>F19,F19,C19) -> 0.7 | H19: =I19*1000 -> 6839 | I19: =G19*9.77 -> 6.839 | K19: -

Sheet nodes_lng_europe_2035
A1: LNG | B1: To | C1: LNG Capacity Mrd m3 [2020] | D1: Imports [2020] | E1: Share [2020] | F1: Capacity after grid connection [2020] | G1: Limitation | H1: GWh/a | I1: Limitation in TWh | N1: From | O1: To
A2: Belgium | B2: BE | C2: 15.3 | D2: 5.1 | E2: =D2/C2 -> 0.33333333 | F2: =C2 -> 15.3 | G2: =IF(C2>F2,F2,C2) -> 15.3 | H2: =I2*1000 -> 149481 | I2: =G2*9.77 -> 149.481 | K2: BE | L2: _LNG | N2: =_xlfn.CONCAT(K2,L2) -> BE_LNG | O2: =K2 -> BE
A3: France | B3: FR | C3: 41.5 | D3: 19.6 | E3: =D3/C3 -> 0.47228916 | F3: =C3 -> 41.5 | G3: =IF(C3>F3,F3,C3) -> 41.5 | H3: =I3*1000 -> 405455 | I3: =G3*9.77 -> 405.455 | K3: FR | L3: _LNG | N3: =_xlfn.CONCAT(K3,L3) -> FR_LNG | O3: =K3 -> FR
A4: Greece | B4: EL | C4: 22.52 | D4: 2.5 | E4: =D4/C4 -> 0.11101243 | F4: =C4 -> 22.52 | G4: =IF(C4>F4,F4,C4) -> 22.52 | H4: =I4*1000 -> 220020.4 | I4: =G4*9.77 -> 220.0204 | K4: EL | L4: _LNG | N4: =_xlfn.CONCAT(K4,L4) -> EL_LNG | O4: =K4 -> EL
A5: Italy | B5: IT | C5: 25.95 | D5: 12.1 | E5: =D5/C5 -> 0.46628131 | F5: =C5 -> 25.95 | G5: =IF(C5>F5,F5,C5) -> 25.95 | H5: =I5*1000 -> 253531.5 | I5: =G5*9.77 -> 253.5315 | K5: IT | L5: _LNG | N5: =_xlfn.CONCAT(K5,L5) -> IT_LNG | O5: =K5 -> IT
A6: Croatia | B6: HR | C6: 5.2 | D6: 0.4 | E6: =D6/C6 -> 0.076923077 | F6: =C6 -> 5.2 | G6: =IF(C6>F6,F6,C6) -> 5.2 | H6: =I6*1000 -> 50804 | I6: =G6*9.77 -> 50.804 | K6: HR | L6: _LNG | N6: =_xlfn.CONCAT(K6,L6) -> HR_LNG | O6: =K6 -> HR
A7: Lithuania | B7: LT | C7: 4 | D7: 1.6 | E7: =D7/C7 -> 0.4 | F7: =C7 -> 4 | G7: =IF(C7>F7,F7,C7) -> 4 | H7: =I7*1000 -> 39080 | I7: =G7*9.77 -> 39.08 | K7: LT | L7: _LNG | N7: =_xlfn.CONCAT(K7,L7) -> LT_LNG | O7: =K7 -> LT
A8: Netherlands | B8: NL | C8: 28 | D8: 8.2 | E8: =D8/C8 -> 0.29285714 | F8: =C8 -> 28 | G8: =IF(C8>F8,F8,C8) -> 28 | H8: =I8*1000 -> 273560 | I8: =G8*9.77 -> 273.56 | K8: NL | L8: _LNG | N8: =_xlfn.CONCAT(K8,L8) -> NL_LNG | O8: =K8 -> NL
A9: Poland | B9: PL | C9: 14.4 | D9: 4.1 | E9: =D9/C9 -> 0.28472222 | F9: =C9 -> 14.4 | G9: =IF(C9>F9,F9,C9) -> 14.4 | H9: =I9*1000 -> 140688 | I9: =G9*9.77 -> 140.688 | K9: PL | L9: _LNG | N9: =_xlfn.CONCAT(K9,L9) -> PL_LNG | O9: =K9 -> PL
A10: Portugal | B10: PT | C10: 7.6 | D10: 6.1 | E10: =D10/C10 -> 0.80263158 | F10: =C10 -> 7.6 | G10: =IF(C10>F10,F10,C10) -> 7.6 | H10: =I10*1000 -> 74252 | I10: =G10*9.77 -> 74.252 | K10: PT | L10: _LNG | N10: =_xlfn.CONCAT(K10,L10) -> PT_LNG | O10: =K10 -> PT
A11: Spain | B11: ES | C11: 67.1 | D11: 20.9 | E11: =D11/C11 -> 0.31147541 | F11: =C11 -> 67.1 | G11: =IF(C11>F11,F11,C11) -> 67.1 | H11: =I11*1000 -> 655567 | I11: =G11*9.77 -> 655.567 | K11: ES | L11: _LNG | N11: =_xlfn.CONCAT(K11,L11) -> ES_LNG | O11: =K11 -> ES
A12: Türkiye | B12: TR | C12: 51.22 | D12: 14.8 | E12: =D12/C12 -> 0.28894963 | F12: =C12 -> 51.22 | G12: =IF(C12>F12,F12,C12) -> 51.22 | H12: =I12*1000 -> 500419.4 | I12: =G12*9.77 -> 500.4194 | K12: TR | L12: _LNG | N12: =_xlfn.CONCAT(K12,L12) -> TR_LNG | O12: =K12 -> TR
A13: UK | B13: UK | C13: 48.1 | D13: 18.6 | E13: =D13/C13 -> 0.38669439 | F13: =C13 -> 48.1 | G13: =IF(C13>F13,F13,C13) -> 48.1 | H13: =I13*1000 -> 469937 | I13: =G13*9.77 -> 469.937 | K13: UK | L13: _LNG | N13: =_xlfn.CONCAT(K13,L13) -> UK_LNG | O13: =K13 -> UK
A14: Estonia Planned | B14: EE | C14: 2.5 | E14: =D14/C14 -> 0 | F14: =C14 -> 2.5 | G14: =IF(C14>F14,F14,C14) -> 2.5 | H14: =I14*1000 -> 24425 | I14: =G14*9.77 -> 24.425 | K14: EE | L14: _LNG | N14: =_xlfn.CONCAT(K14,L14) -> EE_LNG | O14: =K14 -> EE
A15: Finland Planned | B15: FI | C15: 4.5 | E15: =D15/C15 -> 0 | F15: =C15 -> 4.5 | G15: =IF(C15>F15,F15,C15) -> 4.5 | H15: =I15*1000 -> 43965 | I15: =G15*9.77 -> 43.965 | K15: FI | L15: _LNG | N15: =_xlfn.CONCAT(K15,L15) -> FI_LNG | O15: =K15 -> FI
A16: Germany Planned | B16: DE | C16: 37.45 | E16: =D16/C16 -> 0 | F16: =C16 -> 37.45 | G16: =IF(C16>F16,F16,C16) -> 37.45 | H16: =I16*1000 -> 365886.5 | I16: =G16*9.77 -> 365.8865 | K16: DE | L16: _LNG | N16: =_xlfn.CONCAT(K16,L16) -> DE_LNG | O16: =K16 -> DE
A17: Ireland Planned | B17: IE | C17: 2.6 | E17: =D17/C17 -> 0 | F17: =C17 -> 2.6 | G17: =IF(C17>F17,F17,C17) -> 2.6 | H17: =I17*1000 -> 25402 | I17: =G17*9.77 -> 25.402 | K17: IE | L17: _LNG | N17: =_xlfn.CONCAT(K17,L17) -> IE_LNG | O17: =K17 -> IE
A18: Latvia Planned | B18: LV | C18: 1.5 | E18: =D18/C18 -> 0 | F18: =C18 -> 1.5 | G18: =IF(C18>F18,F18,C18) -> 1.5 | H18: =I18*1000 -> 14655 | I18: =G18*9.77 -> 14.655 | K18: LV | L18: _LNG | N18: =_xlfn.CONCAT(K18,L18) -> LV_LNG | O18: =K18 -> LV
A19: Malta | B19: - | C19: 0.7 | E19: =D19/C19 -> 0 | F19: =C19 -> 0.7 | G19: =IF(C19>F19,F19,C19) -> 0.7 | H19: =I19*1000 -> 6839 | I19: =G19*9.77 -> 6.839 | K19: -

Sheet nodes_gas_prod_europe_2020
A1: Country | B1: Long_name | C1: Mrd m3 [2020] | D1: Mil m3 EU [2020] | E1: Mrd m3 EU [2020] | F1: GWh [2020] | G1: TWh [2020]2 | M1: From | N1: To
A2: AL | B2: Albania | D2: 56.895 | E2: =Table2[[#This Row],[Mil m3 EU '[2020']]]/1000 -> 0.056895 | F2: =Table2[[#This Row],[TWh '[2020']2]]*1000 -> 555.86415 | G2: =IF(Table2[[#This Row],[Mil m3 EU '[2020']]]>0,Table2[[#This Row],[Mrd m3 EU '[2020']]],Table2[[#This Row],[Mrd m3 '[2020']]])*9.77 -> 0.55586415 | J2: _Prod | M2: =_xlfn.CONCAT(A2,$J$2) -> AL_Prod | N2: =Table2[[#This Row],[Country]] -> AL
A3: DZ | B3: Algeria | C3: 81.424612 | E3: =Table2[[#This Row],[Mil m3 EU '[2020']]]/1000 -> 0 | F3: =Table2[[#This Row],[TWh '[2020']2]]*1000 -> 795518.46 | G3: =IF(Table2[[#This Row],[Mil m3 EU '[2020']]]>0,Table2[[#This Row],[Mrd m3 EU '[2020']]],Table2[[#This Row],[Mrd m3 '[2020']]])*9.77 -> 795.51846 | M3: =_xlfn.CONCAT(A3,$J$2) -> DZ_Prod | N3: =Table2[[#This Row],[Country]] -> DZ
A4: AT | B4: Austria | D4: 773.976 | E4: =Table2[[#This Row],[Mil m3 EU '[2020']]]/1000 -> 0.773976 | F4: =Table2[[#This Row],[TWh '[2020']2]]*1000 -> 7561.7455 | G4: =IF(Table2[[#This Row],[Mil m3 EU '[2020']]]>0,Table2[[#This Row],[Mrd m3 EU '[2020']]],Table2[[#This Row],[Mrd m3 '[2020']]])*9.77 -> 7.5617455 | M4: =_xlfn.CONCAT(A4,$J$2) -> AT_Prod | N4: =Table2[[#This Row],[Country]] -> AT
A5: BY | B5: Belarus | E5: =Table2[[#This Row],[Mil m3 EU '[2020']]]/1000 -> 0 | F5: =Table2[[#This Row],[TWh '[2020']2]]*1000 -> 0 | G5: =IF(Table2[[#This Row],[Mil m3 EU '[2020']]]>0,Table2[[#This Row],[Mrd m3 EU '[2020']]],Table2[[#This Row],[Mrd m3 '[2020']]])*9.77 -> 0 | M5: =_xlfn.CONCAT(A5,$J$2) -> BY_Prod | N5: =Table2[[#This Row],[Country]] -> BY
A6: BE | B6: Belgium | D6: 5.9 | E6: =Table2[[#This Row],[Mil m3 EU '[2020']]]/1000 -> 0.0059 | F6: =Table2[[#This Row],[TWh '[2020']2]]*1000 -> 57.643 | G6: =IF(Table2[[#This Row],[Mil m3 EU '[2020']]]>0,Table2[[#This Row],[Mrd m3 EU '[2020']]],Table2[[#This Row],[Mrd m3 '[2020']]])*9.77 -> 0.057643 | M6: =_xlfn.CONCAT(A6,$J$2) -> BE_Prod | N6: =Table2[[#This Row],[Country]] -> BE
A7: BA | B7: Bosnia and Herzegovina | E7: =Table2[[#This Row],[Mil m3 EU '[2020']]]/1000 -> 0 | F7: =Table2[[#This Row],[TWh '[2020']2]]*1000 -> 0 | G7: =IF(Table2[[#This Row],[Mil m3 EU '[2020']]]>0,Table2[[#This Row],[Mrd m3 EU '[2020']]],Table2[[#This Row],[Mrd m3 '[2020']]])*9.77 -> 0 | M7: =_xlfn.CONCAT(A7,$J$2) -> BA_Prod | N7: =Table2[[#This Row],[Country]] -> BA
A8: BG | B8: Bulgaria | D8: 54.351 | E8: =Table2[[#This Row],[Mil m3 EU '[2020']]]/1000 -> 0.054351 | F8: =Table2[[#This Row],[TWh '[2020']2]]*1000 -> 531.00927 | G8: =IF(Table2[[#This Row],[Mil m3 EU '[2020']]]>0,Table2[[#This Row],[Mrd m3 EU '[2020']]],Table2[[#This Row],[Mrd m3 '[2020']]])*9.77 -> 0.53100927 | M8: =_xlfn.CONCAT(A8,$J$2) -> BG_Prod | N8: =Table2[[#This Row],[Country]] -> BG
A9: HR | B9: Croatia | D9: 888.385 | E9: =Table2[[#This Row],[Mil m3 EU '[2020']]]/1000 -> 0.888385 | F9: =Table2[[#This Row],[TWh '[2020']2]]*1000 -> 8679.5215 | G9: =IF(Table2[[#This Row],[Mil m3 EU '[2020']]]>0,Table2[[#This Row],[Mrd m3 EU '[2020']]],Table2[[#This Row],[Mrd m3 '[2020']]])*9.77 -> 8.6795214 | M9: =_xlfn.CONCAT(A9,$J$2) -> HR_Prod | N9: =Table2[[#This Row],[Country]] -> HR
A10: CZ | B10: Czech Republic | D10: 196.075 | E10: =Table2[[#This Row],[Mil m3 EU '[2020']]]/1000 -> 0.196075 | F10: =Table2[[#This Row],[TWh '[2020']2]]*1000 -> 1915.6528 | G10: =IF(Table2[[#This Row],[Mil m3 EU '[2020']]]>0,Table2[[#This Row],[Mrd m3 EU '[2020']]],Table2[[#This Row],[Mrd m3 '[2020']]])*9.77 -> 1.9156528 | M10: =_xlfn.CONCAT(A10,$J$2) -> CZ_Prod | N10: =Table2[[#This Row],[Country]] -> CZ
A11: DK | B11: Denmark | C11: 1.379693 | D11: 1427.541 | E11: =Table2[[#This Row],[Mil m3 EU '[2020']]]/1000 -> 1.427541 | F11: =Table2[[#This Row],[TWh '[2020']2]]*1000 -> 13947.076 | G11: =IF(Table2[[#This Row],[Mil m3 EU '[2020']]]>0,Table2[[#This Row],[Mrd m3 EU '[2020']]],Table2[[#This Row],[Mrd m3 '[2020']]])*9.77 -> 13.947076 | M11: =_xlfn.CONCAT(A11,$J$2) -> DK_Prod | N11: =Table2[[#This Row],[Country]] -> DK
A12: EE | B12: Estonia | D12: 0 | E12: =Table2[[#This Row],[Mil m3 EU '[2020']]]/1000 -> 0 | F12: =Table2[[#This Row],[TWh '[2020']2]]*1000 -> 0 | G12: =IF(Table2[[#This Row],[Mil m3 EU '[2020']]]>0,Table2[[#This Row],[Mrd m3 EU '[2020']]],Table2[[#This Row],[Mrd m3 '[2020']]])*9.77 -> 0 | M12: =_xlfn.CONCAT(A12,$J$2) -> EE_Prod | N12: =Table2[[#This Row],[Country]] -> EE
A13: FI | B13: Finland | E13: =Table2[[#This Row],[Mil m3 EU '[2020']]]/1000 -> 0 | F13: =Table2[[#This Row],[TWh '[2020']2]]*1000 -> 0 | G13: =IF(Table2[[#This Row],[Mil m3 EU '[2020']]]>0,Table2[[#This Row],[Mrd m3 EU '[2020']]],Table2[[#This Row],[Mrd m3 '[2020']]])*9.77 -> 0 | M13: =_xlfn.CONCAT(A13,$J$2) -> FI_Prod | N13: =Table2[[#This Row],[Country]] -> FI
A14: FR | B14: France | D14: 17.349 | E14: =Table2[[#This Row],[Mil m3 EU '[2020']]]/1000 -> 0.017349 | F14: =Table2[[#This Row],[TWh '[2020']2]]*1000 -> 169.49973 | G14: =IF(Table2[[#This Row],[Mil m3 EU '[2020']]]>0,Table2[[#This Row],[Mrd m3 EU '[2020']]],Table2[[#This Row],[Mrd m3 '[2020']]])*9.77 -> 0.16949973 | M14: =_xlfn.CONCAT(A14,$J$2) -> FR_Prod | N14: =Table2[[#This Row],[Country]] -> FR
A15: DE | B15: Germany | C15: 4.5324203 | D15: 4874 | E15: =Table2[[#This Row],[Mil m3 EU '[2020']]]/1000 -> 4.874 | F15: =Table2[[#This Row],[TWh '[2020']2]]*1000 -> 47618.98 | G15: =IF(Table2[[#This Row],[Mil m3 EU '[2020']]]>0,Table2[[#This Row],[Mrd m3 EU '[2020']]],Table2[[#This Row],[Mrd m3 '[2020']]])*9.77 -> 47.61898 | M15: =_xlfn.CONCAT(A15,$J$2) -> DE_Prod | N15: =Table2[[#This Row],[Country]] -> DE
A16: EL | B16: Greece | D16: 6.48 | E16: =Table2[[#This Row],[Mil m3 EU '[2020']]]/1000 -> 0.00648 | F16: =Table2[[#This Row],[TWh '[2020']2]]*1000 -> 63.3096 | G16: =IF(Table2[[#This Row],[Mil m3 EU '[2020']]]>0,Table2[[#This Row],[Mrd m3 EU '[2020']]],Table2[[#This Row],[Mrd m3 '[2020']]])*9.77 -> 0.0633096 | M16: =_xlfn.CONCAT(A16,$J$2) -> EL_Prod | N16: =Table2[[#This Row],[Country]] -> EL
A17: HU | B17: Hungary | D17: 1685 | E17: =Table2[[#This Row],[Mil m3 EU '[2020']]]/1000 -> 1.685 | F17: =Table2[[#This Row],[TWh '[2020']2]]*1000 -> 16462.45 | G17: =IF(Table2[[#This Row],[Mil m3 EU '[2020']]]>0,Table2[[#This Row],[Mrd m3 EU '[2020']]],Table2[[#This Row],[Mrd m3 '[2020']]])*9.77 -> 16.46245 | M17: =_xlfn.CONCAT(A17,$J$2) -> HU_Prod | N17: =Table2[[#This Row],[Country]] -> HU
A18: IE | B18: Ireland | D18: 2029.651 | E18: =Table2[[#This Row],[Mil m3 EU '[2020']]]/1000 -> 2.029651 | F18: =Table2[[#This Row],[TWh '[2020']2]]*1000 -> 19829.69 | G18: =IF(Table2[[#This Row],[Mil m3 EU '[2020']]]>0,Table2[[#This Row],[Mrd m3 EU '[2020']]],Table2[[#This Row],[Mrd m3 '[2020']]])*9.77 -> 19.82969 | M18: =_xlfn.CONCAT(A18,$J$2) -> IE_Prod | N18: =Table2[[#This Row],[Country]] -> IE
A19: IT | B19: Italy | C19: 3.9120907 | D19: 3932 | E19: =Table2[[#This Row],[Mil m3 EU '[2020']]]/1000 -> 3.932 | F19: =Table2[[#This Row],[TWh '[2020']2]]*1000 -> 38415.64 | G19: =IF(Table2[[#This Row],[Mil m3 EU '[2020']]]>0,Table2[[#This Row],[Mrd m3 EU '[2020']]],Table2[[#This Row],[Mrd m3 '[2020']]])*9.77 -> 38.41564 | M19: =_xlfn.CONCAT(A19,$J$2) -> IT_Prod | N19: =Table2[[#This Row],[Country]] -> IT
A20: LV | B20: Latvia | E20: =Table2[[#This Row],[Mil m3 EU '[2020']]]/1000 -> 0 | F20: =Table2[[#This Row],[TWh '[2020']2]]*1000 -> 0 | G20: =IF(Table2[[#This Row],[Mil m3 EU '[2020']]]>0,Table2[[#This Row],[Mrd m3 EU '[2020']]],Table2[[#This Row],[Mrd m3 '[2020']]])*9.77 -> 0 | M20: =_xlfn.CONCAT(A20,$J$2) -> LV_Prod | N20: =Table2[[#This Row],[Country]] -> LV
A21: LY | B21: Libya | C21: 12.699712 | E21: =Table2[[#This Row],[Mil m3 EU '[2020']]]/1000 -> 0 | F21: =Table2[[#This Row],[TWh '[2020']2]]*1000 -> 124076.19 | G21: =IF(Table2[[#This Row],[Mil m3 EU '[2020']]]>0,Table2[[#This Row],[Mrd m3 EU '[2020']]],Table2[[#This Row],[Mrd m3 '[2020']]])*9.77 -> 124.07619 | M21: =_xlfn.CONCAT(A21,$J$2) -> LY_Prod | N21: =Table2[[#This Row],[Country]] -> LY
A22: LT | B22: Lithuania | E22: =Table2[[#This Row],[Mil m3 EU '[2020']]]/1000 -> 0 | F22: =Table2[[#This Row],[TWh '[2020']2]]*1000 -> 0 | G22: =IF(Table2[[#This Row],[Mil m3 EU '[2020']]]>0,Table2[[#This Row],[Mrd m3 EU '[2020']]],Table2[[#This Row],[Mrd m3 '[2020']]])*9.77 -> 0 | M22: =_xlfn.CONCAT(A22,$J$2) -> LT_Prod | N22: =Table2[[#This Row],[Country]] -> LT
A23: LU | B23: Luxemburg | E23: =Table2[[#This Row],[Mil m3 EU '[2020']]]/1000 -> 0 | F23: =Table2[[#This Row],[TWh '[2020']2]]*1000 -> 0 | G23: =IF(Table2[[#This Row],[Mil m3 EU '[2020']]]>0,Table2[[#This Row],[Mrd m3 EU '[2020']]],Table2[[#This Row],[Mrd m3 '[2020']]])*9.77 -> 0 | M23: =_xlfn.CONCAT(A23,$J$2) -> LU_Prod | N23: =Table2[[#This Row],[Country]] -> LU
A24: MD | B24: Moldova | E24: =Table2[[#This Row],[Mil m3 EU '[2020']]]/1000 -> 0 | F24: =Table2[[#This Row],[TWh '[2020']2]]*1000 -> 0 | G24: =IF(Table2[[#This Row],[Mil m3 EU '[2020']]]>0,Table2[[#This Row],[Mrd m3 EU '[2020']]],Table2[[#This Row],[Mrd m3 '[2020']]])*9.77 -> 0 | M24: =_xlfn.CONCAT(A24,$J$2) -> MD_Prod | N24: =Table2[[#This Row],[Country]] -> MD
A25: NL | B25: Netherlands | C25: 20.091667 | D25: 23966.123 | E25: =Table2[[#This Row],[Mil m3 EU '[2020']]]/1000 -> 23.966123 | F25: =Table2[[#This Row],[TWh '[2020']2]]*1000 -> 234149.02 | G25: =IF(Table2[[#This Row],[Mil m3 EU '[2020']]]>0,Table2[[#This Row],[Mrd m3 EU '[2020']]],Table2[[#This Row],[Mrd m3 '[2020']]])*9.77 -> 234.14902 | M25: =_xlfn.CONCAT(A25,$J$2) -> NL_Prod | N25: =Table2[[#This Row],[Country]] -> NL
A26: MK | B26: North Macedonia | E26: =Table2[[#This Row],[Mil m3 EU '[2020']]]/1000 -> 0 | F26: =Table2[[#This Row],[TWh '[2020']2]]*1000 -> 0 | G26: =IF(Table2[[#This Row],[Mil m3 EU '[2020']]]>0,Table2[[#This Row],[Mrd m3 EU '[2020']]],Table2[[#This Row],[Mrd m3 '[2020']]])*9.77 -> 0 | M26: =_xlfn.CONCAT(A26,$J$2) -> MK_Prod | N26: =Table2[[#This Row],[Country]] -> MK
A27: NO | B27: Norway | C27: 111.71588 | D27: 116206.12 | E27: =Table2[[#This Row],[Mil m3 EU '[2020']]]/1000 -> 116.20612 | F27: =Table2[[#This Row],[TWh '[2020']2]]*1000 -> 1135333.8 | G27: =IF(Table2[[#This Row],[Mil m3 EU '[2020']]]>0,Table2[[#This Row],[Mrd m3 EU '[2020']]],Table2[[#This Row],[Mrd m3 '[2020']]])*9.77 -> 1135.3338 | M27: =_xlfn.CONCAT(A27,$J$2) -> NO_Prod | N27: =Table2[[#This Row],[Country]] -> NO
A28: PL | B28: Poland | C28: 3.9287778 | D28: 5592.88 | E28: =Table2[[#This Row],[Mil m3 EU '[2020']]]/1000 -> 5.59288 | F28: =Table2[[#This Row],[TWh '[2020']2]]*1000 -> 54642.438 | G28: =IF(Table2[[#This Row],[Mil m3 EU '[2020']]]>0,Table2[[#This Row],[Mrd m3 EU '[2020']]],Table2[[#This Row],[Mrd m3 '[2020']]])*9.77 -> 54.642438 | M28: =_xlfn.CONCAT(A28,$J$2) -> PL_Prod | N28: =Table2[[#This Row],[Country]] -> PL
A29: PT | B29: Portugal | E29: =Table2[[#This Row],[Mil m3 EU '[2020']]]/1000 -> 0 | F29: =Table2[[#This Row],[TWh '[2020']2]]*1000 -> 0 | G29: =IF(Table2[[#This Row],[Mil m3 EU '[2020']]]>0,Table2[[#This Row],[Mrd m3 EU '[2020']]],Table2[[#This Row],[Mrd m3 '[2020']]])*9.77 -> 0 | M29: =_xlfn.CONCAT(A29,$J$2) -> PT_Prod | N29: =Table2[[#This Row],[Country]] -> PT
A30: RO | B30: Romania | C30: 8.5963214 | D30: 9017 | E30: =Table2[[#This Row],[Mil m3 EU '[2020']]]/1000 -> 9.017 | F30: =Table2[[#This Row],[TWh '[2020']2]]*1000 -> 88096.09 | G30: =IF(Table2[[#This Row],[Mil m3 EU '[2020']]]>0,Table2[[#This Row],[Mrd m3 EU '[2020']]],Table2[[#This Row],[Mrd m3 '[2020']]])*9.77 -> 88.09609 | M30: =_xlfn.CONCAT(A30,$J$2) -> RO_Prod | N30: =Table2[[#This Row],[Country]] -> RO
A31: RU | B31: Russia | C31: 638.44666 | E31: =Table2[[#This Row],[Mil m3 EU '[2020']]]/1000 -> 0 | F31: =Table2[[#This Row],[TWh '[2020']2]]*1000 -> 6237623.8 | G31: =IF(Table2[[#This Row],[Mil m3 EU '[2020']]]>0,Table2[[#This Row],[Mrd m3 EU '[2020']]],Table2[[#This Row],[Mrd m3 '[2020']]])*9.77 -> 6237.6238 | M31: =_xlfn.CONCAT(A31,$J$2) -> RU_Prod | N31: =Table2[[#This Row],[Country]] -> RU
A32: SM | B32: San Marino | E32: =Table2[[#This Row],[Mil m3 EU '[2020']]]/1000 -> 0 | F32: =Table2[[#This Row],[TWh '[2020']2]]*1000 -> 0 | G32: =IF(Table2[[#This Row],[Mil m3 EU '[2020']]]>0,Table2[[#This Row],[Mrd m3 EU '[2020']]],Table2[[#This Row],[Mrd m3 '[2020']]])*9.77 -> 0 | M32: =_xlfn.CONCAT(A32,$J$2) -> SM_Prod | N32: =Table2[[#This Row],[Country]] -> SM
A33: RS | B33: Serbia | D33: 409 | E33: =Table2[[#This Row],[Mil m3 EU '[2020']]]/1000 -> 0.409 | F33: =Table2[[#This Row],[TWh '[2020']2]]*1000 -> 3995.93 | G33: =IF(Table2[[#This Row],[Mil m3 EU '[2020']]]>0,Table2[[#This Row],[Mrd m3 EU '[2020']]],Table2[[#This Row],[Mrd m3 '[2020']]])*9.77 -> 3.99593 | M33: =_xlfn.CONCAT(A33,$J$2) -> RS_Prod | N33: =Table2[[#This Row],[Country]] -> RS
A34: SK | B34: Slovakia | D34: 66.701 | E34: =Table2[[#This Row],[Mil m3 EU '[2020']]]/1000 -> 0.066701 | F34: =Table2[[#This Row],[TWh '[2020']2]]*1000 -> 651.66877 | G34: =IF(Table2[[#This Row],[Mil m3 EU '[2020']]]>0,Table2[[#This Row],[Mrd m3 EU '[2020']]],Table2[[#This Row],[Mrd m3 '[2020']]])*9.77 -> 0.65166877 | M34: =_xlfn.CONCAT(A34,$J$2) -> SK_Prod | N34: =Table2[[#This Row],[Country]] -> SK
A35: SI | B35: Slovenia | D35: 5.334 | E35: =Table2[[#This Row],[Mil m3 EU '[2020']]]/1000 -> 0.005334 | F35: =Table2[[#This Row],[TWh '[2020']2]]*1000 -> 52.11318 | G35: =IF(Table2[[#This Row],[Mil m3 EU '[2020']]]>0,Table2[[#This Row],[Mrd m3 EU '[2020']]],Table2[[#This Row],[Mrd m3 '[2020']]])*9.77 -> 0.05211318 | M35: =_xlfn.CONCAT(A35,$J$2) -> SI_Prod | N35: =Table2[[#This Row],[Country]] -> SI
A36: CH | B36: Switzerland | E36: =Table2[[#This Row],[Mil m3 EU '[2020']]]/1000 -> 0 | F36: =Table2[[#This Row],[TWh '[2020']2]]*1000 -> 0 | G36: =IF(Table2[[#This Row],[Mil m3 EU '[2020']]]>0,Table2[[#This Row],[Mrd m3 EU '[2020']]],Table2[[#This Row],[Mrd m3 '[2020']]])*9.77 -> 0 | M36: =_xlfn.CONCAT(A36,$J$2) -> CH_Prod | N36: =Table2[[#This Row],[Country]] -> CH
A37: TN | B37: Tunisia | C37: 1.9 | E37: =Table2[[#This Row],[Mil m3 EU '[2020']]]/1000 -> 0 | F37: =Table2[[#This Row],[TWh '[2020']2]]*1000 -> 18563 | G37: =IF(Table2[[#This Row],[Mil m3 EU '[2020']]]>0,Table2[[#This Row],[Mrd m3 EU '[2020']]],Table2[[#This Row],[Mrd m3 '[2020']]])*9.77 -> 18.563 | M37: =_xlfn.CONCAT(A37,$J$2) -> TN_Prod | N37: =Table2[[#This Row],[Country]] -> TN
A38: TR | B38: Türkiye | D38: 437.51 | E38: =Table2[[#This Row],[Mil m3 EU '[2020']]]/1000 -> 0.43751 | F38: =Table2[[#This Row],[TWh '[2020']2]]*1000 -> 4274.4727 | G38: =IF(Table2[[#This Row],[Mil m3 EU '[2020']]]>0,Table2[[#This Row],[Mrd m3 EU '[2020']]],Table2[[#This Row],[Mrd m3 '[2020']]])*9.77 -> 4.2744727 | M38: =_xlfn.CONCAT(A38,$J$2) -> TR_Prod | N38: =Table2[[#This Row],[Country]] -> TR
A39: UK | B39: UK | C39: 39.571421 | D39: 32836.552 | E39: =Table2[[#This Row],[Mil m3 EU '[2020']]]/1000 -> 32.836552 | F39: =Table2[[#This Row],[TWh '[2020']2]]*1000 -> 320813.11 | G39: =IF(Table2[[#This Row],[Mil m3 EU '[2020']]]>0,Table2[[#This Row],[Mrd m3 EU '[2020']]],Table2[[#This Row],[Mrd m3 '[2020']]])*9.77 -> 320.81311 | M39: =_xlfn.CONCAT(A39,$J$2) -> UK_Prod | N39: =Table2[[#This Row],[Country]] -> UK
A40: UA | B40: Ukraine | C40: 19.117502 | D40: 19516 | E40: =Table2[[#This Row],[Mil m3 EU '[2020']]]/1000 -> 19.516 | F40: =Table2[[#This Row],[TWh '[2020']2]]*1000 -> 190671.32 | G40: =IF(Table2[[#This Row],[Mil m3 EU '[2020']]]>0,Table2[[#This Row],[Mrd m3 EU '[2020']]],Table2[[#This Row],[Mrd m3 '[2020']]])*9.77 -> 190.67132 | M40: =_xlfn.CONCAT(A40,$J$2) -> UA_Prod | N40: =Table2[[#This Row],[Country]] -> UA
...

Sheet nodes_gas_prod_world_2020
A1: Country | B1: Long_name | C1: Mrd m3 [2020] | D1: Mil m3 [2020] | E1: Mrd m3 [2020]2 | F1: GWh [2020] | G1: TWh [2020]2
A2: USA | B2: USA | C2: 924.81293 | E2: =Table7[[#This Row],[Mil m3 '[2020']]]/1000 -> 0 | F2: =Table7[[#This Row],[TWh '[2020']2]]*1000 -> 9035422.3 | G2: =IF(Table7[[#This Row],[Mil m3 '[2020']]]>0,Table7[[#This Row],[Mrd m3 '[2020']2]],Table7[[#This Row],[Mrd m3 '[2020']]])*9.77 -> 9035.4223
A3: CM | B3: North America | C3: =165.613+35.5252809102083 -> 201.13828 | E3: =Table7[[#This Row],[Mil m3 '[2020']]]/1000 -> 0 | F3: =Table7[[#This Row],[TWh '[2020']2]]*1000 -> 1965121 | G3: =IF(Table7[[#This Row],[Mil m3 '[2020']]]>0,Table7[[#This Row],[Mrd m3 '[2020']2]],Table7[[#This Row],[Mrd m3 '[2020']]])*9.77 -> 1965.121
A4: SA | B4: South America | C4: =156.619145389645-29.4652641615749 -> 127.15388 | E4: =Table7[[#This Row],[Mil m3 '[2020']]]/1000 -> 0 | F4: =Table7[[#This Row],[TWh '[2020']2]]*1000 -> 1242293.4 | G4: =IF(Table7[[#This Row],[Mil m3 '[2020']]]>0,Table7[[#This Row],[Mrd m3 '[2020']2]],Table7[[#This Row],[Mrd m3 '[2020']]])*9.77 -> 1242.2934
A5: TT | B5: Trinidad & Tobago | C5: 29.465264 | E5: =Table7[[#This Row],[Mil m3 '[2020']]]/1000 -> 0 | F5: =Table7[[#This Row],[TWh '[2020']2]]*1000 -> 287875.63 | G5: =IF(Table7[[#This Row],[Mil m3 '[2020']]]>0,Table7[[#This Row],[Mrd m3 '[2020']2]],Table7[[#This Row],[Mrd m3 '[2020']]])*9.77 -> 287.87563
A6: ME | B6: Middle East | C6: =667.939379731508-174.9348378172 -> 493.00454 | E6: =Table7[[#This Row],[Mil m3 '[2020']]]/1000 -> 0 | F6: =Table7[[#This Row],[TWh '[2020']2]]*1000 -> 4816654.4 | G6: =IF(Table7[[#This Row],[Mil m3 '[2020']]]>0,Table7[[#This Row],[Mrd m3 '[2020']2]],Table7[[#This Row],[Mrd m3 '[2020']]])*9.77 -> 4816.6544
A7: QA | B7: Qatar | C7: 174.93484 | E7: =Table7[[#This Row],[Mil m3 '[2020']]]/1000 -> 0 | F7: =Table7[[#This Row],[TWh '[2020']2]]*1000 -> 1709113.4 | G7: =IF(Table7[[#This Row],[Mil m3 '[2020']]]>0,Table7[[#This Row],[Mrd m3 '[2020']2]],Table7[[#This Row],[Mrd m3 '[2020']]])*9.77 -> 1709.1134
A8: AF | B8: Africa | C8: =231.909048813308-nodes_gas_prod_europe_2020!C21-nodes_gas_prod_europe_2020!C3-nodes_gas_prod_europe_2020!C37-C16 -> 77.41955 | E8: =Table7[[#This Row],[Mil m3 '[2020']]]/1000 -> 0 | F8: =Table7[[#This Row],[TWh '[2020']2]]*1000 -> 756389 | G8: =IF(Table7[[#This Row],[Mil m3 '[2020']]]>0,Table7[[#This Row],[Mrd m3 '[2020']2]],Table7[[#This Row],[Mrd m3 '[2020']]])*9.77 -> 756.389
A9: MA | B9: Morroco | C9: 0.07 | E9: =Table7[[#This Row],[Mil m3 '[2020']]]/1000 -> 0 | F9: =Table7[[#This Row],[TWh '[2020']2]]*1000 -> 683.9 | G9: =IF(Table7[[#This Row],[Mil m3 '[2020']]]>0,Table7[[#This Row],[Mrd m3 '[2020']2]],Table7[[#This Row],[Mrd m3 '[2020']]])*9.77 -> 0.6839
A10: AU | B10: Australia | C10: 145.71638 | E10: =Table7[[#This Row],[Mil m3 '[2020']]]/1000 -> 0 | F10: =Table7[[#This Row],[TWh '[2020']2]]*1000 -> 1423649 | G10: =IF(Table7[[#This Row],[Mil m3 '[2020']]]>0,Table7[[#This Row],[Mrd m3 '[2020']2]],Table7[[#This Row],[Mrd m3 '[2020']]])*9.77 -> 1423.649
A11: CN | B11: China | C11: 194.00922 | E11: =Table7[[#This Row],[Mil m3 '[2020']]]/1000 -> 0 | F11: =Table7[[#This Row],[TWh '[2020']2]]*1000 -> 1895470.1 | G11: =IF(Table7[[#This Row],[Mil m3 '[2020']]]>0,Table7[[#This Row],[Mrd m3 '[2020']2]],Table7[[#This Row],[Mrd m3 '[2020']]])*9.77 -> 1895.4701
A12: JS | B12: Japan & South Korea | C12: 0 | E12: =Table7[[#This Row],[Mil m3 '[2020']]]/1000 -> 0 | F12: =Table7[[#This Row],[TWh '[2020']2]]*1000 -> 0 | G12: =IF(Table7[[#This Row],[Mil m3 '[2020']]]>0,Table7[[#This Row],[Mrd m3 '[2020']2]],Table7[[#This Row],[Mrd m3 '[2020']]])*9.77 -> 0
A13: IN | B13: India | C13: 23.760627 | E13: =Table7[[#This Row],[Mil m3 '[2020']]]/1000 -> 0 | F13: =Table7[[#This Row],[TWh '[2020']2]]*1000 -> 232141.32 | G13: =IF(Table7[[#This Row],[Mil m3 '[2020']]]>0,Table7[[#This Row],[Mrd m3 '[2020']2]],Table7[[#This Row],[Mrd m3 '[2020']]])*9.77 -> 232.14132
A14: AS | B14: Asia | C14: =656.2735508682-C13-C11-C10-C12-C17 -> 154.99711 | E14: =Table7[[#This Row],[Mil m3 '[2020']]]/1000 -> 0 | F14: =Table7[[#This Row],[TWh '[2020']2]]*1000 -> 1514321.7 | G14: =IF(Table7[[#This Row],[Mil m3 '[2020']]]>0,Table7[[#This Row],[Mrd m3 '[2020']2]],Table7[[#This Row],[Mrd m3 '[2020']]])*9.77 -> 1514.3217
A15: CR | B15: Caspian Region | C15: =808.357450256401-638.446656032448 -> 169.91079 | E15: =Table7[[#This Row],[Mil m3 '[2020']]]/1000 -> 0 | F15: =Table7[[#This Row],[TWh '[2020']2]]*1000 -> 1660028.5 | G15: =IF(Table7[[#This Row],[Mil m3 '[2020']]]>0,Table7[[#This Row],[Mrd m3 '[2020']2]],Table7[[#This Row],[Mrd m3 '[2020']]])*9.77 -> 1660.0285
A16: EG | B16: Egypt | C16: 58.465174 | E16: =Table7[[#This Row],[Mil m3 '[2020']]]/1000 -> 0 | F16: =Table7[[#This Row],[TWh '[2020']2]]*1000 -> 571204.75 | G16: =IF(Table7[[#This Row],[Mil m3 '[2020']]]>0,Table7[[#This Row],[Mrd m3 '[2020']2]],Table7[[#This Row],[Mrd m3 '[2020']]])*9.77 -> 571.20475
A17: IM | B17: Indonesia & Malaysia | C17: =64.6974253845862+73.0927934801951 -> 137.79022 | E17: =Table7[[#This Row],[Mil m3 '[2020']]]/1000 -> 0 | F17: =Table7[[#This Row],[TWh '[2020']2]]*1000 -> 1346210.4 | G17: =IF(Table7[[#This Row],[Mil m3 '[2020']]]>0,Table7[[#This Row],[Mrd m3 '[2020']2]],Table7[[#This Row],[Mrd m3 '[2020']]])*9.77 -> 1346.2104
A20: https://www.energyinst.org/statistical-review
A21: https://www.statista.com/statistics/1538667/natural-gas-production-in-morocco-by-field/ | B21: for Morroco

Sheet nodes_gas_prod_europe_2024
A1: Country | B1: Long_name | C1: Mrd m3 [2020] | D1: Mil m3 EU [2020] | E1: Mrd m3 EU [2020] | F1: GWh [2020] | G1: TWh [2020] | M1: From | N1: To
A2: AL | B2: Albania | D2: 53.951 | E2: =Table26[[#This Row],[Mil m3 EU '[2020']]]/1000 -> 0.053951 | F2: =Table26[[#This Row],[TWh '[2020']]]*1000 -> 527.10127 | G2: =IF(Table26[[#This Row],[Mil m3 EU '[2020']]]>0,Table26[[#This Row],[Mrd m3 EU '[2020']]],Table26[[#This Row],[Mrd m3 '[2020']]])*9.77 -> 0.52710127 | J2: _Prod | M2: =_xlfn.CONCAT(A2,$J$2) -> AL_Prod | N2: =Table26[[#This Row],[Country]] -> AL
A3: DZ | B3: Algeria | C3: 101.54375 | E3: =Table26[[#This Row],[Mil m3 EU '[2020']]]/1000 -> 0 | F3: =Table26[[#This Row],[TWh '[2020']]]*1000 -> 992082.44 | G3: =IF(Table26[[#This Row],[Mil m3 EU '[2020']]]>0,Table26[[#This Row],[Mrd m3 EU '[2020']]],Table26[[#This Row],[Mrd m3 '[2020']]])*9.77 -> 992.08244 | M3: =_xlfn.CONCAT(A3,$J$2) -> DZ_Prod | N3: =Table26[[#This Row],[Country]] -> DZ
A4: AT | B4: Austria | D4: 548.072 | E4: =Table26[[#This Row],[Mil m3 EU '[2020']]]/1000 -> 0.548072 | F4: =Table26[[#This Row],[TWh '[2020']]]*1000 -> 5354.6634 | G4: =IF(Table26[[#This Row],[Mil m3 EU '[2020']]]>0,Table26[[#This Row],[Mrd m3 EU '[2020']]],Table26[[#This Row],[Mrd m3 '[2020']]])*9.77 -> 5.3546634 | M4: =_xlfn.CONCAT(A4,$J$2) -> AT_Prod | N4: =Table26[[#This Row],[Country]] -> AT
A5: BY | B5: Belarus | E5: =Table26[[#This Row],[Mil m3 EU '[2020']]]/1000 -> 0 | F5: =Table26[[#This Row],[TWh '[2020']]]*1000 -> 0 | G5: =IF(Table26[[#This Row],[Mil m3 EU '[2020']]]>0,Table26[[#This Row],[Mrd m3 EU '[2020']]],Table26[[#This Row],[Mrd m3 '[2020']]])*9.77 -> 0 | M5: =_xlfn.CONCAT(A5,$J$2) -> BY_Prod | N5: =Table26[[#This Row],[Country]] -> BY
A6: BE | B6: Belgium | D6: 15 | E6: =Table26[[#This Row],[Mil m3 EU '[2020']]]/1000 -> 0.015 | F6: =Table26[[#This Row],[TWh '[2020']]]*1000 -> 146.55 | G6: =IF(Table26[[#This Row],[Mil m3 EU '[2020']]]>0,Table26[[#This Row],[Mrd m3 EU '[2020']]],Table26[[#This Row],[Mrd m3 '[2020']]])*9.77 -> 0.14655 | M6: =_xlfn.CONCAT(A6,$J$2) -> BE_Prod | N6: =Table26[[#This Row],[Country]] -> BE
A7: BA | B7: Bosnia and Herzegovina | E7: =Table26[[#This Row],[Mil m3 EU '[2020']]]/1000 -> 0 | F7: =Table26[[#This Row],[TWh '[2020']]]*1000 -> 0 | G7: =IF(Table26[[#This Row],[Mil m3 EU '[2020']]]>0,Table26[[#This Row],[Mrd m3 EU '[2020']]],Table26[[#This Row],[Mrd m3 '[2020']]])*9.77 -> 0 | M7: =_xlfn.CONCAT(A7,$J$2) -> BA_Prod | N7: =Table26[[#This Row],[Country]] -> BA
A8: BG | B8: Bulgaria | D8: 8.14 | E8: =Table26[[#This Row],[Mil m3 EU '[2020']]]/1000 -> 0.00814 | F8: =Table26[[#This Row],[TWh '[2020']]]*1000 -> 79.5278 | G8: =IF(Table26[[#This Row],[Mil m3 EU '[2020']]]>0,Table26[[#This Row],[Mrd m3 EU '[2020']]],Table26[[#This Row],[Mrd m3 '[2020']]])*9.77 -> 0.0795278 | M8: =_xlfn.CONCAT(A8,$J$2) -> BG_Prod | N8: =Table26[[#This Row],[Country]] -> BG
A9: HR | B9: Croatia | D9: 754.1 | E9: =Table26[[#This Row],[Mil m3 EU '[2020']]]/1000 -> 0.7541 | F9: =Table26[[#This Row],[TWh '[2020']]]*1000 -> 7367.557 | G9: =IF(Table26[[#This Row],[Mil m3 EU '[2020']]]>0,Table26[[#This Row],[Mrd m3 EU '[2020']]],Table26[[#This Row],[Mrd m3 '[2020']]])*9.77 -> 7.367557 | M9: =_xlfn.CONCAT(A9,$J$2) -> HR_Prod | N9: =Table26[[#This Row],[Country]] -> HR
A10: CZ | B10: Czech Republic | D10: 186.469 | E10: =Table26[[#This Row],[Mil m3 EU '[2020']]]/1000 -> 0.186469 | F10: =Table26[[#This Row],[TWh '[2020']]]*1000 -> 1821.8021 | G10: =IF(Table26[[#This Row],[Mil m3 EU '[2020']]]>0,Table26[[#This Row],[Mrd m3 EU '[2020']]],Table26[[#This Row],[Mrd m3 '[2020']]])*9.77 -> 1.8218021 | M10: =_xlfn.CONCAT(A10,$J$2) -> CZ_Prod | N10: =Table26[[#This Row],[Country]] -> CZ
A11: DK | B11: Denmark | C11: 1.401156 | D11: 1801.47 | E11: =Table26[[#This Row],[Mil m3 EU '[2020']]]/1000 -> 1.80147 | F11: =Table26[[#This Row],[TWh '[2020']]]*1000 -> 17600.362 | G11: =IF(Table26[[#This Row],[Mil m3 EU '[2020']]]>0,Table26[[#This Row],[Mrd m3 EU '[2020']]],Table26[[#This Row],[Mrd m3 '[2020']]])*9.77 -> 17.600362 | M11: =_xlfn.CONCAT(A11,$J$2) -> DK_Prod | N11: =Table26[[#This Row],[Country]] -> DK
A12: EE | B12: Estonia | D12: 0 | E12: =Table26[[#This Row],[Mil m3 EU '[2020']]]/1000 -> 0 | F12: =Table26[[#This Row],[TWh '[2020']]]*1000 -> 0 | G12: =IF(Table26[[#This Row],[Mil m3 EU '[2020']]]>0,Table26[[#This Row],[Mrd m3 EU '[2020']]],Table26[[#This Row],[Mrd m3 '[2020']]])*9.77 -> 0 | M12: =_xlfn.CONCAT(A12,$J$2) -> EE_Prod | N12: =Table26[[#This Row],[Country]] -> EE
A13: FI | B13: Finland | E13: =Table26[[#This Row],[Mil m3 EU '[2020']]]/1000 -> 0 | F13: =Table26[[#This Row],[TWh '[2020']]]*1000 -> 0 | G13: =IF(Table26[[#This Row],[Mil m3 EU '[2020']]]>0,Table26[[#This Row],[Mrd m3 EU '[2020']]],Table26[[#This Row],[Mrd m3 '[2020']]])*9.77 -> 0 | M13: =_xlfn.CONCAT(A13,$J$2) -> FI_Prod | N13: =Table26[[#This Row],[Country]] -> FI
A14: FR | B14: France | D14: 12.376 | E14: =Table26[[#This Row],[Mil m3 EU '[2020']]]/1000 -> 0.012376 | F14: =Table26[[#This Row],[TWh '[2020']]]*1000 -> 120.91352 | G14: =IF(Table26[[#This Row],[Mil m3 EU '[2020']]]>0,Table26[[#This Row],[Mrd m3 EU '[2020']]],Table26[[#This Row],[Mrd m3 '[2020']]])*9.77 -> 0.12091352 | M14: =_xlfn.CONCAT(A14,$J$2) -> FR_Prod | N14: =Table26[[#This Row],[Country]] -> FR
A15: DE | B15: Germany | C15: 3.8061187 | D15: 3873 | E15: =Table26[[#This Row],[Mil m3 EU '[2020']]]/1000 -> 3.873 | F15: =Table26[[#This Row],[TWh '[2020']]]*1000 -> 37839.21 | G15: =IF(Table26[[#This Row],[Mil m3 EU '[2020']]]>0,Table26[[#This Row],[Mrd m3 EU '[2020']]],Table26[[#This Row],[Mrd m3 '[2020']]])*9.77 -> 37.83921 | M15: =_xlfn.CONCAT(A15,$J$2) -> DE_Prod | N15: =Table26[[#This Row],[Country]] -> DE
A16: EL | B16: Greece | D16: 1.991 | E16: =Table26[[#This Row],[Mil m3 EU '[2020']]]/1000 -> 0.001991 | F16: =Table26[[#This Row],[TWh '[2020']]]*1000 -> 19.45207 | G16: =IF(Table26[[#This Row],[Mil m3 EU '[2020']]]>0,Table26[[#This Row],[Mrd m3 EU '[2020']]],Table26[[#This Row],[Mrd m3 '[2020']]])*9.77 -> 0.01945207 | M16: =_xlfn.CONCAT(A16,$J$2) -> EL_Prod | N16: =Table26[[#This Row],[Country]] -> EL
A17: HU | B17: Hungary | D17: 1723.8 | E17: =Table26[[#This Row],[Mil m3 EU '[2020']]]/1000 -> 1.7238 | F17: =Table26[[#This Row],[TWh '[2020']]]*1000 -> 16841.526 | G17: =IF(Table26[[#This Row],[Mil m3 EU '[2020']]]>0,Table26[[#This Row],[Mrd m3 EU '[2020']]],Table26[[#This Row],[Mrd m3 '[2020']]])*9.77 -> 16.841526 | M17: =_xlfn.CONCAT(A17,$J$2) -> HU_Prod | N17: =Table26[[#This Row],[Country]] -> HU
A18: IE | B18: Ireland | D18: 1080.785 | E18: =Table26[[#This Row],[Mil m3 EU '[2020']]]/1000 -> 1.080785 | F18: =Table26[[#This Row],[TWh '[2020']]]*1000 -> 10559.269 | G18: =IF(Table26[[#This Row],[Mil m3 EU '[2020']]]>0,Table26[[#This Row],[Mrd m3 EU '[2020']]],Table26[[#This Row],[Mrd m3 '[2020']]])*9.77 -> 10.559269 | M18: =_xlfn.CONCAT(A18,$J$2) -> IE_Prod | N18: =Table26[[#This Row],[Country]] -> IE
A19: IT | B19: Italy | C19: 2.8462663 | D19: 2940.244 | E19: =Table26[[#This Row],[Mil m3 EU '[2020']]]/1000 -> 2.940244 | F19: =Table26[[#This Row],[TWh '[2020']]]*1000 -> 28726.184 | G19: =IF(Table26[[#This Row],[Mil m3 EU '[2020']]]>0,Table26[[#This Row],[Mrd m3 EU '[2020']]],Table26[[#This Row],[Mrd m3 '[2020']]])*9.77 -> 28.726184 | M19: =_xlfn.CONCAT(A19,$J$2) -> IT_Prod | N19: =Table26[[#This Row],[Country]] -> IT
A20: LV | B20: Latvia | E20: =Table26[[#This Row],[Mil m3 EU '[2020']]]/1000 -> 0 | F20: =Table26[[#This Row],[TWh '[2020']]]*1000 -> 0 | G20: =IF(Table26[[#This Row],[Mil m3 EU '[2020']]]>0,Table26[[#This Row],[Mrd m3 EU '[2020']]],Table26[[#This Row],[Mrd m3 '[2020']]])*9.77 -> 0 | M20: =_xlfn.CONCAT(A20,$J$2) -> LV_Prod | N20: =Table26[[#This Row],[Country]] -> LV
A21: LY | B21: Libya | C21: 16.307676 | E21: =Table26[[#This Row],[Mil m3 EU '[2020']]]/1000 -> 0 | F21: =Table26[[#This Row],[TWh '[2020']]]*1000 -> 159325.99 | G21: =IF(Table26[[#This Row],[Mil m3 EU '[2020']]]>0,Table26[[#This Row],[Mrd m3 EU '[2020']]],Table26[[#This Row],[Mrd m3 '[2020']]])*9.77 -> 159.32599 | M21: =_xlfn.CONCAT(A21,$J$2) -> LY_Prod | N21: =Table26[[#This Row],[Country]] -> LY
A22: LT | B22: Lithuania | E22: =Table26[[#This Row],[Mil m3 EU '[2020']]]/1000 -> 0 | F22: =Table26[[#This Row],[TWh '[2020']]]*1000 -> 0 | G22: =IF(Table26[[#This Row],[Mil m3 EU '[2020']]]>0,Table26[[#This Row],[Mrd m3 EU '[2020']]],Table26[[#This Row],[Mrd m3 '[2020']]])*9.77 -> 0 | M22: =_xlfn.CONCAT(A22,$J$2) -> LT_Prod | N22: =Table26[[#This Row],[Country]] -> LT
A23: LU | B23: Luxemburg | E23: =Table26[[#This Row],[Mil m3 EU '[2020']]]/1000 -> 0 | F23: =Table26[[#This Row],[TWh '[2020']]]*1000 -> 0 | G23: =IF(Table26[[#This Row],[Mil m3 EU '[2020']]]>0,Table26[[#This Row],[Mrd m3 EU '[2020']]],Table26[[#This Row],[Mrd m3 '[2020']]])*9.77 -> 0 | M23: =_xlfn.CONCAT(A23,$J$2) -> LU_Prod | N23: =Table26[[#This Row],[Country]] -> LU
A24: MD | B24: Moldova | E24: =Table26[[#This Row],[Mil m3 EU '[2020']]]/1000 -> 0 | F24: =Table26[[#This Row],[TWh '[2020']]]*1000 -> 0 | G24: =IF(Table26[[#This Row],[Mil m3 EU '[2020']]]>0,Table26[[#This Row],[Mrd m3 EU '[2020']]],Table26[[#This Row],[Mrd m3 '[2020']]])*9.77 -> 0 | M24: =_xlfn.CONCAT(A24,$J$2) -> MD_Prod | N24: =Table26[[#This Row],[Country]] -> MD
A25: NL | B25: Netherlands | C25: 9.8527778 | D25: 9838.773 | E25: =Table26[[#This Row],[Mil m3 EU '[2020']]]/1000 -> 9.838773 | F25: =Table26[[#This Row],[TWh '[2020']]]*1000 -> 96124.812 | G25: =IF(Table26[[#This Row],[Mil m3 EU '[2020']]]>0,Table26[[#This Row],[Mrd m3 EU '[2020']]],Table26[[#This Row],[Mrd m3 '[2020']]])*9.77 -> 96.124812 | M25: =_xlfn.CONCAT(A25,$J$2) -> NL_Prod | N25: =Table26[[#This Row],[Country]] -> NL
A26: MK | B26: North Macedonia | E26: =Table26[[#This Row],[Mil m3 EU '[2020']]]/1000 -> 0 | F26: =Table26[[#This Row],[TWh '[2020']]]*1000 -> 0 | G26: =IF(Table26[[#This Row],[Mil m3 EU '[2020']]]>0,Table26[[#This Row],[Mrd m3 EU '[2020']]],Table26[[#This Row],[Mrd m3 '[2020']]])*9.77 -> 0 | M26: =_xlfn.CONCAT(A26,$J$2) -> MK_Prod | N26: =Table26[[#This Row],[Country]] -> MK
A27: NO | B27: Norway | C27: 116.63358 | D27: 117972.9 | E27: =Table26[[#This Row],[Mil m3 EU '[2020']]]/1000 -> 117.9729 | F27: =Table26[[#This Row],[TWh '[2020']]]*1000 -> 1152595.3 | G27: =IF(Table26[[#This Row],[Mil m3 EU '[2020']]]>0,Table26[[#This Row],[Mrd m3 EU '[2020']]],Table26[[#This Row],[Mrd m3 '[2020']]])*9.77 -> 1152.5953 | M27: =_xlfn.CONCAT(A27,$J$2) -> NO_Prod | N27: =Table26[[#This Row],[Country]] -> NO
A28: PL | B28: Poland | C28: 3.597013 | E28: =Table26[[#This Row],[Mil m3 EU '[2020']]]/1000 -> 0 | F28: =Table26[[#This Row],[TWh '[2020']]]*1000 -> 35142.817 | G28: =IF(Table26[[#This Row],[Mil m3 EU '[2020']]]>0,Table26[[#This Row],[Mrd m3 EU '[2020']]],Table26[[#This Row],[Mrd m3 '[2020']]])*9.77 -> 35.142817 | M28: =_xlfn.CONCAT(A28,$J$2) -> PL_Prod | N28: =Table26[[#This Row],[Country]] -> PL
A29: PT | B29: Portugal | E29: =Table26[[#This Row],[Mil m3 EU '[2020']]]/1000 -> 0 | F29: =Table26[[#This Row],[TWh '[2020']]]*1000 -> 0 | G29: =IF(Table26[[#This Row],[Mil m3 EU '[2020']]]>0,Table26[[#This Row],[Mrd m3 EU '[2020']]],Table26[[#This Row],[Mrd m3 '[2020']]])*9.77 -> 0 | M29: =_xlfn.CONCAT(A29,$J$2) -> PT_Prod | N29: =Table26[[#This Row],[Country]] -> PT
A30: RO | B30: Romania | C30: 8.8722169 | D30: 9372 | E30: =Table26[[#This Row],[Mil m3 EU '[2020']]]/1000 -> 9.372 | F30: =Table26[[#This Row],[TWh '[2020']]]*1000 -> 91564.44 | G30: =IF(Table26[[#This Row],[Mil m3 EU '[2020']]]>0,Table26[[#This Row],[Mrd m3 EU '[2020']]],Table26[[#This Row],[Mrd m3 '[2020']]])*9.77 -> 91.56444 | M30: =_xlfn.CONCAT(A30,$J$2) -> RO_Prod | N30: =Table26[[#This Row],[Country]] -> RO
A31: RU | B31: Russia | C31: 586.3822 | E31: =Table26[[#This Row],[Mil m3 EU '[2020']]]/1000 -> 0 | F31: =Table26[[#This Row],[TWh '[2020']]]*1000 -> 5728954.1 | G31: =IF(Table26[[#This Row],[Mil m3 EU '[2020']]]>0,Table26[[#This Row],[Mrd m3 EU '[2020']]],Table26[[#This Row],[Mrd m3 '[2020']]])*9.77 -> 5728.9541 | M31: =_xlfn.CONCAT(A31,$J$2) -> RU_Prod | N31: =Table26[[#This Row],[Country]] -> RU
A32: SM | B32: San Marino | E32: =Table26[[#This Row],[Mil m3 EU '[2020']]]/1000 -> 0 | F32: =Table26[[#This Row],[TWh '[2020']]]*1000 -> 0 | G32: =IF(Table26[[#This Row],[Mil m3 EU '[2020']]]>0,Table26[[#This Row],[Mrd m3 EU '[2020']]],Table26[[#This Row],[Mrd m3 '[2020']]])*9.77 -> 0 | M32: =_xlfn.CONCAT(A32,$J$2) -> SM_Prod | N32: =Table26[[#This Row],[Country]] -> SM
A33: RS | B33: Serbia | D33: 295 | E33: =Table26[[#This Row],[Mil m3 EU '[2020']]]/1000 -> 0.295 | F33: =Table26[[#This Row],[TWh '[2020']]]*1000 -> 2882.15 | G33: =IF(Table26[[#This Row],[Mil m3 EU '[2020']]]>0,Table26[[#This Row],[Mrd m3 EU '[2020']]],Table26[[#This Row],[Mrd m3 '[2020']]])*9.77 -> 2.88215 | M33: =_xlfn.CONCAT(A33,$J$2) -> RS_Prod | N33: =Table26[[#This Row],[Country]] -> RS
A34: SK | B34: Slovakia | D34: 40.037 | E34: =Table26[[#This Row],[Mil m3 EU '[2020']]]/1000 -> 0.040037 | F34: =Table26[[#This Row],[TWh '[2020']]]*1000 -> 391.16149 | G34: =IF(Table26[[#This Row],[Mil m3 EU '[2020']]]>0,Table26[[#This Row],[Mrd m3 EU '[2020']]],Table26[[#This Row],[Mrd m3 '[2020']]])*9.77 -> 0.39116149 | M34: =_xlfn.CONCAT(A34,$J$2) -> SK_Prod | N34: =Table26[[#This Row],[Country]] -> SK
A35: SI | B35: Slovenia | D35: 3.802 | E35: =Table26[[#This Row],[Mil m3 EU '[2020']]]/1000 -> 0.003802 | F35: =Table26[[#This Row],[TWh '[2020']]]*1000 -> 37.14554 | G35: =IF(Table26[[#This Row],[Mil m3 EU '[2020']]]>0,Table26[[#This Row],[Mrd m3 EU '[2020']]],Table26[[#This Row],[Mrd m3 '[2020']]])*9.77 -> 0.03714554 | M35: =_xlfn.CONCAT(A35,$J$2) -> SI_Prod | N35: =Table26[[#This Row],[Country]] -> SI
A36: CH | B36: Switzerland | E36: =Table26[[#This Row],[Mil m3 EU '[2020']]]/1000 -> 0 | F36: =Table26[[#This Row],[TWh '[2020']]]*1000 -> 0 | G36: =IF(Table26[[#This Row],[Mil m3 EU '[2020']]]>0,Table26[[#This Row],[Mrd m3 EU '[2020']]],Table26[[#This Row],[Mrd m3 '[2020']]])*9.77 -> 0 | M36: =_xlfn.CONCAT(A36,$J$2) -> CH_Prod | N36: =Table26[[#This Row],[Country]] -> CH
A37: TN | B37: Tunisia | C37: 1.8432 | E37: =Table26[[#This Row],[Mil m3 EU '[2020']]]/1000 -> 0 | F37: =Table26[[#This Row],[TWh '[2020']]]*1000 -> 18008.064 | G37: =IF(Table26[[#This Row],[Mil m3 EU '[2020']]]>0,Table26[[#This Row],[Mrd m3 EU '[2020']]],Table26[[#This Row],[Mrd m3 '[2020']]])*9.77 -> 18.008064 | M37: =_xlfn.CONCAT(A37,$J$2) -> TN_Prod | N37: =Table26[[#This Row],[Country]] -> TN
A38: TR | B38: Türkiye | D38: 2259.11 | E38: =Table26[[#This Row],[Mil m3 EU '[2020']]]/1000 -> 2.25911 | F38: =Table26[[#This Row],[TWh '[2020']]]*1000 -> 22071.505 | G38: =IF(Table26[[#This Row],[Mil m3 EU '[2020']]]>0,Table26[[#This Row],[Mrd m3 EU '[2020']]],Table26[[#This Row],[Mrd m3 '[2020']]])*9.77 -> 22.071505 | M38: =_xlfn.CONCAT(A38,$J$2) -> TR_Prod | N38: =Table26[[#This Row],[Country]] -> TR
A39: UK | B39: UK | C39: 34.473206 | E39: =Table26[[#This Row],[Mil m3 EU '[2020']]]/1000 -> 0 | F39: =Table26[[#This Row],[TWh '[2020']]]*1000 -> 336803.22 | G39: =IF(Table26[[#This Row],[Mil m3 EU '[2020']]]>0,Table26[[#This Row],[Mrd m3 EU '[2020']]],Table26[[#This Row],[Mrd m3 '[2020']]])*9.77 -> 336.80322 | M39: =_xlfn.CONCAT(A39,$J$2) -> UK_Prod | N39: =Table26[[#This Row],[Country]] -> UK
A40: UA | B40: Ukraine | C40: 17.697886 | E40: =Table26[[#This Row],[Mil m3 EU '[2020']]]/1000 -> 0 | F40: =Table26[[#This Row],[TWh '[2020']]]*1000 -> 172908.35 | G40: =IF(Table26[[#This Row],[Mil m3 EU '[2020']]]>0,Table26[[#This Row],[Mrd m3 EU '[2020']]],Table26[[#This Row],[Mrd m3 '[2020']]])*9.77 -> 172.90835 | M40: =_xlfn.CONCAT(A40,$J$2) -> UA_Prod | N40: =Table26[[#This Row],[Country]] -> UA
...

Sheet nodes_gas_prod_world_2024
A1: Country | B1: Long_name | C1: Mrd m3 [2020] | D1: Mil m3 [2020] | E1: Mrd m3 [2020]2 | F1: GWh [2020] | G1: TWh [2020]
A2: USA | B2: USA | C2: 1035.2967 | E2: =Table79[[#This Row],[Mil m3 '[2020']]]/1000 -> 0 | F2: =Table79[[#This Row],[TWh '[2020']]]*1000 -> 10114849 | G2: =IF(Table79[[#This Row],[Mil m3 '[2020']]]>0,Table79[[#This Row],[Mrd m3 '[2020']2]],Table79[[#This Row],[Mrd m3 '[2020']]])*9.77 -> 10114.849
A3: CM | B3: North America | C3: =1261.13549926252-1035.29668748294 -> 225.83881 | E3: =Table79[[#This Row],[Mil m3 '[2020']]]/1000 -> 0 | F3: =Table79[[#This Row],[TWh '[2020']]]*1000 -> 2206445.2 | G3: =IF(Table79[[#This Row],[Mil m3 '[2020']]]>0,Table79[[#This Row],[Mrd m3 '[2020']2]],Table79[[#This Row],[Mrd m3 '[2020']]])*9.77 -> 2206.4452
A4: SA | B4: South America | C4: =162.021478179314-24.9936060429938 -> 137.02787 | E4: =Table79[[#This Row],[Mil m3 '[2020']]]/1000 -> 0 | F4: =Table79[[#This Row],[TWh '[2020']]]*1000 -> 1338762.3 | G4: =IF(Table79[[#This Row],[Mil m3 '[2020']]]>0,Table79[[#This Row],[Mrd m3 '[2020']2]],Table79[[#This Row],[Mrd m3 '[2020']]])*9.77 -> 1338.7623
A5: TT | B5: Trinidad & Tobago | C5: 24.993606 | E5: =Table79[[#This Row],[Mil m3 '[2020']]]/1000 -> 0 | F5: =Table79[[#This Row],[TWh '[2020']]]*1000 -> 244187.53 | G5: =IF(Table79[[#This Row],[Mil m3 '[2020']]]>0,Table79[[#This Row],[Mrd m3 '[2020']2]],Table79[[#This Row],[Mrd m3 '[2020']]])*9.77 -> 244.18753
A6: ME | B6: Middle East | C6: =712.704008488226-180.976586566424 -> 531.72742 | E6: =Table79[[#This Row],[Mil m3 '[2020']]]/1000 -> 0 | F6: =Table79[[#This Row],[TWh '[2020']]]*1000 -> 5194976.9 | G6: =IF(Table79[[#This Row],[Mil m3 '[2020']]]>0,Table79[[#This Row],[Mrd m3 '[2020']2]],Table79[[#This Row],[Mrd m3 '[2020']]])*9.77 -> 5194.9769
A7: QA | B7: Qatar | C7: 180.97659 | E7: =Table79[[#This Row],[Mil m3 '[2020']]]/1000 -> 0 | F7: =Table79[[#This Row],[TWh '[2020']]]*1000 -> 1768141.3 | G7: =IF(Table79[[#This Row],[Mil m3 '[2020']]]>0,Table79[[#This Row],[Mrd m3 '[2020']2]],Table79[[#This Row],[Mrd m3 '[2020']]])*9.77 -> 1768.1413
A8: AF | B8: Africa | C8: =253.649617284986-nodes_gas_prod_europe_2024!C21-nodes_gas_prod_europe_2024!C3-nodes_gas_prod_europe_2024!C37-C16 -> 76.854578 | E8: =Table79[[#This Row],[Mil m3 '[2020']]]/1000 -> 0 | F8: =Table79[[#This Row],[TWh '[2020']]]*1000 -> 750869.23 | G8: =IF(Table79[[#This Row],[Mil m3 '[2020']]]>0,Table79[[#This Row],[Mrd m3 '[2020']2]],Table79[[#This Row],[Mrd m3 '[2020']]])*9.77 -> 750.86923
A9: MA | B9: Morroco | C9: 0.07 | E9: =Table79[[#This Row],[Mil m3 '[2020']]]/1000 -> 0 | F9: =Table79[[#This Row],[TWh '[2020']]]*1000 -> 683.9 | G9: =IF(Table79[[#This Row],[Mil m3 '[2020']]]>0,Table79[[#This Row],[Mrd m3 '[2020']2]],Table79[[#This Row],[Mrd m3 '[2020']]])*9.77 -> 0.6839
A10: AU | B10: Australia | C10: 151.74021 | E10: =Table79[[#This Row],[Mil m3 '[2020']]]/1000 -> 0 | F10: =Table79[[#This Row],[TWh '[2020']]]*1000 -> 1482501.9 | G10: =IF(Table79[[#This Row],[Mil m3 '[2020']]]>0,Table79[[#This Row],[Mrd m3 '[2020']2]],Table79[[#This Row],[Mrd m3 '[2020']]])*9.77 -> 1482.5019
A11: CN | B11: China | C11: 234.25836 | E11: =Table79[[#This Row],[Mil m3 '[2020']]]/1000 -> 0 | F11: =Table79[[#This Row],[TWh '[2020']]]*1000 -> 2288704.2 | G11: =IF(Table79[[#This Row],[Mil m3 '[2020']]]>0,Table79[[#This Row],[Mrd m3 '[2020']2]],Table79[[#This Row],[Mrd m3 '[2020']]])*9.77 -> 2288.7042
A12: JS | B12: Japan & South Korea | C12: 0 | E12: =Table79[[#This Row],[Mil m3 '[2020']]]/1000 -> 0 | F12: =Table79[[#This Row],[TWh '[2020']]]*1000 -> 0 | G12: =IF(Table79[[#This Row],[Mil m3 '[2020']]]>0,Table79[[#This Row],[Mrd m3 '[2020']2]],Table79[[#This Row],[Mrd m3 '[2020']]])*9.77 -> 0
A13: IN | B13: India | C13: 31.585489 | E13: =Table79[[#This Row],[Mil m3 '[2020']]]/1000 -> 0 | F13: =Table79[[#This Row],[TWh '[2020']]]*1000 -> 308590.22 | G13: =IF(Table79[[#This Row],[Mil m3 '[2020']]]>0,Table79[[#This Row],[Mrd m3 '[2020']2]],Table79[[#This Row],[Mrd m3 '[2020']]])*9.77 -> 308.59022
A14: AS | B14: Asia | C14: =691.83903700697-C13-C11-C10-C12-C17 -> 128.9168 | E14: =Table79[[#This Row],[Mil m3 '[2020']]]/1000 -> 0 | F14: =Table79[[#This Row],[TWh '[2020']]]*1000 -> 1259517.2 | G14: =IF(Table79[[#This Row],[Mil m3 '[2020']]]>0,Table79[[#This Row],[Mrd m3 '[2020']2]],Table79[[#This Row],[Mrd m3 '[2020']]])*9.77 -> 1259.5172
A15: CR | B15: Caspian Region | C15: =773.5530598751-586.382199872419 -> 187.17086 | E15: =Table79[[#This Row],[Mil m3 '[2020']]]/1000 -> 0 | F15: =Table79[[#This Row],[TWh '[2020']]]*1000 -> 1828659.3 | G15: =IF(Table79[[#This Row],[Mil m3 '[2020']]]>0,Table79[[#This Row],[Mrd m3 '[2020']2]],Table79[[#This Row],[Mrd m3 '[2020']]])*9.77 -> 1828.6593
A16: EG | B16: Egypt | C16: 57.100413 | E16: =Table79[[#This Row],[Mil m3 '[2020']]]/1000 -> 0 | F16: =Table79[[#This Row],[TWh '[2020']]]*1000 -> 557871.04 | G16: =IF(Table79[[#This Row],[Mil m3 '[2020']]]>0,Table79[[#This Row],[Mrd m3 '[2020']2]],Table79[[#This Row],[Mrd m3 '[2020']]])*9.77 -> 557.87104
A17: IM | B17: Indonesia & Malaysia | C17: =64.2640381356325+81.074134147023 -> 145.33817 | E17: =Table79[[#This Row],[Mil m3 '[2020']]]/1000 -> 0 | F17: =Table79[[#This Row],[TWh '[2020']]]*1000 -> 1419953.9 | G17: =IF(Table79[[#This Row],[Mil m3 '[2020']]]>0,Table79[[#This Row],[Mrd m3 '[2020']2]],Table79[[#This Row],[Mrd m3 '[2020']]])*9.77 -> 1419.9539
A20: https://www.energyinst.org/statistical-review
A21: https://www.statista.com/statistics/1538667/natural-gas-production-in-morocco-by-field/ | B21: for Morroco

Sheet nodes_gas_prod_europe_2035_SP
A1: Country | B1: Long_name | C1: Mrd m3 [2035] SP | D1: Mil m3 EU [2024] | E1: Mrd m3 EU [2020] | F1: GWh [2020] | G1: TWh [2020] | M1: From | N1: To
A2: AL | B2: Albania | C2: =$J$6*(D2/$K$6) -> 0.047470068 | D2: 527.10127 | F2: =Table2620[[#This Row],[TWh '[2020']]]*1000 -> 463.78257 | G2: =(Table2620[[#This Row],[Mrd m3 '[2035'] SP]])*9.77 -> 0.46378257 | J2: _Prod | M2: =_xlfn.CONCAT(A2,$J$2) -> AL_Prod | N2: =Table2620[[#This Row],[Country]] -> AL
A3: DZ | B3: Algeria | C3: =298*(101.54375/nodes_gas_prod_world_2035!$E$8) -> 119.29857 | D3: 992082.44 | F3: =Table2620[[#This Row],[TWh '[2020']]]*1000 -> 1165547.1 | G3: =(Table2620[[#This Row],[Mrd m3 '[2035'] SP]])*9.77 -> 1165.5471 | M3: =_xlfn.CONCAT(A3,$J$2) -> DZ_Prod | N3: =Table2620[[#This Row],[Country]] -> DZ
A4: AT | B4: Austria | C4: =$J$5*(D4/$K$5) -> 0.44373917 | D4: 5354.6634 | F4: =Table2620[[#This Row],[TWh '[2020']]]*1000 -> 4335.3317 | G4: =(Table2620[[#This Row],[Mrd m3 '[2035'] SP]])*9.77 -> 4.3353317 | J4: Stated Policy | K4: 2024 | M4: =_xlfn.CONCAT(A4,$J$2) -> AT_Prod | N4: =Table2620[[#This Row],[Country]] -> AT
A5: BY | B5: Belarus | C5: =$J$6*(D5/$K$6) -> 0 | D5: 0 | F5: =Table2620[[#This Row],[TWh '[2020']]]*1000 -> 0 | G5: =(Table2620[[#This Row],[Mrd m3 '[2035'] SP]])*9.77 -> 0 | I5: EU | J5: 29 | K5: =D4+D6+D8+D9+D10+D11+D12+D13+D14+D15+D16+D17+D18+D19+D20+D22+D23+D25+D28+D29+D30+D34+D35+D42 -> 349947.11 | M5: =_xlfn.CONCAT(A5,$J$2) -> BY_Prod | N5: =Table2620[[#This Row],[Country]] -> BY
A6: BE | B6: Belgium | C6: =$J$5*(D6/$K$5) -> 0.01214455 | D6: 146.55 | F6: =Table2620[[#This Row],[TWh '[2020']]]*1000 -> 118.65225 | G6: =(Table2620[[#This Row],[Mrd m3 '[2035'] SP]])*9.77 -> 0.11865225 | I6: non EU | J6: =181-J5 -> 152 | K6: =D2+D5+D7+D24+D26+D27+D32+D33+D36+D38+D39+D40 -> 1687787.6 | M6: =_xlfn.CONCAT(A6,$J$2) -> BE_Prod | N6: =Table2620[[#This Row],[Country]] -> BE
A7: BA | B7: Bosnia and Herzegovina | C7: =$J$6*(D7/$K$6) -> 0 | D7: 0 | F7: =Table2620[[#This Row],[TWh '[2020']]]*1000 -> 0 | G7: =(Table2620[[#This Row],[Mrd m3 '[2035'] SP]])*9.77 -> 0 | M7: =_xlfn.CONCAT(A7,$J$2) -> BA_Prod | N7: =Table2620[[#This Row],[Country]] -> BA
A8: BG | B8: Bulgaria | C8: =$J$5*(D8/$K$5) -> 0.0065904423 | D8: 79.5278 | F8: =Table2620[[#This Row],[TWh '[2020']]]*1000 -> 64.388621 | G8: =(Table2620[[#This Row],[Mrd m3 '[2035'] SP]])*9.77 -> 0.064388621 | M8: =_xlfn.CONCAT(A8,$J$2) -> BG_Prod | N8: =Table2620[[#This Row],[Country]] -> BG
A9: HR | B9: Croatia | C9: =$J$5*(D9/$K$5) -> 0.61054699 | D9: 7367.557 | F9: =Table2620[[#This Row],[TWh '[2020']]]*1000 -> 5965.0441 | G9: =(Table2620[[#This Row],[Mrd m3 '[2035'] SP]])*9.77 -> 5.9650441 | M9: =_xlfn.CONCAT(A9,$J$2) -> HR_Prod | N9: =Table2620[[#This Row],[Country]] -> HR
A10: CZ | B10: Czech Republic | C10: =$J$5*(D10/$K$5) -> 0.15097214 | D10: 1821.8021 | F10: =Table2620[[#This Row],[TWh '[2020']]]*1000 -> 1474.9978 | G10: =(Table2620[[#This Row],[Mrd m3 '[2035'] SP]])*9.77 -> 1.4749978 | M10: =_xlfn.CONCAT(A10,$J$2) -> CZ_Prod | N10: =Table2620[[#This Row],[Country]] -> CZ
A11: DK | B11: Denmark | C11: =$J$5*(D11/$K$5) -> 1.4585361 | D11: 17600.362 | F11: =Table2620[[#This Row],[TWh '[2020']]]*1000 -> 14249.898 | G11: =(Table2620[[#This Row],[Mrd m3 '[2035'] SP]])*9.77 -> 14.249898 | M11: =_xlfn.CONCAT(A11,$J$2) -> DK_Prod | N11: =Table2620[[#This Row],[Country]] -> DK
A12: EE | B12: Estonia | C12: =$J$5*(D12/$K$5) -> 0 | D12: 0 | F12: =Table2620[[#This Row],[TWh '[2020']]]*1000 -> 0 | G12: =(Table2620[[#This Row],[Mrd m3 '[2035'] SP]])*9.77 -> 0 | M12: =_xlfn.CONCAT(A12,$J$2) -> EE_Prod | N12: =Table2620[[#This Row],[Country]] -> EE
A13: FI | B13: Finland | C13: =$J$5*(D13/$K$5) -> 0 | D13: 0 | F13: =Table2620[[#This Row],[TWh '[2020']]]*1000 -> 0 | G13: =(Table2620[[#This Row],[Mrd m3 '[2035'] SP]])*9.77 -> 0 | M13: =_xlfn.CONCAT(A13,$J$2) -> FI_Prod | N13: =Table2620[[#This Row],[Country]] -> FI
A14: FR | B14: France | C14: =$J$5*(D14/$K$5) -> 0.010020063 | D14: 120.91352 | F14: =Table2620[[#This Row],[TWh '[2020']]]*1000 -> 97.896016 | G14: =(Table2620[[#This Row],[Mrd m3 '[2035'] SP]])*9.77 -> 0.097896016 | M14: =_xlfn.CONCAT(A14,$J$2) -> FR_Prod | N14: =Table2620[[#This Row],[Country]] -> FR
A15: DE | B15: Germany | C15: =$J$5*(D15/$K$5) -> 3.1357227 | D15: 37839.21 | F15: =Table2620[[#This Row],[TWh '[2020']]]*1000 -> 30636.011 | G15: =(Table2620[[#This Row],[Mrd m3 '[2035'] SP]])*9.77 -> 30.636011 | M15: =_xlfn.CONCAT(A15,$J$2) -> DE_Prod | N15: =Table2620[[#This Row],[Country]] -> DE
A16: EL | B16: Greece | C16: =$J$5*(D16/$K$5) -> 0.0016119866 | D16: 19.45207 | F16: =Table2620[[#This Row],[TWh '[2020']]]*1000 -> 15.749109 | G16: =(Table2620[[#This Row],[Mrd m3 '[2035'] SP]])*9.77 -> 0.015749109 | M16: =_xlfn.CONCAT(A16,$J$2) -> EL_Prod | N16: =Table2620[[#This Row],[Country]] -> EL
A17: HU | B17: Hungary | C17: =$J$5*(D17/$K$5) -> 1.3956516 | D17: 16841.526 | F17: =Table2620[[#This Row],[TWh '[2020']]]*1000 -> 13635.517 | G17: =(Table2620[[#This Row],[Mrd m3 '[2035'] SP]])*9.77 -> 13.635517 | M17: =_xlfn.CONCAT(A17,$J$2) -> HU_Prod | N17: =Table2620[[#This Row],[Country]] -> HU
