Workbook

Sheet LNG_Cost_Params
A1: type | B1: Cost
A2: cost per GWh and km | B2: =LNG_Cost_raw!B33 -> 0.080496656
A3: liquefication per GWh | B3: =LNG_Cost_raw!B34 -> 8530.3537
A4: regasification per GWh | B4: =LNG_Cost_raw!B35 -> 2217.892
A5: Cost Panama per GWh | B5: =LNG_Cost_raw!B36 -> 1000
A6: Cost Suez per GWh | B6: =LNG_Cost_raw!B37 -> 950
A7: cost pipe per GWh and km | B7: =LNG_Cost_raw!B39 -> 1.7060707

Sheet LNG_Cost_raw
A1: Euro to Dollar | B1: 1.14 | C1: Euro/Dollar | G1: https://www.sciencedirect.com/science/article/pii/S0360544224013859#b72
G2: https://link.springer.com/chapter/10.1007/978-3-030-86884-0_2
A3: Vessel size | B3: 160000 | C3: m3
A4: Vessel cost | B4: 69340 | C4: Dollar/day
A5: ship speed | B5: 17 | C5: knots/hour
A6: km/h to knots | B6: 1.852 | C6: km/h/knot
G7: Adjust!!! | H7: https://www.suezcanal.gov.eg/English/Navigation/Tolls/Pages/TollsTable.aspx
A8: Fee Suez | B8: 1000000 | C8: Dolar/ship | G8: Adjust!!! | H8: https://pancanal.com/wp-content/uploads/2021/08/Post-publishing-Maritime-Tariffs-2025-2.pdf
A9: Fee Panama | B9: 950000 | C9: Dolar/ship
A11: Pipeline cost upper | B11: 2.5 | C11: Dollar/MMBtu/1000km
A12: Pipeline cost lower | B12: 0.5 | C12: Dollar/MMBtu/1000km
A14: Liquification cost upper | B14: 3 | C14: Dollar/MMBtu
A15: Liquification cost lower | B15: 2 | C15: Dollar/MMBtu
A16: Regasification cost upper | B16: 1 | C16: Dollar/MMBtu
A17: Regasification cost lower | B17: 0.3 | C17: Dollar/MMBtu
A19: MMBtu to GWh | B19: 0.00029307108 | C19: GWH/MMBtu
A20: Mt LNG to GWh | B20: 14447.205 | C20: GWh / Mt LNG
A21: energy density | B21: 6250 | C21: kWh/m3 LNG
A22: energy density | B22: 50 | C22: MJ/kg
A23: energy density | B23: 450 | C23: kg/m3
A24: energy density | B24: =B22*B23 -> 22500 | C24: MJ/m3
A25: energy density | B25: =B24/B26 -> 0.00625 | C25: GWh/m3
B26: 3600000 | C26: MJ/GWh
A28: Load per vessel | B28: =B3*B25 -> 1000 | C28: GWh / vessel
A29: ship speed | B29: =B5*B6 -> 31.484 | C29: kmh
A30: distance per day | B30: =B29*24 -> 755.616 | C30: km/day
A31: cost per energy | B31: =(B4/B1)/B28 -> 60.824561 | C31: Euro per day/GWh
A33: cost per energy and km | B33: =B31/B30 -> 0.080496656 | C33: Euro/GWh/km
A34: loading | B34: =1/B19*AVERAGE(B14:B15) -> 8530.3537 | C34: Euro/GWh
A35: regasification | B35: =1/B19*AVERAGE(B16:B17) -> 2217.892 | C35: Euro/GWh
A36: Cost Panama | B36: =B8/$B$28 -> 1000 | C36: Euro/GWh
A37: Cost Suez | B37: =B9/$B$28 -> 950 | C37: Euro/GWh
A39: pipeline transport cost | B39: =B12/1000/B19 -> 1.7060707 | C39: Euro/GWh/km

Sheet Production_Cost_Nodes
A1: Node | B1: Cost
A2: AL_Prod | B2: =Production_Cost_Raw!$C$11 -> 19449.206
A3: DZ_Prod | B3: =Production_Cost_Raw!C2 -> 19060.222
A4: AT_Prod | B4: =Production_Cost_Raw!$C$11 -> 19449.206
A5: BY_Prod | B5: =Production_Cost_Raw!$C$11 -> 19449.206
A6: BE_Prod | B6: =Production_Cost_Raw!$C$11 -> 19449.206
A7: BA_Prod | B7: =Production_Cost_Raw!$C$11 -> 19449.206
A8: BG_Prod | B8: =Production_Cost_Raw!$C$11 -> 19449.206
A9: HR_Prod | B9: =Production_Cost_Raw!$C$11 -> 19449.206
A10: CZ_Prod | B10: =Production_Cost_Raw!$C$11 -> 19449.206
A11: DK_Prod | B11: =Production_Cost_Raw!$C$11 -> 19449.206
A12: EE_Prod | B12: =Production_Cost_Raw!$C$11 -> 19449.206
A13: FI_Prod | B13: =Production_Cost_Raw!$C$11 -> 19449.206
A14: FR_Prod | B14: =Production_Cost_Raw!$C$11 -> 19449.206
A15: DE_Prod | B15: =Production_Cost_Raw!$C$11 -> 19449.206
... A20: LV_Prod | B20: =Production_Cost_Raw!$C$11 -> 19449.206
A21: LY_Prod | B21: =Production_Cost_Raw!$C$8 -> 17504.286
A22: LT_Prod | B22: =Production_Cost_Raw!$C$11 -> 19449.206
A23: LU_Prod | B23: =Production_Cost_Raw!$C$11 -> 19449.206
A24: MD_Prod | B24: =Production_Cost_Raw!$C$11 -> 19449.206
A25: NL_Prod | B25: =Production_Cost_Raw!$C$11 -> 19449.206
A26: MK_Prod | B26: =Production_Cost_Raw!$C$11 -> 19449.206
A27: NO_Prod | B27: =Production_Cost_Raw!$C$11 -> 19449.206
A28: PL_Prod | B28: =Production_Cost_Raw!$C$11 -> 19449.206
A29: PT_Prod | B29: =Production_Cost_Raw!$C$11 -> 19449.206
A30: RO_Prod | B30: =Production_Cost_Raw!$C$11 -> 19449.206
A31: RU_Prod | B31: =Production_Cost_Raw!C14 -> 17504.286
A32: RS_Prod | B32: =Production_Cost_Raw!$C$11 -> 19449.206
A33: SK_Prod | B33: =Production_Cost_Raw!$C$11 -> 19449.206
A34: SI_Prod | B34: =Production_Cost_Raw!$C$11 -> 19449.206
A35: CH_Prod | B35: =Production_Cost_Raw!$C$11 -> 19449.206
A36: TN_Prod | B36: =Production_Cost_Raw!$C$8 -> 17504.286
A37: TR_Prod | B37: =Production_Cost_Raw!$C$11 -> 19449.206
A38: UK_Prod | B38: =Production_Cost_Raw!$C$11 -> 19449.206
A39: UA_Prod | B39: =Production_Cost_Raw!$C$11 -> 19449.206
A40: ES_Prod | B40: =Production_Cost_Raw!$C$11 -> 19449.206
A41: USA_Prod | B41: =Production_Cost_Raw!C16 -> 22950.064
A42: CM_Prod | B42: =Production_Cost_Raw!C9 -> 23339.048
A43: SA_Prod | B43: =Production_Cost_Raw!C9 -> 23339.048
A44: TT_Prod | B44: =Production_Cost_Raw!C15 -> 19838.191
...

Sheet Production_Cost_Raw
A1: Exporter | B1: Break even cost in $/MMBtu | C1: Euro/GWh | D1: Liquefication cap in billions MMBtu/year | G1: https://www.sciencedirect.com/science/article/pii/S0360544224013859#appA
A2: Algeria | B2: 4.9 | C2: =B2*LNG_Cost_raw!$B$1/LNG_Cost_raw!$B$19 -> 19060.222 | D2: 0.72
A3: Australia | B3: 7.5 | C3: =B3*LNG_Cost_raw!$B$1/LNG_Cost_raw!$B$19 -> 29173.81 | D3: 5.04
A4: Indonesia | B4: 6 | C4: =B4*LNG_Cost_raw!$B$1/LNG_Cost_raw!$B$19 -> 23339.048 | D4: 1.357
A5: Malaysia | B5: 6 | C5: =B5*LNG_Cost_raw!$B$1/LNG_Cost_raw!$B$19 -> 23339.048 | D5: 1.548
A6: Nigeria | B6: 4.1 | C6: =B6*LNG_Cost_raw!$B$1/LNG_Cost_raw!$B$19 -> 15948.349 | D6: 2.52
A7: Oman | B7: 3.7 | C7: =B7*LNG_Cost_raw!$B$1/LNG_Cost_raw!$B$19 -> 14392.413 | D7: 0.571
A8: Other Africa | B8: 4.5 | C8: =B8*LNG_Cost_raw!$B$1/LNG_Cost_raw!$B$19 -> 17504.286 | D8: 3.6
A9: Other Americas | B9: 6 | C9: =B9*LNG_Cost_raw!$B$1/LNG_Cost_raw!$B$19 -> 23339.048 | D9: 2.16
A10: Other Asia Pacific | B10: 8.4 | C10: =B10*LNG_Cost_raw!$B$1/LNG_Cost_raw!$B$19 -> 32674.667 | D10: 0.752
A11: Other Europe | B11: 5 | C11: =B11*LNG_Cost_raw!$B$1/LNG_Cost_raw!$B$19 -> 19449.206 | D11: 0.31
A12: Other Middle East | B12: 3 | C12: =B12*LNG_Cost_raw!$B$1/LNG_Cost_raw!$B$19 -> 11669.524 | D12: 0.277
A13: Qatar | B13: 2.4 | C13: =B13*LNG_Cost_raw!$B$1/LNG_Cost_raw!$B$19 -> 9335.6191 | D13: 6.255
... A16: USA | B16: 5.9 | C16: =B16*LNG_Cost_raw!$B$1/LNG_Cost_raw!$B$19 -> 22950.064 | D16: 7.92
