Workbook
Name Beschriftung: OFFSET([1]Daten!$B$10,0,0,COUNTA([1]Daten!$B$10:$B$24),-1)
Name Beschriftung2: OFFSET(#REF!,0,0,COUNTA(#REF!),-1)
Name CRF_CountryName: [2]Sheet1!$C$4
Name CRF_InventoryYear: [2]Sheet1!$C$6
Name CRF_Submission: [2]Sheet1!$C$30
Name CRF_Table10s5_Main1: #REF!
Name CRF_Table10s5_Main2: #REF!
Name CRF_Table3.A_D_Doc: '[2]Table3.A-D'!#REF!
Name Daten01: OFFSET([1]Daten!$C$10,0,0,COUNTA([1]Daten!$C$10:$C$24),-1)
Name Daten02: OFFSET([1]Daten!$D$10,0,0,COUNTA([1]Daten!$D$10:$D$24),-1)
Name Daten03: OFFSET([1]Daten!$E$10,0,0,COUNTA([1]Daten!$E$10:$E$24),-1)
Name Daten04: OFFSET([1]Daten!$F$10,0,0,COUNTA([1]Daten!$F$10:$F$24),-1)
Name Daten05: OFFSET([1]Daten!$G$10,0,0,COUNTA([1]Daten!$G$10:$G$24),-1)
Name Daten06: OFFSET([1]Daten!$H$10,0,0,COUNTA([1]Daten!$H$10:$H$24),-1)
Name Daten07: OFFSET([1]Daten!$I$10,0,0,COUNTA([1]Daten!$I$10:$I$24),-1)
Name Daten08: OFFSET([1]Daten!$J$10,0,0,COUNTA([1]Daten!$J$10:$J$24),-1)
Name Daten09: OFFSET([1]Daten!$K$10,0,0,COUNTA([1]Daten!$K$10:$K$24),-1)
Name Daten10: OFFSET([1]Daten!$L$10,0,0,COUNTA([1]Daten!$L$10:$L$24),-1)

Sheet Overview
A1: Overview Input Data for Optimization
B4: 2045 | D4: 2045
B5: Peak hour | D5: Annual Demand | E5: Percentage | J5: TXT | K5: Input
A6: Industry | B6: MWh/h | D6: TWh/a | F6: Äquivalence in dena | J6: TXT | K6: Referenced from other sheet
A7: Refineries | B7: =Refineries!B6 -> 0 | D7: =E71 -> 0 | F7: - | J7: TXT | K7: Hardcoded data
A8: Chemicals | B8: =Chemicals!B6 -> 9589 | D8: =SUM(E69,E70) -> 82 | E8: =D8/$D$28 -> 0.17864924 | F8: Chemie
A9: Steel | B9: =Steel!B6 -> 8562 | D9: =SUM(E67,E68) -> 75 | E9: =D9/$D$28 -> 0.16339869 | F9: Stahl & EisenMetalle
A10: Paper | B10: =Paper!B6 -> 223 | D10: =E64 -> 2 | E10: =D10/$D$28 -> 0.0043572985 | F10: Papier
A11: Mineral Processing | B11: =Mineral_Processing!B6 -> 1256 | D11: =E62 -> 11 | E11: =D11/$D$28 -> 0.023965142 | F11: Steine & Erden
A12: Metal Processing | B12: =Metal_Processing!B6 -> 456 | D12: =E65 -> 4 | E12: =D12/$D$28 -> 0.0087145969 | F12: Nichteisenmetalle
A13: Non Metallic Minerals | B13: =Non_Metallic_Minerals!B6 -> 226 | D13: =E66 -> 2 | E13: =D13/$D$28 -> 0.0043572985 | F13: Glas & Keramik
A14: Other Industry | B14: =Other_Industry!B4 -> 1598 | D14: =E63 -> 14 | E14: =D14/$D$28 -> 0.030501089 | F14: Sonstige Industrie
D15: =SUM(D7:D14) -> 190 | E15: =D15/$D$28 -> 0.41394336
A16: Heat & Power
A17: Residential Heat | B17: ='Residential Heat '!B7 -> 21603 | D17: =F81 -> 79 | E17: =D17/$D$28 -> 0.17211329
A18: District Heat & Power | B18: ='District Heat'!B8 -> 36098 | D18: =F121+F97+39 -> 132 | E18: =D18/$D$28 -> 0.2875817
D19: =SUM(D17:D18) -> 211 | E19: =D19/$D$28 -> 0.45969499
A20: Mobility
A21: Passenger | B21: =Passenger!B7 -> 2062 | D21: =F47 -> 6 | E21: =D21/$D$28 -> 0.013071895
A22: Air | B22: =Air!B6 -> 342 | D22: =F48 -> 3 | E22: =D22/$D$28 -> 0.0065359477
A23: Train | B23: =Train!B5 -> 348 | D23: =F49 -> 3 | E23: =D23/$D$28 -> 0.0065359477
A24: Public | B24: =Public!B6 -> 199 | D24: =F51 -> 2 | E24: =D24/$D$28 -> 0.0043572985
A25: Long distance | B25: =Trucks!B6 -> 5040 | D25: =SUM(F52:F54) -> 44 | E25: =D25/$D$28 -> 0.095860566
D26: 58 | E26: =D26/$D$28 -> 0.12636166
A28: Demand | B28: =SUM(B7:B25) -> 87602 | D28: =SUM(D7:D25)-D15-D19 -> 459
A30: Storage | B30: =Storage!B3 -> -30627
A32: Production
A33: Domestic Wasserstoffatlas | B33: =Electrolyser_Wasserstoffatlas!B6 -> 5700 | D33: =E146 -> 60
A34: Domestic Industry | B34: =Industry_Electrolyser!B15 -> 5689 | E34: =D33/$D$37 -> 0.13071895
A35: LH2 | B35: ='LH2'!B5 -> 11003 | D35: =E156 -> 96.39 | E35: =D35/$D$37 -> 0.21
A36: IC | B36: =IC!B5 -> 34583 | D36: =E159 -> 302.61 | E36: =D36/$D$37 -> 0.65928105
A37: Supply | B37: =B33+B34+B35+B36 -> 56975 | D37: =SUM(D33:D36) -> 459
A39: Balance | B39: =B28-B37+B30 -> 0
A40: Ratio Demand/Supply | D40: =D28/D37 -> 1
A43: Dena Input Data
A44: Mobility
A45: Abbildung 24: Wasserstoffbedarf nach Verkehrsträgern
A46: TWh | B46: 2018 | C46: 2030 | D46: 2035 | E46: 2040 | F46: 2045 | G46: 2050
A47: PKW | B47: 0 | C47: 0 | D47: 2 | E47: 4 | F47: 6 | G47: 7
A48: Luft | B48: 0 | C48: 0 | D48: 1 | E48: 2 | F48: 3 | G48: 3
...

Sheet Storage
A2: Balance between Demand and Supply in Peak Load Hour [MWh/h] | B2: =Overview!B37-Overview!B28 -> -30627 | C2: Negative - Supply, Positive - Demand | E2: TXT | F2: Input
A3: Balance Rounded | B3: =Table22[[#Totals],[Peak Load '[MWh/h']]] -> -30627 | E3: TXT | F3: Calculation
E4: TXT | F4: Referenced from other sheet
A5: Manually manipulated cells - Roundup | B5: 0 | E5: TXT | F5: Hardcoded data
A8: Country | B8: Concatenate | C8: Country Code | D8: Company code | E8: Facility code | F8: Operator | G8: geometry | H8: Latitude | I8: Longitude | J8: Facility/Location | K8: Status | L8: Investment | M8: Start-up year | N8: Closing year | O8: Type | P8: Notes | Q8: onshore/ offshore | R8: Working gas (technical) TWh | S8: Working gas TPA TWh | T8: Working gas no TPA TWh | U8: Injection technical GWh/day | V8: Injection TPA GWh/day | W8: Injection no TPA GWh/day | X8: Withdrawal technical GWh/day | Y8: Withdrawal TPA GWh/day | Z8: Withdrawal no TPA GWh/day | AA8: Access regime | AB8: in number | AC8: in sum | AD8: EU filter | AE8: GIE | AF8: Normiert Injection | AG8: Normiert Withdrawal2 | AH8: Peak Load [MWh/h] | AI8: Manually Roundup to balance
A9: Germany | B9: DE0101 | C9: DE | D9: 1 | E9: 1 | F9: astora | G9: POINT (7.40786 53.25724) | H9: 53.25724 | I9: 7.40786 | J9: Jemgum | K9: operational | L9: existing | M9: 2013 | O9: Salt cavern | Q9: Onshore | R9: =S9+T9 -> 6.86 | S9: 6.86 | U9: =V9+W9 -> 99.9 | V9: 99.9 | X9: =Y9+Z9 -> 145.8 | Y9: 145.8 | AA9: TPA | AB9: y | AC9: y | AD9: YES | AE9: y | AF9: =Table22[[#This Row],[Injection technical GWh/day]]/Table22[[#Totals],[Injection technical GWh/day]] -> 0.04333433 | AG9: =Table22[[#This Row],[Withdrawal technical GWh/day]]/Table22[[#Totals],[Withdrawal technical GWh/day]] -> 0.031378962 | AH9: =ROUND(IF($B$2>=0,$B$2*Table22[[#This Row],[Normiert Injection]],$B$2*Table22[[#This Row],[Normiert Withdrawal2]]),0) -> -961
A10: Germany | B10: DE0102 | C10: DE | D10: 1 | E10: 2 | F10: astora | G10: POINT (7.40786 53.25724) | H10: 53.25724 | I10: 7.40786 | J10: Jemgum | K10: operational | L10: extension | M10: 2018 | O10: Salt cavern | Q10: Onshore | R10: =S10+T10 -> 1.43 | S10: =8.29-S9 -> 1.43 | U10: =V10+W10 -> 36.23 | V10: =136.13-V9 -> 36.23 | X10: =Y10+Z10 -> 63.45 | Y10: =209.25-Y9 -> 63.45 | AA10: TPA | AB10: n | AC10: y | AD10: YES | AE10: y | AF10: =Table22[[#This Row],[Injection technical GWh/day]]/Table22[[#Totals],[Injection technical GWh/day]] -> 0.015715743 | AG10: =Table22[[#This Row],[Withdrawal technical GWh/day]]/Table22[[#Totals],[Withdrawal technical GWh/day]] -> 0.013655659 | AH10: =ROUND(IF($B$2>=0,$B$2*Table22[[#This Row],[Normiert Injection]],$B$2*Table22[[#This Row],[Normiert Withdrawal2]]),0) -> -418
A11: Germany | B11: =C11&TEXT(D11,"0#")&TEXT(E11,"0#") -> DE0301 | C11: DE | D11: 3 | E11: 1 | F11: Crystal, Friedeburger Speicherbetriebsgesellschaft | G11: POINT (7.91209 53.46106) | H11: 53.746106 | I11: 7.91209 | J11: Etzel Crystal | K11: operational | L11: existing | M11: 2012 | O11: Salt cavern | Q11: Onshore | R11: =S11+T11 -> 2.421 | S11: 2.421 | U11: =V11+W11 -> 54 | V11: =2.25*24 -> 54 | X11: =Y11+Z11 -> 94.08 | Y11: =3.92*24 -> 94.08 | AA11: TPA | AB11: y | AC11: y | AD11: YES | AF11: =Table22[[#This Row],[Injection technical GWh/day]]/Table22[[#Totals],[Injection technical GWh/day]] -> 0.023423962 | AG11: =Table22[[#This Row],[Withdrawal technical GWh/day]]/Table22[[#Totals],[Withdrawal technical GWh/day]] -> 0.020247824 | AH11: =ROUND(IF($B$2>=0,$B$2*Table22[[#This Row],[Normiert Injection]],$B$2*Table22[[#This Row],[Normiert Withdrawal2]]),0) -> -620
A12: Germany | B12: =C12&TEXT(D12,"0#")&TEXT(E12,"0#") -> DE0501 | C12: DE | D12: 5 | E12: 1 | F12: EKB (Etzel-Kavernenbetriebsgesellschaft) | G12: POINT (7.91209 53.46106) | H12: 53.46106 | I12: 7.91209 | J12: Etzel EKB | K12: operational | L12: existing | M12: 2012 | O12: Salt cavern | Q12: Onshore | R12: =S12+T12 -> 11.202 | S12: 11.202 | U12: =V12+W12 -> 122.04 | V12: 122.04 | X12: =Y12+Z12 -> 216.96 | Y12: 216.96 | AA12: TPA | AB12: y | AC12: y | AD12: YES | AF12: =Table22[[#This Row],[Injection technical GWh/day]]/Table22[[#Totals],[Injection technical GWh/day]] -> 0.052938154 | AG12: =Table22[[#This Row],[Withdrawal technical GWh/day]]/Table22[[#Totals],[Withdrawal technical GWh/day]] -> 0.046693961 | AH12: =ROUND(IF($B$2>=0,$B$2*Table22[[#This Row],[Normiert Injection]],$B$2*Table22[[#This Row],[Normiert Withdrawal2]]),0) -> -1430
A13: Germany | B13: =C13&TEXT(D13,"0#")&TEXT(E13,"0#") -> DE0601 | C13: DE | D13: 6 | E13: 1 | F13: EnBW Energie Baden-Württemberg | G13: POINT (7.91209 53.46106) | H13: 53.46106 | I13: 7.91209 | J13: Etzel | K13: operational | L13: existing | M13: 2012 | O13: Salt cavern | Q13: Onshore | R13: =S13+T13 -> 2.32 | S13: 2.32 | U13: =V13+W13 -> 54 | V13: =2250*24/1000 -> 54 | X13: =Y13+Z13 -> 94.08 | Y13: =3920*24/1000 -> 94.08 | AA13: TPA | AB13: y | AC13: y | AD13: YES | AF13: =Table22[[#This Row],[Injection technical GWh/day]]/Table22[[#Totals],[Injection technical GWh/day]] -> 0.023423962 | AG13: =Table22[[#This Row],[Withdrawal technical GWh/day]]/Table22[[#Totals],[Withdrawal technical GWh/day]] -> 0.020247824 | AH13: =ROUND(IF($B$2>=0,$B$2*Table22[[#This Row],[Normiert Injection]],$B$2*Table22[[#This Row],[Normiert Withdrawal2]]),0) -> -620
A14: Germany | B14: =C14&TEXT(D14,"0#")&TEXT(E14,"0#") -> DE0701 | C14: DE | D14: 7 | E14: 1 | F14: Eneco | G14: POINT (7.02868 52.17597) | H14: 52.17597 | I14: 7.02868 | J14: Epe Eneco | K14: operational | L14: existing | M14: 2012 | O14: Salt cavern | Q14: Onshore | R14: =S14+T14 -> 1.4352 | S14: 1.4352 | U14: =V14+W14 -> 46.8 | V14: 46.8 | X14: =Y14+Z14 -> 93.6 | Y14: 93.6 | AA14: TPA | AB14: y | AC14: y | AD14: YES | AF14: =Table22[[#This Row],[Injection technical GWh/day]]/Table22[[#Totals],[Injection technical GWh/day]] -> 0.020300767 | AG14: =Table22[[#This Row],[Withdrawal technical GWh/day]]/Table22[[#Totals],[Withdrawal technical GWh/day]] -> 0.020144519 | AH14: =ROUND(IF($B$2>=0,$B$2*Table22[[#This Row],[Normiert Injection]],$B$2*Table22[[#This Row],[Normiert Withdrawal2]]),0) -> -617
A15: Germany | B15: =C15&TEXT(D15,"0#")&TEXT(E15,"0#") -> DE0901 | C15: DE | D15: 9 | E15: 1 | F15: Erdgasspeicher Peissen | G15: POINT (11.75922 51.75025) | H15: 51.75025 | I15: 11.75922 | J15: Katharina | K15: operational | L15: existing | M15: 2012 | O15: Salt cavern | Q15: Onshore | R15: =S15+T15 -> 5.4315366 | S15: =484.31*11.215/1000 -> 5.4315366 | U15: =V15+W16 -> 135.04 | V15: 135.04 | X15: =Y15+Z16 -> 270.07 | Y15: 270.07 | AA15: TPA | AB15: y | AC15: y | AD15: YES | AF15: =Table22[[#This Row],[Injection technical GWh/day]]/Table22[[#Totals],[Injection technical GWh/day]] -> 0.058577256 | AG15: =Table22[[#This Row],[Withdrawal technical GWh/day]]/Table22[[#Totals],[Withdrawal technical GWh/day]] -> 0.058124253 | AH15: =ROUND(IF($B$2>=0,$B$2*Table22[[#This Row],[Normiert Injection]],$B$2*Table22[[#This Row],[Normiert Withdrawal2]]),0) -> -1780
A16: =A15 -> Germany | B16: =C16&TEXT(D16,"0#")&TEXT(E16,"0#") -> DE0902 | C16: DE | D16: 9 | E16: 2 | F16: =F15 -> Erdgasspeicher Peissen | G16: POINT (11.75922 51.75025) | H16: 51.75025 | I16: 11.75922 | J16: =J15 -> Katharina | K16: planned | L16: extension | M16: 2025 | O16: =O15 -> Salt cavern | Q16: Onshore | R16: =S16+T16 -> 1.2974634 | S16: =600*11.215/1000-S15 -> 1.2974634 | AA16: TPA | AB16: n | AC16: y | AD16: YES | AF16: =Table22[[#This Row],[Injection technical GWh/day]]/Table22[[#Totals],[Injection technical GWh/day]] -> 0 | AG16: =Table22[[#This Row],[Withdrawal technical GWh/day]]/Table22[[#Totals],[Withdrawal technical GWh/day]] -> 0 | AH16: =ROUND(IF($B$2>=0,$B$2*Table22[[#This Row],[Normiert Injection]],$B$2*Table22[[#This Row],[Normiert Withdrawal2]]),0) -> 0
A17: Germany | B17: =C17&TEXT(D17,"0#")&TEXT(E17,"0#") -> DE1001 | C17: DE | D17: 10 | E17: 1 | F17: EWE Gasspeicher | G17: POINT (7.40786 53.25724) | H17: 53.25724 | I17: 7.40786 | J17: EWE-Zone L | K17: operational | L17: existing | M17: 1972 | O17: Salt cavern | Q17: Onshore | R17: =S17+T17 -> 9.1 | S17: 9.1 | U17: =V17+W17 -> 98.78 | V17: 98.78 | X17: =Y17+Z17 -> 258.72 | Y17: 258.72 | AA17: TPA | AB17: y | AC17: y | AD17: YES | AF17: =Table22[[#This Row],[Injection technical GWh/day]]/Table22[[#Totals],[Injection technical GWh/day]] -> 0.042848499 | AG17: =Table22[[#This Row],[Withdrawal technical GWh/day]]/Table22[[#Totals],[Withdrawal technical GWh/day]] -> 0.055681515 | AH17: =ROUND(IF($B$2>=0,$B$2*Table22[[#This Row],[Normiert Injection]],$B$2*Table22[[#This Row],[Normiert Withdrawal2]]),0) -> -1705
A18: Germany | B18: =C18&TEXT(D18,"0#")&TEXT(E18,"0#") -> DE1009 | C18: DE | D18: 10 | E18: 9 | F18: EWE Gasspeicher | G18: POINT (8.40070 53.19426) | H18: 53.19426 | I18: 8.4007 | J18: EWE H-Gas Zone | K18: operational | L18: existing | O18: Salt cavern | R18: =S18+T18 -> 0.81 | S18: 0.81 | U18: =V18+W18 -> 13.8 | V18: 13.8 | X18: =Y18+Z18 -> 27.6 | Y18: 27.6 | AA18: TPA | AB18: y | AC18: y | AD18: YES | AF18: =Table22[[#This Row],[Injection technical GWh/day]]/Table22[[#Totals],[Injection technical GWh/day]] -> 0.0059861236 | AG18: =Table22[[#This Row],[Withdrawal technical GWh/day]]/Table22[[#Totals],[Withdrawal technical GWh/day]] -> 0.0059400503 | AH18: =ROUND(IF($B$2>=0,$B$2*Table22[[#This Row],[Normiert Injection]],$B$2*Table22[[#This Row],[Normiert Withdrawal2]]),0) -> -182
A19: Germany | B19: =C19&TEXT(D19,"0#")&TEXT(E19,"0#") -> DE1002 | C19: DE | D19: 10 | E19: 2 | F19: EWE Gasspeicher | G19: POINT (7.40786 53.25724) | H19: 53.25724 | I19: 7.40786 | J19: Jemgum H | K19: operational | L19: existing | M19: 2013 | O19: Salt cavern | Q19: Onshore | R19: =S19+T19 -> 3.5 | S19: 3.5 | U19: =V19+W19 -> 55.2 | V19: 55.2 | X19: =Y19+Z19 -> 69 | Y19: 69 | AA19: TPA | AB19: y | AC19: y | AD19: YES | AF19: =Table22[[#This Row],[Injection technical GWh/day]]/Table22[[#Totals],[Injection technical GWh/day]] -> 0.023944494 | AG19: =Table22[[#This Row],[Withdrawal technical GWh/day]]/Table22[[#Totals],[Withdrawal technical GWh/day]] -> 0.014850126 | AH19: =ROUND(IF($B$2>=0,$B$2*Table22[[#This Row],[Normiert Injection]],$B$2*Table22[[#This Row],[Normiert Withdrawal2]]),0) -> -455
A20: Germany | B20: =C20&TEXT(D20,"0#")&TEXT(E20,"0#") -> DE1004 | C20: DE | D20: 10 | E20: 4 | F20: EWE Gasspeicher | G20: POINT (7.40786 53.25724) | H20: 53.25724 | I20: 7.40786 | J20: Nüttermoor H-1 | K20: operational | L20: existing | M20: 1979 | O20: Salt cavern | Q20: Onshore | R20: =S20+T20 -> 1.832 | S20: 1.832 | U20: =V20+W20 -> 48.72 | V20: 48.72 | X20: =Y20+Z20 -> 69.6 | Y20: 69.6 | AA20: TPA | AB20: y | AC20: y | AD20: YES | AF20: =Table22[[#This Row],[Injection technical GWh/day]]/Table22[[#Totals],[Injection technical GWh/day]] -> 0.021133619 | AG20: =Table22[[#This Row],[Withdrawal technical GWh/day]]/Table22[[#Totals],[Withdrawal technical GWh/day]] -> 0.014979257 | AH20: =ROUND(IF($B$2>=0,$B$2*Table22[[#This Row],[Normiert Injection]],$B$2*Table22[[#This Row],[Normiert Withdrawal2]]),0) -> -459
A21: Germany | B21: =C21&TEXT(D21,"0#")&TEXT(E21,"0#") -> DE1005 | C21: DE | D21: 10 | E21: 5 | F21: EWE Gasspeicher | G21: POINT (7.40786 53.25724) | H21: 53.25724 | I21: 7.40786 | J21: Nüttermoor H-2 | K21: operational | L21: existing | M21: 1979 | O21: Salt cavern | Q21: Onshore | R21: =S21+T21 -> 1.955 | S21: 1.955 | U21: =V21+W21 -> 24.84 | V21: 24.84 | X21: =Y21+Z21 -> 49.68 | Y21: 49.68 | AA21: TPA | AB21: y | AC21: y | AD21: YES | AF21: =Table22[[#This Row],[Injection technical GWh/day]]/Table22[[#Totals],[Injection technical GWh/day]] -> 0.010775023 | AG21: =Table22[[#This Row],[Withdrawal technical GWh/day]]/Table22[[#Totals],[Withdrawal technical GWh/day]] -> 0.010692091 | AH21: =ROUND(IF($B$2>=0,$B$2*Table22[[#This Row],[Normiert Injection]],$B$2*Table22[[#This Row],[Normiert Withdrawal2]]),0) -> -327
A22: Germany | B22: =C22&TEXT(D22,"0#")&TEXT(E22,"0#") -> DE1006 | C22: DE | D22: 10 | E22: 6 | F22: EWE Gasspeicher | G22: POINT (7.40786 53.25724) | H22: 53.25724 | I22: 7.40786 | J22: Nüttermoor H-3 | K22: operational | L22: existing | M22: 1979 | O22: Salt cavern | Q22: Onshore | R22: =S22+T22 -> 2.69 | S22: 2.69 | U22: =V22+W22 -> 41.04 | V22: 41.04 | X22: =Y22+Z22 -> 82.08 | Y22: 82.08 | AA22: TPA | AB22: y | AC22: y | AD22: YES | AF22: =Table22[[#This Row],[Injection technical GWh/day]]/Table22[[#Totals],[Injection technical GWh/day]] -> 0.017802211 | AG22: =Table22[[#This Row],[Withdrawal technical GWh/day]]/Table22[[#Totals],[Withdrawal technical GWh/day]] -> 0.017665193 | AH22: =ROUND(IF($B$2>=0,$B$2*Table22[[#This Row],[Normiert Injection]],$B$2*Table22[[#This Row],[Normiert Withdrawal2]]),0) -> -541
A23: Germany | B23: =C23&TEXT(D23,"0#")&TEXT(E23,"0#") -> DE1007 | C23: DE | D23: 10 | E23: 7 | F23: EWE Gasspeicher | G23: POINT (7.40786 53.25724) | H23: 53.25724 | I23: 7.40786 | J23: Nüttermoor L | K23: operational | L23: existing | M23: 1979 | O23: Salt cavern | Q23: Onshore | R23: =S23+T23 -> 0.4303 | S23: 0.4303 | U23: =V23+W23 -> 10.58 | V23: 10.58 | X23: =Y23+Z23 -> 23.52 | Y23: 23.52 | AA23: TPA | AB23: y | AC23: y | AD23: YES | AF23: =Table22[[#This Row],[Injection technical GWh/day]]/Table22[[#Totals],[Injection technical GWh/day]] -> 0.0045893614 | AG23: =Table22[[#This Row],[Withdrawal technical GWh/day]]/Table22[[#Totals],[Withdrawal technical GWh/day]] -> 0.0050619559 | AH23: =ROUND(IF($B$2>=0,$B$2*Table22[[#This Row],[Normiert Injection]],$B$2*Table22[[#This Row],[Normiert Withdrawal2]]),0) -> -155
A24: Germany | B24: =C24&TEXT(D24,"0#")&TEXT(E24,"0#") -> DE1008 | C24: DE | D24: 10 | E24: 8 | F24: EWE Gasspeicher | G24: POINT (13.78118 52.48327) | H24: 52.48327 | I24: 13.78118 | J24: Rüdersdorf H | K24: operational | L24: existing | M24: 2007 | O24: Salt cavern | Q24: Onshore | R24: =S24+T24 -> 1.09 | S24: 1.09 | U24: =V24+W24 -> 10.66 | V24: 10.66 | X24: =Y24+Z24 -> 32.76 | Y24: 32.76 | AA24: TPA | AB24: y | AC24: y | AD24: YES | AF24: =Table22[[#This Row],[Injection technical GWh/day]]/Table22[[#Totals],[Injection technical GWh/day]] -> 0.0046240636 | AG24: =Table22[[#This Row],[Withdrawal technical GWh/day]]/Table22[[#Totals],[Withdrawal technical GWh/day]] -> 0.0070505815 | AH24: =ROUND(IF($B$2>=0,$B$2*Table22[[#This Row],[Normiert Injection]],$B$2*Table22[[#This Row],[Normiert Withdrawal2]]),0) -> -216
A25: Germany | B25: =C25&TEXT(D25,"0#")&TEXT(E25,"0#") -> DE1101 | C25: DE | D25: 11 | E25: 1 | F25: Equinor Storage Deutschland | G25: POINT (7.91209 53.46106) | H25: 53.46106 | I25: 7.91209 | J25: Etzel EGL | K25: operational | L25: existing | M25: 1993 | O25: Salt cavern | Q25: Onshore | R25: =S25+T25 -> 2.1851 | S25: 2.1851 | U25: =V25+W25 -> 210.672 | V25: 210.672 | X25: =Y25+Z25 -> 361.152 | Y25: 361.152 | AA25: TPA | AB25: y | AC25: y | AD25: YES | AF25: =Table22[[#This Row],[Injection technical GWh/day]]/Table22[[#Totals],[Injection technical GWh/day]] -> 0.091384684 | AG25: =Table22[[#This Row],[Withdrawal technical GWh/day]]/Table22[[#Totals],[Withdrawal technical GWh/day]] -> 0.07772685 | AH25: =ROUND(IF($B$2>=0,$B$2*Table22[[#This Row],[Normiert Injection]],$B$2*Table22[[#This Row],[Normiert Withdrawal2]]),0) -> -2381
A26: Germany | B26: =C26&TEXT(D26,"0#")&TEXT(E26,"0#") -> DE1201 | C26: DE | D26: 12 | E26: 1 | F26: GHG - Gasspeicher Hannover | G26: POINT (9.65089 52.33962) | H26: 52.33962 | I26: 9.65089 | J26: Empelde | K26: operational | L26: existing | M26: 1982 | O26: Salt cavern | Q26: Onshore | R26: =S26+T26 -> 3.8295 | S26: =333*11.5/1000 -> 3.8295 | U26: =V26+W26 -> 44.16 | V26: =160000*11.5*24/1000000 -> 44.16 | X26: =Y26+Z26 -> 140.76 | Y26: =510000*11.5*24/1000000 -> 140.76 | AA26: TPA | AB26: y | AC26: y | AD26: YES | AF26: =Table22[[#This Row],[Injection technical GWh/day]]/Table22[[#Totals],[Injection technical GWh/day]] -> 0.019155596 | AG26: =Table22[[#This Row],[Withdrawal technical GWh/day]]/Table22[[#Totals],[Withdrawal technical GWh/day]] -> 0.030294257 | AH26: =ROUND(IF($B$2>=0,$B$2*Table22[[#This Row],[Normiert Injection]],$B$2*Table22[[#This Row],[Normiert Withdrawal2]]),0) -> -928
A27: Germany | B27: =C27&TEXT(D27,"0#")&TEXT(E27,"0#") -> DE1202 | C27: DE | D27: 12 | E27: 2 | F27: GHG - Gasspeicher Hannover | G27: POINT (9.65089 52.33962) | H27: 52.33962 | I27: 9.65089 | J27: Empelde | K27: planned | L27: extension | O27: Salt cavern | Q27: Onshore | R27: =S27+T27 -> 4.6 | S27: =100*11.5/1000*4 -> 4.6 | U27: =V27+W27 -> 58.88 | V27: =160000*11.5*24/1000000/3*4 -> 58.88 | X27: =Y27+Z27 -> 187.68 | Y27: =510000*11.5*24/1000000/3*4 -> 187.68 | AA27: TPA | AB27: n | AC27: y | AD27: YES | AF27: =Table22[[#This Row],[Injection technical GWh/day]]/Table22[[#Totals],[Injection technical GWh/day]] -> 0.025540794 | AG27: =Table22[[#This Row],[Withdrawal technical GWh/day]]/Table22[[#Totals],[Withdrawal technical GWh/day]] -> 0.040392342 | AH27: =ROUND(IF($B$2>=0,$B$2*Table22[[#This Row],[Normiert Injection]],$B$2*Table22[[#This Row],[Normiert Withdrawal2]]),0) -> -1237
A28: Germany | B28: =C28&TEXT(D28,"0#")&TEXT(E28,"0#") -> DE1301 | C28: DE | D28: 13 | E28: 1 | F28: Gas Union Storage | G28: POINT (7.91209 53.46106) | H28: 53.46106 | I28: 7.91209 | J28: Etzel ESE | K28: operational | L28: existing | M28: 2012 | O28: Salt cavern | Q28: Onshore | R28: =S28+T28 -> 1.5801 | S28: =137.4*11.5/1000 -> 1.5801 | U28: =V28+W28 -> 31.7952 | V28: =(104500+10700)*11.5*24/1000000 -> 31.7952 | X28: =Y28+Z28 -> 55.6416 | Y28: =(168000+33600)*11.5*24/1000000 -> 55.6416 | AA28: TPA | AB28: y | AC28: y | AD28: YES | AF28: =Table22[[#This Row],[Injection technical GWh/day]]/Table22[[#Totals],[Injection technical GWh/day]] -> 0.013792029 | AG28: =Table22[[#This Row],[Withdrawal technical GWh/day]]/Table22[[#Totals],[Withdrawal technical GWh/day]] -> 0.011975141 | AH28: =ROUND(IF($B$2>=0,$B$2*Table22[[#This Row],[Normiert Injection]],$B$2*Table22[[#This Row],[Normiert Withdrawal2]]),0) -> -367
A29: Germany | B29: =C29&TEXT(D29,"0#")&TEXT(E29,"0#") -> DE1302 | C29: DE | D29: 13 | E29: 2 | F29: Gas Union Storage | G29: POINT (9.80939 50.78791) | H29: 50.78791 | I29: 9.80939 | J29: Reckrod | K29: operational | L29: existing | M29: 2001 | O29: Salt cavern | Q29: Onshore | R29: =S29+T29 -> 1.3225 | S29: =115*11.5/1000 -> 1.3225 | U29: =V29+W29 -> 13.8 | V29: =50000*11.5*24/1000000 -> 13.8 | X29: =Y29+Z29 -> 27.6 | Y29: =100000*11.5*24/1000000 -> 27.6 | AA29: TPA | AB29: y | AC29: y | AD29: YES | AF29: =Table22[[#This Row],[Injection technical GWh/day]]/Table22[[#Totals],[Injection technical GWh/day]] -> 0.0059861236 | AG29: =Table22[[#This Row],[Withdrawal technical GWh/day]]/Table22[[#Totals],[Withdrawal technical GWh/day]] -> 0.0059400503 | AH29: =ROUND(IF($B$2>=0,$B$2*Table22[[#This Row],[Normiert Injection]],$B$2*Table22[[#This Row],[Normiert Withdrawal2]]),0) -> -182
A30: Germany | B30: =C30&TEXT(D30,"0#")&TEXT(E30,"0#") -> DE1401 | C30: DE | D30: 14 | E30: 1 | F30: Hansewerk | G30: POINT (10.20084 54.26660) | H30: 54.2666 | I30: 10.20084 | J30: Kiel-Rönne | K30: operational | L30: existing | M30: 1971 | O30: Salt cavern | Q30: Onshore | R30: =S30+T30 -> 0.243 | S30: 0.243 | U30: =V30+W30 -> 5.69 | V30: 5.69 | X30: =Y30+Z30 -> 13.56 | Y30: 13.56 | AA30: TPA | AB30: y | AC30: y | AD30: YES | AF30: =Table22[[#This Row],[Injection technical GWh/day]]/Table22[[#Totals],[Injection technical GWh/day]] -> 0.0024681915 | AG30: =Table22[[#This Row],[Withdrawal technical GWh/day]]/Table22[[#Totals],[Withdrawal technical GWh/day]] -> 0.0029183726 | AH30: =ROUND(IF($B$2>=0,$B$2*Table22[[#This Row],[Normiert Injection]],$B$2*Table22[[#This Row],[Normiert Withdrawal2]]),0) -> -89
A31: Germany | B31: =C31&TEXT(D31,"0#")&TEXT(E31,"0#") -> DE1402 | C31: DE | D31: 14 | E31: 2 | F31: Hansewerk | G31: POINT (11.36076 53.42277) | H31: 53.42277 | I31: 11.36076 | J31: Kraak | K31: operational | L31: existing | M31: 2000 | O31: Salt cavern | Q31: Onshore | R31: =S31+T31 -> 2.88 | S31: 2.88 | U31: =V31+W31 -> 48.38 | V31: 48.38 | X31: =Y31+Z31 -> 107.52 | Y31: 107.52 | AA31: TPA | AB31: y | AC31: y | AD31: YES | AF31: =Table22[[#This Row],[Injection technical GWh/day]]/Table22[[#Totals],[Injection technical GWh/day]] -> 0.020986135 | AG31: =Table22[[#This Row],[Withdrawal technical GWh/day]]/Table22[[#Totals],[Withdrawal technical GWh/day]] -> 0.02314037 | AH31: =ROUND(IF($B$2>=0,$B$2*Table22[[#This Row],[Normiert Injection]],$B$2*Table22[[#This Row],[Normiert Withdrawal2]]),0) -> -709
A32: Germany | B32: =C32&TEXT(D32,"0#")&TEXT(E32,"0#") -> DE1501 | C32: DE | D32: 15 | E32: 1 | F32: RWE Gas Storage West | G32: POINT (7.02868 52.17597) | H32: 52.17597 | I32: 7.02868 | J32: Epe L-Gas | K32: operational | L32: existing | M32: 2012 | O32: Salt cavern | Q32: Onshore | R32: =S32+T32 -> 1.8256 | S32: 1.8256 | U32: =V32+W32 -> 49.23 | V32: 49.23 | X32: =Y32+Z32 -> 98.46 | Y32: 98.46 | AA32: TPA | AB32: y | AC32: y | AD32: YES | AE32: y | AF32: =Table22[[#This Row],[Injection technical GWh/day]]/Table22[[#Totals],[Injection technical GWh/day]] -> 0.021354845 | AG32: =Table22[[#This Row],[Withdrawal technical GWh/day]]/Table22[[#Totals],[Withdrawal technical GWh/day]] -> 0.021190484 | AH32: =ROUND(IF($B$2>=0,$B$2*Table22[[#This Row],[Normiert Injection]],$B$2*Table22[[#This Row],[Normiert Withdrawal2]]),0) -> -649
A33: Germany | B33: =C33&TEXT(D33,"0#")&TEXT(E33,"0#") -> DE1502 | C33: DE | D33: 15 | E33: 2 | F33: RWE Gas Storage West | G33: POINT (7.02868 52.17597) | H33: 52.17597 | I33: 7.02868 | J33: Epe NL | K33: operational | L33: existing | M33: 2006 | O33: Salt cavern | Q33: Onshore | R33: =S33+T33 -> 2.9392 | S33: 2.9392 | U33: =V33+W33 -> 47.73 | V33: 47.73 | X33: =Y33+Z33 -> 175.47 | Y33: 175.47 | AA33: TPA | AB33: y | AC33: y | AD33: YES | AE33: y | AF33: =Table22[[#This Row],[Injection technical GWh/day]]/Table22[[#Totals],[Injection technical GWh/day]] -> 0.02070418 | AG33: =Table22[[#This Row],[Withdrawal technical GWh/day]]/Table22[[#Totals],[Withdrawal technical GWh/day]] -> 0.037764516 | AH33: =ROUND(IF($B$2>=0,$B$2*Table22[[#This Row],[Normiert Injection]],$B$2*Table22[[#This Row],[Normiert Withdrawal2]]),0) -> -1157
A34: Germany | B34: =C34&TEXT(D34,"0#")&TEXT(E34,"0#") -> DE1503 | C34: DE | D34: 15 | E34: 3 | F34: RWE Gas Storage West | G34: POINT (11.55570 51.89172) | H34: 51.89172 | I34: 11.5557 | J34: Stassfurt | K34: operational | L34: existing | M34: 1996 | O34: Salt cavern | Q34: Onshore | R34: =S34+T34 -> 7.2561 | S34: 7.2561 | U34: =V34+W34 -> 83.69 | V34: 83.69 | X34: =Y34+Z34 -> 175.47 | Y34: 175.47 | AA34: TPA | AB34: y | AC34: y | AD34: YES | AE34: y | AF34: =Table22[[#This Row],[Injection technical GWh/day]]/Table22[[#Totals],[Injection technical GWh/day]] -> 0.036302803 | AG34: =Table22[[#This Row],[Withdrawal technical GWh/day]]/Table22[[#Totals],[Withdrawal technical GWh/day]] -> 0.037764516 | AH34: =ROUND(IF($B$2>=0,$B$2*Table22[[#This Row],[Normiert Injection]],$B$2*Table22[[#This Row],[Normiert Withdrawal2]]),0) -> -1157
A35: Germany | B35: =C35&TEXT(D35,"0#")&TEXT(E35,"0#") -> DE1504 | C35: DE | D35: 15 | E35: 4 | F35: RWE Gas Storage West | G35: POINT (7.02868 52.17597) | H35: 52.17597 | I35: 7.02868 | J35: Epe H-Gas | K35: operational | L35: existing | M35: 1990 | O35: Salt cavern | Q35: Onshore | R35: =S35+T35 -> 0 | U35: =V35+W35 -> 0 | X35: =Y35+Z35 -> 0 | AA35: TPA | AB35: y | AC35: n | AD35: YES | AE35: y | AF35: =Table22[[#This Row],[Injection technical GWh/day]]/Table22[[#Totals],[Injection technical GWh/day]] -> 0 | AG35: =Table22[[#This Row],[Withdrawal technical GWh/day]]/Table22[[#Totals],[Withdrawal technical GWh/day]] -> 0 | AH35: =ROUND(IF($B$2>=0,$B$2*Table22[[#This Row],[Normiert Injection]],$B$2*Table22[[#This Row],[Normiert Withdrawal2]]),0) -> 0
A36: Germany | B36: =C36&TEXT(D36,"0#")&TEXT(E36,"0#") -> DE1505 | C36: DE | D36: 15 | E36: 5 | F36: RWE Gas Storage West | G36: POINT (6.42637 51.66376) | H36: 51.66376 | I36: 6.42637 | J36: Xanten | K36: operational | L36: existing | M36: 1985 | O36: Salt cavern | Q36: Onshore | R36: =S36+T36 -> 0 | U36: =V36+W36 -> 0 | X36: =Y36+Z36 -> 0 | AA36: TPA | AB36: y | AC36: n | AD36: YES | AE36: y | AF36: =Table22[[#This Row],[Injection technical GWh/day]]/Table22[[#Totals],[Injection technical GWh/day]] -> 0 | AG36: =Table22[[#This Row],[Withdrawal technical GWh/day]]/Table22[[#Totals],[Withdrawal technical GWh/day]] -> 0 | AH36: =ROUND(IF($B$2>=0,$B$2*Table22[[#This Row],[Normiert Injection]],$B$2*Table22[[#This Row],[Normiert Withdrawal2]]),0) -> 0
A37: Germany | B37: =C37&TEXT(D37,"0#")&TEXT(E37,"00#") -> DE15V1 | C37: DE | D37: 15 | E37: V1 | F37: RWE Gas Storage NWE | G37: POINT (7.02868 52.17597) | H37: 52.17597 | I37: 7.02868 | J37: VGS innEXpool | K37: operational | L37: existing | M37: 1986 | O37: Salt cavern | Q37: Onshore | R37: =S37+T37 -> 6.3852 | S37: 6.3852 | U37: =V37+W37 -> 104.03 | V37: 104.03 | X37: =Y37+Z37 -> 325.78 | Y37: 325.78 | AA37: TPA | AB37: n | AC37: y | AD37: YES | AF37: =Table22[[#This Row],[Injection technical GWh/day]]/Table22[[#Totals],[Injection technical GWh/day]] -> 0.045125829 | AG37: =Table22[[#This Row],[Withdrawal technical GWh/day]]/Table22[[#Totals],[Withdrawal technical GWh/day]] -> 0.070114116 | AH37: =ROUND(IF($B$2>=0,$B$2*Table22[[#This Row],[Normiert Injection]],$B$2*Table22[[#This Row],[Normiert Withdrawal2]]),0) -> -2147
A38: Germany | B38: =C38&TEXT(D38,"0#")&TEXT(E38,"0#") -> DE1601 | C38: DE | D38: 16 | E38: 1 | F38: KGE (Kommunale Gasspeichergesellschaft Epe) | G38: POINT (7.02868 52.17597) | H38: 52.17597 | I38: 7.02868 | J38: Epe KGE | K38: operational | L38: existing | M38: 2012 | O38: Salt cavern | Q38: Onshore | R38: =S38+T38 -> 2.1244 | S38: 2.1244 | U38: =V38+W38 -> 41.04 | V38: 41.04 | X38: =Y38+Z38 -> 109.44 | Y38: 109.44 | AA38: TPA | AB38: y | AC38: y | AD38: YES | AF38: =Table22[[#This Row],[Injection technical GWh/day]]/Table22[[#Totals],[Injection technical GWh/day]] -> 0.017802211 | AG38: =Table22[[#This Row],[Withdrawal technical GWh/day]]/Table22[[#Totals],[Withdrawal technical GWh/day]] -> 0.023553591 | AH38: =ROUND(IF($B$2>=0,$B$2*Table22[[#This Row],[Normiert Injection]],$B$2*Table22[[#This Row],[Normiert Withdrawal2]]),0) -> -721
A39: Germany | B39: =C39&TEXT(D39,"0#")&TEXT(E39,"0#") -> DE1901 | C39: DE | D39: 19 | E39: 1 | F39: Nuon | G39: POINT (7.02868 52.17597) | H39: 52.17597 | I39: 7.02868 | J39: Epe Nuon | K39: operational | L39: existing | M39: 2007 | O39: Salt cavern | Q39: Onshore | R39: =S39+T39 -> 3.012 | S39: 3.012 | U39: =V39+W39 -> 84.97 | V39: 84.97 | X39: =Y39+Z39 -> 141.61 | Y39: 141.61 | AA39: TPA | AB39: y | AC39: y | AD39: YES | AF39: =Table22[[#This Row],[Injection technical GWh/day]]/Table22[[#Totals],[Injection technical GWh/day]] -> 0.036858038 | AG39: =Table22[[#This Row],[Withdrawal technical GWh/day]]/Table22[[#Totals],[Withdrawal technical GWh/day]] -> 0.030477193 | AH39: =ROUND(IF($B$2>=0,$B$2*Table22[[#This Row],[Normiert Injection]],$B$2*Table22[[#This Row],[Normiert Withdrawal2]]),0) -> -933
A40: Germany | B40: =C40&TEXT(D40,"0#")&TEXT(E40,"0#") -> DE2001 | C40: DE | D40: 20 | E40: 1 | F40: OMV Gas Storage Germany | G40: POINT (7.91209 53.46106) | H40: 53.46106 | I40: 7.91209 | J40: Etzel ESE | K40: operational | L40: existing | M40: 2012 | O40: Salt cavern | Q40: Onshore | R40: =S40+T40 -> 5.295 | S40: 5.295 | U40: =V40+W40 -> 71.28 | V40: 71.28 | X40: =Y40+Z40 -> 106.8 | Y40: 106.8 | AA40: TPA | AB40: y | AC40: y | AD40: YES | AF40: =Table22[[#This Row],[Injection technical GWh/day]]/Table22[[#Totals],[Injection technical GWh/day]] -> 0.03091963 | AG40: =Table22[[#This Row],[Withdrawal technical GWh/day]]/Table22[[#Totals],[Withdrawal technical GWh/day]] -> 0.022985412 | AH40: =ROUND(IF($B$2>=0,$B$2*Table22[[#This Row],[Normiert Injection]],$B$2*Table22[[#This Row],[Normiert Withdrawal2]]),0) -> -704
A41: Germany | B41: =C41&TEXT(D41,"0#")&TEXT(E41,"0#") -> DE2101 | C41: DE | D41: 21 | E41: 1 | F41: Ontras Gastransport | G41: POINT (11.46145 51.20517) | H41: 51.20517 | I41: 11.46145 | J41: Bruggraf-Bernsdorf | K41: operational | L41: existing | M41: 1970 | O41: Salt cavern | Q41: Onshore | R41: =S41+T41 -> 0.0345 | S41: 0 | T41: =3*11.5/1000 -> 0.0345 | U41: =V41+W41 -> 0 | X41: =Y41+Z41 -> 0 | AA41: TPA | AB41: y | AC41: y | AD41: YES | AE41: y | AF41: =Table22[[#This Row],[Injection technical GWh/day]]/Table22[[#Totals],[Injection technical GWh/day]] -> 0 | AG41: =Table22[[#This Row],[Withdrawal technical GWh/day]]/Table22[[#Totals],[Withdrawal technical GWh/day]] -> 0 | AH41: =ROUND(IF($B$2>=0,$B$2*Table22[[#This Row],[Normiert Injection]],$B$2*Table22[[#This Row],[Normiert Withdrawal2]]),0) -> 0
A42: Germany | B42: =C42&TEXT(D42,"0#")&TEXT(E42,"0#") -> DE2201 | C42: DE | D42: 22 | E42: 1 | F42: Stadtwerke Bremen (wesernetz) | G42: POINT (8.71631 53.16257) | H42: 53.16257 | I42: 8.71631 | J42: Bremen-Lesum | K42: operational | L42: existing | M42: 2000 | O42: Salt cavern | Q42: Onshore | R42: =S42+T42 -> 0.8625 | S42: =75*11.5/1000 -> 0.8625 | U42: =V42+W42 -> 1.38 | V42: =5000*11.5*24/1000000 -> 1.38 | X42: =Y42+Z42 -> 4.14 | Y42: =15000*11.5*24/1000000 -> 4.14 | AA42: TPA | AB42: y | AC42: y | AD42: YES | AF42: =Table22[[#This Row],[Injection technical GWh/day]]/Table22[[#Totals],[Injection technical GWh/day]] -> 0.00059861236 | AG42: =Table22[[#This Row],[Withdrawal technical GWh/day]]/Table22[[#Totals],[Withdrawal technical GWh/day]] -> 0.00089100755 | AH42: =ROUND(IF($B$2>=0,$B$2*Table22[[#This Row],[Normiert Injection]],$B$2*Table22[[#This Row],[Normiert Withdrawal2]]),0) -> -27
A43: Germany | B43: =C43&TEXT(D43,"0#")&TEXT(E43,"0#") -> DE2301 | C43: DE | D43: 23 | E43: 1 | F43: Stadtwerke Kiel | G43: POINT (10.20084 54.26660) | H43: 54.2666 | I43: 10.20084 | J43: Kiel-Rönne | K43: operational | L43: existing | M43: 1971 | O43: Salt cavern | Q43: Onshore | R43: =S43+T43 -> 0.668 | S43: 0.668 | U43: =V43+W43 -> 11.38 | V43: 11.38 | X43: =Y43+Z43 -> 27.12 | Y43: 27.12 | AA43: TPA | AB43: y | AC43: y | AD43: YES | AF43: =Table22[[#This Row],[Injection technical GWh/day]]/Table22[[#Totals],[Injection technical GWh/day]] -> 0.0049363831 | AG43: =Table22[[#This Row],[Withdrawal technical GWh/day]]/Table22[[#Totals],[Withdrawal technical GWh/day]] -> 0.0058367451 | AH43: =ROUND(IF($B$2>=0,$B$2*Table22[[#This Row],[Normiert Injection]],$B$2*Table22[[#This Row],[Normiert Withdrawal2]]),0) -> -179
...

Sheet Storage_Input
A1: {=Storage!H8:H49} -> Latitude | B1: {=Storage!I8:I49} -> Longitude | C1: {=Storage!AH8:AH49} -> Peak Load [MWh/h]
A2: 53.25724 | B2: 7.40786 | C2: -961
A3: 53.25724 | B3: 7.40786 | C3: -418
A4: 53.746106 | B4: 7.91209 | C4: -620
A5: 53.46106 | B5: 7.91209 | C5: -1430
A6: 53.46106 | B6: 7.91209 | C6: -620
A7: 52.17597 | B7: 7.02868 | C7: -617
A8: 51.75025 | B8: 11.75922 | C8: -1780
A9: 51.75025 | B9: 11.75922 | C9: 0
A10: 53.25724 | B10: 7.40786 | C10: -1705
A11: 53.19426 | B11: 8.4007 | C11: -182
A12: 53.25724 | B12: 7.40786 | C12: -455
A13: 53.25724 | B13: 7.40786 | C13: -459
... A42: 52.17597 | B42: 7.02868 | C42: -3066

Sheet LH2
A2: Import LH2 | B2: =Overview!E151*0.21 -> 96.39 | C2: TWh/a
A3: Import LH2 | B3: =B2*1000000 -> 96390000 | C3: MWh/a
A4: Peak Hour Supply | B4: =B3/(365*24) -> 11003.425 | C4: MWh/h
A5: Peak Hour Supply Rounded | B5: =SUM(Table2[Peak Load '[MWh/h']]) -> 11003 | C5: MWh/h
A7: Properties
A8: Fluid | B8: Volumetric LHV | C8: Unit
A9: Natural Gas | B9: 23 | C9: GJ/m^3
A10: Hydrogen | B10: 8.5 | C10: GJ/m^4
A12: LNG Terminals Location & Capacity
A13: ID | B13: Latitude | C13: Longitude | D13: Storage Capacity [m^3 LNG] | E13: Pipeline capacity[bcm] | F13: Terminal Capacity [m^3/a] | G13: Terminal capacity [TWh_CH4/a] | H13: Terminal Capacity [TWh_H2/a] | I13: Relative size | J13: Peak Load [MWh/h]
A14: Wilhelmshaven | B14: 53.5916 | C14: 8.1475 | D14: n.d. | E14: 5 | F14: =Table2[[#This Row],[Pipeline capacity'[bcm']]]*1000000000 -> 5000000000 | G14: =Table2[[#This Row],[Terminal Capacity '[m^3/a']]]*$B$9/3.6 -> 3.1944444e+10 | H14: =Table2[[#This Row],[Terminal Capacity '[m^3/a']]]*$B$10/3.6 -> 1.1805556e+10 | I14: =Table2[[#This Row],[Terminal Capacity '[m^3/a']]]/Table2[[#Totals],[Terminal Capacity '[m^3/a']]] -> 0.2173913 | J14: =ROUND(IF(Table2[[#Totals],[Terminal Capacity '[TWh_H2/a']]]>=$B$3,(I14*$B$3/(365*24))),0) -> 2392
A15: Brunsbüttel | B15: 53.88887 | C15: 9.17466 | D15: 330000 | E15: 5 | F15: =Table2[[#This Row],[Pipeline capacity'[bcm']]]*1000000000 -> 5000000000 | G15: =Table2[[#This Row],[Terminal Capacity '[m^3/a']]]*$B$9/3.6 -> 3.1944444e+10 | H15: =Table2[[#This Row],[Terminal Capacity '[m^3/a']]]*$B$10/3.6 -> 1.1805556e+10 | I15: =Table2[[#This Row],[Terminal Capacity '[m^3/a']]]/Table2[[#Totals],[Terminal Capacity '[m^3/a']]] -> 0.2173913 | J15: =ROUND(IF(Table2[[#Totals],[Terminal Capacity '[TWh_H2/a']]]>=$B$3,(I15*$B$3/(365*24))),0) -> 2392
A16: Stade | B16: 53.6484 | C16: 9.5053 | D16: 480000 | E16: 13 | F16: =Table2[[#This Row],[Pipeline capacity'[bcm']]]*1000000000 -> 13000000000 | G16: =Table2[[#This Row],[Terminal Capacity '[m^3/a']]]*$B$9/3.6 -> 8.3055556e+10 | H16: =Table2[[#This Row],[Terminal Capacity '[m^3/a']]]*$B$10/3.6 -> 3.0694444e+10 | I16: =Table2[[#This Row],[Terminal Capacity '[m^3/a']]]/Table2[[#Totals],[Terminal Capacity '[m^3/a']]] -> 0.56521739 | J16: =ROUND(IF(Table2[[#Totals],[Terminal Capacity '[TWh_H2/a']]]>=$B$3,(I16*$B$3/(365*24))),0) -> 6219
F17: =SUM(Table2[Terminal Capacity '[m^3/a']]) -> 23000000000 | H17: =SUM(Table2[Terminal Capacity '[TWh_H2/a']]) -> 5.4305556e+10 | I17: =SUM(Table2[Relative size]) -> 1

Sheet LH2_Input
A1: {=Table2[[#Headers],[#Data],[Latitude]:[Longitude]]} -> Latitude | B1: Longitude | C1: {=Table2[[#Headers],[#Data],[Peak Load '[MWh/h']]]} -> Peak Load [MWh/h]
A2: 53.5916 | B2: 8.1475 | C2: 2392
A3: 53.88887 | B3: 9.17466 | C3: 2392
A4: 53.6484 | B4: 9.5053 | C4: 6219

Sheet IC
A2: Import | B2: =Overview!E151*(0.87-0.21) -> 302.94 | C2: TWh/a | D2: TXT | E2: Input
A3: Annual Hydrogen Supply MWh | B3: =B2*1000000 -> 302940000 | C3: Mwh/a | D3: TXT | E3: Calculation
A4: Peak Hour Supply | B4: =B3/(365*24) -> 34582.192 | C4: Mwh/h | D4: TXT | E4: Referenced from other sheet
A5: Peak Hour Supply Rounded | B5: =SUM(Table269[Peak Load '[MWh/h']]) -> 34583 | C5: Mwh/a | D5: TXT | E5: Hardcoded data
A6: Supply in a day | B6: =B3/365 -> 829972.6
A7: Properties
A8: Fluid | B8: Volumetric Energy Density [MJ/m^3]
A9: Natural Gas | B9: 40.34
A10: Hydrogen | B10: 12.79
A11: Flow capacity from NG to H2 | B11: 0.85
A13: IC Location & Capacity
A14: ID | B14: Latitude | C14: Longitude | D14: From | E14: to | F14: Max_Capacity_from_to [M_m3/d] | G14: Max_Capacity_to_from [M_m3/d] | H14: Capacity [MWh_CH4/d] | I14: Capacity [MWh_H2/d] | J14: Relative size | K14: Peak Load [MWh/h]
A15: Basel_[77] | B15: 47.56344 | C15: 7.673591 | D15: DE | E15: CH | F15: 0.77418684 | G15: 0 | H15: =IF(Table269[[#This Row],[to]]="DE", Table269[[#This Row],[Max_Capacity_from_to '[M_m3/d']]]*$B$9*1000000/3600, Table269[[#This Row],[Max_Capacity_to_from '[M_m3/d']]]*$B$9*1000000/3600) -> 0 | I15: =Table269[[#This Row],[Capacity '[MWh_CH4/d']]]*$B$11 -> 0 | J15: =Table269[[#This Row],[Capacity '[MWh_CH4/d']]]/Table269[[#Totals],[Capacity '[MWh_CH4/d']]] -> 0 | K15: =ROUND(Table269[[#This Row],[Relative size]]*$B$4,0) -> 0
A16: Brandov_[40, 42, 84] | B16: 50.648857 | C16: 13.384905999999999 | D16: CZ | E16: DE | F16: 16.134758 | G16: 115.40663 | H16: =IF(Table269[[#This Row],[to]]="DE", Table269[[#This Row],[Max_Capacity_from_to '[M_m3/d']]]*$B$9*1000000/3600, Table269[[#This Row],[Max_Capacity_to_from '[M_m3/d']]]*$B$9*1000000/3600) -> 180798.92 | I16: =Table269[[#This Row],[Capacity '[MWh_CH4/d']]]*$B$11 -> 153679.08 | J16: =Table269[[#This Row],[Capacity '[MWh_CH4/d']]]/Table269[[#Totals],[Capacity '[MWh_CH4/d']]] -> 0.033191566 | K16: =ROUND(Table269[[#This Row],[Relative size]]*$B$4,0) -> 1148
A17: Dornum_[201, 228] | B17: 53.652496 | C17: 7.4163169999999985 | D17: NO | E17: DE | F17: 64.14314 | G17: 0 | H17: =IF(Table269[[#This Row],[to]]="DE", Table269[[#This Row],[Max_Capacity_from_to '[M_m3/d']]]*$B$9*1000000/3600, Table269[[#This Row],[Max_Capacity_to_from '[M_m3/d']]]*$B$9*1000000/3600) -> 718759.51 | I17: =Table269[[#This Row],[Capacity '[MWh_CH4/d']]]*$B$11 -> 610945.59 | J17: =Table269[[#This Row],[Capacity '[MWh_CH4/d']]]/Table269[[#Totals],[Capacity '[MWh_CH4/d']]] -> 0.13195186 | K17: =ROUND(Table269[[#This Row],[Relative size]]*$B$4,0) -> 4563
A18: Ellund_[36] | B18: 54.803583999999994 | C18: 9.285375 | D18: DK | E18: DE | F18: 8.0057958 | G18: 10.249178 | H18: =IF(Table269[[#This Row],[to]]="DE", Table269[[#This Row],[Max_Capacity_from_to '[M_m3/d']]]*$B$9*1000000/3600, Table269[[#This Row],[Max_Capacity_to_from '[M_m3/d']]]*$B$9*1000000/3600) -> 89709.389 | I18: =Table269[[#This Row],[Capacity '[MWh_CH4/d']]]*$B$11 -> 76252.981 | J18: =Table269[[#This Row],[Capacity '[MWh_CH4/d']]]/Table269[[#Totals],[Capacity '[MWh_CH4/d']]] -> 0.016469098 | K18: =ROUND(Table269[[#This Row],[Relative size]]*$B$4,0) -> 570
A19: Emden_[202] | B19: 53.31488100000001 | C19: 7.286939999999999 | D19: NO | E19: DE | F19: 130.34491 | G19: 0 | H19: =IF(Table269[[#This Row],[to]]="DE", Table269[[#This Row],[Max_Capacity_from_to '[M_m3/d']]]*$B$9*1000000/3600, Table269[[#This Row],[Max_Capacity_to_from '[M_m3/d']]]*$B$9*1000000/3600) -> 1460587.2 | I19: =Table269[[#This Row],[Capacity '[MWh_CH4/d']]]*$B$11 -> 1241499.1 | J19: =Table269[[#This Row],[Capacity '[MWh_CH4/d']]]/Table269[[#Totals],[Capacity '[MWh_CH4/d']]] -> 0.26813863 | K19: =ROUND(Table269[[#This Row],[Relative size]]*$B$4,0) -> 9273
A20: Epe_[15] | B20: 52.12406 | C20: 7.01965 | D20: NL | E20: DE | F20: 14.841514 | G20: 27.650787 | H20: =IF(Table269[[#This Row],[to]]="DE", Table269[[#This Row],[Max_Capacity_from_to '[M_m3/d']]]*$B$9*1000000/3600, Table269[[#This Row],[Max_Capacity_to_from '[M_m3/d']]]*$B$9*1000000/3600) -> 166307.41 | I20: =Table269[[#This Row],[Capacity '[MWh_CH4/d']]]*$B$11 -> 141361.3 | J20: =Table269[[#This Row],[Capacity '[MWh_CH4/d']]]/Table269[[#Totals],[Capacity '[MWh_CH4/d']]] -> 0.030531174 | K20: =ROUND(Table269[[#This Row],[Relative size]]*$B$4,0) -> 1056
A21: Eynatten_[6] | B21: 50.700959999999995 | C21: 6.21729 | D21: BE | E21: DE | F21: 25.468988 | G21: 35.234299 | H21: =IF(Table269[[#This Row],[to]]="DE", Table269[[#This Row],[Max_Capacity_from_to '[M_m3/d']]]*$B$9*1000000/3600, Table269[[#This Row],[Max_Capacity_to_from '[M_m3/d']]]*$B$9*1000000/3600) -> 285394.16 | I21: =Table269[[#This Row],[Capacity '[MWh_CH4/d']]]*$B$11 -> 242585.03 | J21: =Table269[[#This Row],[Capacity '[MWh_CH4/d']]]/Table269[[#Totals],[Capacity '[MWh_CH4/d']]] -> 0.052393449 | K21: =ROUND(Table269[[#This Row],[Relative size]]*$B$4,0) -> 1812
A22: Haiming_2_[61] | B22: 48.55907 | C22: 13.763841000000001 | D22: DE | E22: AT | F22: 21.351721 | G22: 14.621574 | H22: =IF(Table269[[#This Row],[to]]="DE", Table269[[#This Row],[Max_Capacity_from_to '[M_m3/d']]]*$B$9*1000000/3600, Table269[[#This Row],[Max_Capacity_to_from '[M_m3/d']]]*$B$9*1000000/3600) -> 163842.86 | I22: =Table269[[#This Row],[Capacity '[MWh_CH4/d']]]*$B$11 -> 139266.43 | J22: =Table269[[#This Row],[Capacity '[MWh_CH4/d']]]/Table269[[#Totals],[Capacity '[MWh_CH4/d']]] -> 0.030078726 | K22: =ROUND(Table269[[#This Row],[Relative size]]*$B$4,0) -> 1040
A23: Jemgum_[74] | B23: 53.233796 | C23: 7.4235929999999986 | D23: DE | E23: NL | F23: 33.976245 | G23: 24.422076 | H23: =IF(Table269[[#This Row],[to]]="DE", Table269[[#This Row],[Max_Capacity_from_to '[M_m3/d']]]*$B$9*1000000/3600, Table269[[#This Row],[Max_Capacity_to_from '[M_m3/d']]]*$B$9*1000000/3600) -> 273662.93 | I23: =Table269[[#This Row],[Capacity '[MWh_CH4/d']]]*$B$11 -> 232613.49 | J23: =Table269[[#This Row],[Capacity '[MWh_CH4/d']]]/Table269[[#Totals],[Capacity '[MWh_CH4/d']]] -> 0.050239797 | K23: =ROUND(Table269[[#This Row],[Relative size]]*$B$4,0) -> 1737
A24: Kamminke_[82] | B24: 53.90201999999999 | C24: 14.175820000000002 | D24: DE | E24: PL | F24: 0.0087975778 | G24: 0.0087975778 | H24: =IF(Table269[[#This Row],[to]]="DE", Table269[[#This Row],[Max_Capacity_from_to '[M_m3/d']]]*$B$9*1000000/3600, Table269[[#This Row],[Max_Capacity_to_from '[M_m3/d']]]*$B$9*1000000/3600) -> 98.581746 | I24: =Table269[[#This Row],[Capacity '[MWh_CH4/d']]]*$B$11 -> 83.794485 | J24: =Table269[[#This Row],[Capacity '[MWh_CH4/d']]]/Table269[[#Totals],[Capacity '[MWh_CH4/d']]] -> 1.809791e-05 | K24: =ROUND(Table269[[#This Row],[Relative size]]*$B$4,0) -> 1
A25: Lindau_[78] | B25: 47.53777 | C25: 9.60093 | D25: DE | E25: AT | F25: 2.2345848 | G25: 0 | H25: =IF(Table269[[#This Row],[to]]="DE", Table269[[#This Row],[Max_Capacity_from_to '[M_m3/d']]]*$B$9*1000000/3600, Table269[[#This Row],[Max_Capacity_to_from '[M_m3/d']]]*$B$9*1000000/3600) -> 0 | I25: =Table269[[#This Row],[Capacity '[MWh_CH4/d']]]*$B$11 -> 0 | J25: =Table269[[#This Row],[Capacity '[MWh_CH4/d']]]/Table269[[#Totals],[Capacity '[MWh_CH4/d']]] -> 0 | K25: =ROUND(Table269[[#This Row],[Relative size]]*$B$4,0) -> 0
A26: Mallnow_[38] | B26: 52.427 | C26: 14.543 | D26: DE | E26: PL | F26: 16.257924 | G26: 81.949437 | H26: =IF(Table269[[#This Row],[to]]="DE", Table269[[#This Row],[Max_Capacity_from_to '[M_m3/d']]]*$B$9*1000000/3600, Table269[[#This Row],[Max_Capacity_to_from '[M_m3/d']]]*$B$9*1000000/3600) -> 918288.97 | I26: =Table269[[#This Row],[Capacity '[MWh_CH4/d']]]*$B$11 -> 780545.62 | J26: =Table269[[#This Row],[Capacity '[MWh_CH4/d']]]/Table269[[#Totals],[Capacity '[MWh_CH4/d']]] -> 0.16858203 | K26: =ROUND(Table269[[#This Row],[Relative size]]*$B$4,0) -> 5830
... A30: Waidhaus_[43] | B30: 49.635529999999996 | C30: 12.51965 | D30: CZ | E30: DE | F30: 79.785233 | G30: 0 | H30: =IF(Table269[[#This Row],[to]]="DE", Table269[[#This Row],[Max_Capacity_from_to '[M_m3/d']]]*$B$9*1000000/3600, Table269[[#This Row],[Max_Capacity_to_from '[M_m3/d']]]*$B$9*1000000/3600) -> 894037.86 | I30: =Table269[[#This Row],[Capacity '[MWh_CH4/d']]]*$B$11 -> 759932.18 | J30: =Table269[[#This Row],[Capacity '[MWh_CH4/d']]]/Table269[[#Totals],[Capacity '[MWh_CH4/d']]] -> 0.16412994 | K30: =ROUND(Table269[[#This Row],[Relative size]]*$B$4,0) -> 5676
E31: DE | H31: =SUM(Table269[Capacity '[MWh_CH4/d']]) -> 5447134.4 | I31: =SUM(Table269[Capacity '[MWh_H2/d']]) -> 4630064.2 | J31: =SUM(Table269[Relative size]) -> 1

Sheet IC_Input
A1: {=Table269[[#Headers],[#Data],[Latitude]:[Longitude]]} -> Latitude | B1: Longitude | C1: {=Table269[[#Headers],[#Data],[Peak Load '[MWh/h']]]} -> Peak Load [MWh/h]
A2: 47.56344 | B2: 7.673591 | C2: 0
A3: 50.648857 | B3: 13.384905999999999 | C3: 1148
A4: 53.652496 | B4: 7.4163169999999985 | C4: 4563
A5: 54.803583999999994 | B5: 9.285375 | C5: 570
A6: 53.31488100000001 | B6: 7.286939999999999 | C6: 9273
A7: 52.12406 | B7: 7.01965 | C7: 1056
A8: 50.700959999999995 | B8: 6.21729 | C8: 1812
A9: 48.55907 | B9: 13.763841000000001 | C9: 1040
A10: 53.233796 | B10: 7.4235929999999986 | C10: 1737
A11: 53.90201999999999 | B11: 14.175820000000002 | C11: 1
A12: 47.53777 | B12: 9.60093 | C12: 0
A13: 52.427 | B13: 14.543 | C13: 5830
... A17: 49.635529999999996 | B17: 12.51965 | C17: 5676

Sheet Electrolyser_Wasserstoffatlas
A2: Domestic | B2: =Overview!E146 -> 60 | C2: TWh/a | D2: TXT | E2: Input
A3: Domestic | B3: =B2*1000000 -> 60000000 | C3: MWh/a | D3: TXT | E3: Calculation
D4: TXT | E4: Referenced from other sheet
A5: Existing Project Production | B5: =SUM(Table12[Peak Load '[MWh/h']])*B9 -> 20901900 | C5: MWh/a | D5: TXT | E5: Hardcoded data
A6: Peak Hour Supply Rounded | B6: =SUM(Table12[Peak Load '[MWh/h']]) -> 5700 | C6: MWh/h
A7: Installed Capacity | B7: =SUM(Table12[[Capacity MW H2 ]]) -> 13614.266 | C7: MW
A8: Efficiency Electrolyzer | B8: 0.68
A9: Full load hour | B9: 3667 | C9: 1870 h–2770 h | D9: 3600
A10: Annual load factor | B10: =B9/(365*24) -> 0.41860731 | C10: Assume the same load factor annually as in peak load
A11: Percentage Feed-In in Peak Hour | B11: =B10 -> 0.41860731 | C11: %
A14: NUTS3 | B14: Landkreis | C14: Elec Capacity MW | D14: Capacity MW H2 | E14: Peak Load [MWh/h]
A15: DE111 | B15: Stuttgart, Stadtkreis | C15: 0.4 | D15: =$B$8*C15 -> 0.272 | E15: =ROUND(D15*$B$10,0) -> 0
A16: DE112 | B16: Böblingen | C16: 0 | D16: =$B$8*C16 -> 0 | E16: =ROUND(D16*$B$10,0) -> 0
A17: DE113 | B17: Esslingen | C17: 1 | D17: =$B$8*C17 -> 0.68 | E17: =ROUND(D17*$B$10,0) -> 0
A18: DE114 | B18: Göppingen | C18: 0 | D18: =$B$8*C18 -> 0 | E18: =ROUND(D18*$B$10,0) -> 0
A19: DE115 | B19: Ludwigsburg | C19: 0 | D19: =$B$8*C19 -> 0 | E19: =ROUND(D19*$B$10,0) -> 0
A20: DE116 | B20: Rems-Murr-Kreis | C20: 2 | D20: =$B$8*C20 -> 1.36 | E20: =ROUND(D20*$B$10,0) -> 1
A21: DE117 | B21: Heilbronn, Stadtkreis | C21: 0 | D21: =$B$8*C21 -> 0 | E21: =ROUND(D21*$B$10,0) -> 0
A22: DE118 | B22: Heilbronn, Landkreis | C22: 0 | D22: =$B$8*C22 -> 0 | E22: =ROUND(D22*$B$10,0) -> 0
A23: DE119 | B23: Hohenlohekreis | C23: 0 | D23: =$B$8*C23 -> 0 | E23: =ROUND(D23*$B$10,0) -> 0
A24: DE11A | B24: Schwäbisch Hall | C24: 0 | D24: =$B$8*C24 -> 0 | E24: =ROUND(D24*$B$10,0) -> 0
A25: DE11B | B25: Main-Tauber-Kreis | C25: 0 | D25: =$B$8*C25 -> 0 | E25: =ROUND(D25*$B$10,0) -> 0
A26: DE11C | B26: Heidenheim | C26: 0 | D26: =$B$8*C26 -> 0 | E26: =ROUND(D26*$B$10,0) -> 0
... A416: DEZZZ | B416: Extra-Regio NUTS 3⁠* | C416: 0 | D416: =$B$8*C416 -> 0 | E416: =ROUND(D416*$B$10,0) -> 0

Sheet Elec_Input
A1: {=Table12[[#All],[NUTS3]]} -> NUTS3 | B1: {=Table12[[#All],[Peak Load '[MWh/h']]]} -> Peak Load [MWh/h]
A2: DE111 | B2: 0
A3: DE112 | B3: 0
A4: DE113 | B4: 0
A5: DE114 | B5: 0
A6: DE115 | B6: 0
A7: DE116 | B7: 1
A8: DE117 | B8: 0
A9: DE118 | B9: 0
A10: DE119 | B10: 0
A11: DE11A | B11: 0
A12: DE11B | B12: 0
A13: DE11C | B13: 0
... A403: DEZZZ | B403: 0

Sheet Industry_Electrolyser
A3: Remaining Domestic Production MWh/a | B3: =Electrolyser_Wasserstoffatlas!B3-Electrolyser_Wasserstoffatlas!B5 -> 39098100 | C3: MWh/a
A4: Full load hour | B4: 3667 | C4: 1870 h–2770 h | D4: In dena | F4: TXT | G4: Input
A5: Annual load factor | B5: =B4/(365*24) -> 0.41860731 | C5: % | F5: TXT | G5: Calculation
A6: Required Electrolyser Production Capacities | B6: =B3/B4 -> 10662.149 | C6: MW | F6: TXT | G6: Referenced from other sheet
A7: According to Dena with 31 GW overall installed capacity | B7: =24000-Electrolyser_Wasserstoffatlas!B7 -> 10385.734 | C7: MW | F7: TXT | G7: Hardcoded data
A9: Annual Electrolyser Production | B9: =SUM(K23:K379)*B4 -> 49882201 | C9: MWh/a
A10: Max Electrolyser Size | B10: 500 | C10: MW
A11: Min Electrolyser Size | B11: 50 | C11: MW
A12: Installed Capacity | B12: =SUM(Table101214[Electrolyser Potential MW]) -> 13603
A13: Percentage Feed-In in Peak Hour | B13: =B5 -> 0.41860731 | C13: %
A14: Peak Hour Supply Potentially | B14: =SUM(Table101214[Potential Peak hour production MWh]) -> 13603 | C14: MWh/h
A15: Peak Hour Supply Rounded | B15: =SUM(Table101214[Peak Load '[MWh/h']]) -> 5689 | C15: MWh/h
A22: SiteId | B22: CompanyName | C22: Subsector_Name | D22: Product | E22: Latitude | F22: Longitude | G22: NUTS3ID | H22: H2-Potential in TWh/a | I22: Potential demand MWh/h | J22: Normalize Demand | K22: Electrolyser Potential MW | L22: Potential Peak hour production MWh | M22: Peak Load [MWh/h]
A23: 16 | B23: Covestro | C23: Chemical industry | E23: 51.36813 | F23: 6.66235 | G23: DEA14 | H23: 0.0544 | I23: =ROUND(Table101214[[#This Row],[H2-Potential in TWh/a]]*1000000/(365*24),0) -> 6 | J23: =Table101214[[#This Row],[Potential demand MWh/h]]/SUM($I$23:$I$379) -> 0.00020510717 | K23: =MIN(IF(Table101214[[#This Row],[Potential demand MWh/h]]>=$B$11,ROUND(Table101214[[#This Row],[Potential demand MWh/h]],0),0),$B$10) -> 0 | L23: =Table101214[[#This Row],[Electrolyser Potential MW]] -> 0 | M23: =ROUND(Table101214[[#This Row],[Potential Peak hour production MWh]]*$B$13,0) -> 0
A24: 17 | B24: Covestro | C24: Chemical industry | E24: 51.08519 | F24: 6.84469 | G24: DEA1D | H24: 0.1005 | I24: =ROUND(Table101214[[#This Row],[H2-Potential in TWh/a]]*1000000/(365*24),0) -> 11 | J24: =Table101214[[#This Row],[Potential demand MWh/h]]/SUM($I$23:$I$379) -> 0.00037602981 | K24: =MIN(IF(Table101214[[#This Row],[Potential demand MWh/h]]>=$B$11,ROUND(Table101214[[#This Row],[Potential demand MWh/h]],0),0),$B$10) -> 0 | L24: =Table101214[[#This Row],[Electrolyser Potential MW]] -> 0 | M24: =ROUND(Table101214[[#This Row],[Potential Peak hour production MWh]]*$B$13,0) -> 0
A25: 18 | B25: INOVYN | C25: Chemical industry | E25: 51.56165 | F25: 6.57928 | G25: DEA1F | H25: 0.0944 | I25: =ROUND(Table101214[[#This Row],[H2-Potential in TWh/a]]*1000000/(365*24),0) -> 11 | J25: =Table101214[[#This Row],[Potential demand MWh/h]]/SUM($I$23:$I$379) -> 0.00037602981 | K25: =MIN(IF(Table101214[[#This Row],[Potential demand MWh/h]]>=$B$11,ROUND(Table101214[[#This Row],[Potential demand MWh/h]],0),0),$B$10) -> 0 | L25: =Table101214[[#This Row],[Electrolyser Potential MW]] -> 0 | M25: =ROUND(Table101214[[#This Row],[Potential Peak hour production MWh]]*$B$13,0) -> 0
A26: 19 | B26: INEOS Manufacturing Deutschland GmbH | C26: Chemical industry | E26: 51.067636 | F26: 6.8467425 | G26: DEA23 | H26: 24.8289 | I26: =ROUND(Table101214[[#This Row],[H2-Potential in TWh/a]]*1000000/(365*24),0) -> 2834 | J26: =Table101214[[#This Row],[Potential demand MWh/h]]/SUM($I$23:$I$379) -> 0.096878953 | K26: =MIN(IF(Table101214[[#This Row],[Potential demand MWh/h]]>=$B$11,ROUND(Table101214[[#This Row],[Potential demand MWh/h]],0),0),$B$10) -> 500 | L26: =Table101214[[#This Row],[Electrolyser Potential MW]] -> 500 | M26: =ROUND(Table101214[[#This Row],[Potential Peak hour production MWh]]*$B$13,0) -> 209
A27: 20 | B27: Covestro | C27: Chemical industry | E27: 51.02508 | F27: 6.98915 | G27: DEA24 | H27: 0.0816 | I27: =ROUND(Table101214[[#This Row],[H2-Potential in TWh/a]]*1000000/(365*24),0) -> 9 | J27: =Table101214[[#This Row],[Potential demand MWh/h]]/SUM($I$23:$I$379) -> 0.00030766075 | K27: =MIN(IF(Table101214[[#This Row],[Potential demand MWh/h]]>=$B$11,ROUND(Table101214[[#This Row],[Potential demand MWh/h]],0),0),$B$10) -> 0 | L27: =Table101214[[#This Row],[Electrolyser Potential MW]] -> 0 | M27: =ROUND(Table101214[[#This Row],[Potential Peak hour production MWh]]*$B$13,0) -> 0
A28: 21 | B28: BASF | C28: Chemical industry | E28: 49.5291 | F28: 8.4247175 | G28: DEB34 | H28: 21.6522 | I28: =ROUND(Table101214[[#This Row],[H2-Potential in TWh/a]]*1000000/(365*24),0) -> 2472 | J28: =Table101214[[#This Row],[Potential demand MWh/h]]/SUM($I$23:$I$379) -> 0.084504153 | K28: =MIN(IF(Table101214[[#This Row],[Potential demand MWh/h]]>=$B$11,ROUND(Table101214[[#This Row],[Potential demand MWh/h]],0),0),$B$10) -> 500 | L28: =Table101214[[#This Row],[Electrolyser Potential MW]] -> 500 | M28: =ROUND(Table101214[[#This Row],[Potential Peak hour production MWh]]*$B$13,0) -> 209
A29: 22 | B29: Basell Polyolefine GmbH Werk Wesseling | C29: Chemical industry | E29: 50.832682 | F29: 6.9440667 | G29: DEA27 | H29: 25.8511 | I29: =ROUND(Table101214[[#This Row],[H2-Potential in TWh/a]]*1000000/(365*24),0) -> 2951 | J29: =Table101214[[#This Row],[Potential demand MWh/h]]/SUM($I$23:$I$379) -> 0.10087854 | K29: =MIN(IF(Table101214[[#This Row],[Potential demand MWh/h]]>=$B$11,ROUND(Table101214[[#This Row],[Potential demand MWh/h]],0),0),$B$10) -> 500 | L29: =Table101214[[#This Row],[Electrolyser Potential MW]] -> 500 | M29: =ROUND(Table101214[[#This Row],[Potential Peak hour production MWh]]*$B$13,0) -> 209
A30: 23 | B30: Evonik Industries | C30: Chemical industry | E30: 50.83062 | F30: 7.02402 | G30: DEA2C | H30: 0.0161 | I30: =ROUND(Table101214[[#This Row],[H2-Potential in TWh/a]]*1000000/(365*24),0) -> 2 | J30: =Table101214[[#This Row],[Potential demand MWh/h]]/SUM($I$23:$I$379) -> 6.8369056e-05 | K30: =MIN(IF(Table101214[[#This Row],[Potential demand MWh/h]]>=$B$11,ROUND(Table101214[[#This Row],[Potential demand MWh/h]],0),0),$B$10) -> 0 | L30: =Table101214[[#This Row],[Electrolyser Potential MW]] -> 0 | M30: =ROUND(Table101214[[#This Row],[Potential Peak hour production MWh]]*$B$13,0) -> 0
A31: 24 | B31: VESTOLIT | C31: Chemical industry | E31: 51.68027 | F31: 7.10186 | G31: DEA36 | H31: 0.0544 | I31: =ROUND(Table101214[[#This Row],[H2-Potential in TWh/a]]*1000000/(365*24),0) -> 6 | J31: =Table101214[[#This Row],[Potential demand MWh/h]]/SUM($I$23:$I$379) -> 0.00020510717 | K31: =MIN(IF(Table101214[[#This Row],[Potential demand MWh/h]]>=$B$11,ROUND(Table101214[[#This Row],[Potential demand MWh/h]],0),0),$B$10) -> 0 | L31: =Table101214[[#This Row],[Electrolyser Potential MW]] -> 0 | M31: =ROUND(Table101214[[#This Row],[Potential Peak hour production MWh]]*$B$13,0) -> 0
A32: 25 | B32: SKW Stickstoffwerke Piesteritz GmbH | C32: Chemical industry | E32: 51.878593 | F32: 12.575129 | G32: DEE0E | H32: 7.0204 | I32: =ROUND(Table101214[[#This Row],[H2-Potential in TWh/a]]*1000000/(365*24),0) -> 801 | J32: =Table101214[[#This Row],[Potential demand MWh/h]]/SUM($I$23:$I$379) -> 0.027381807 | K32: =MIN(IF(Table101214[[#This Row],[Potential demand MWh/h]]>=$B$11,ROUND(Table101214[[#This Row],[Potential demand MWh/h]],0),0),$B$10) -> 500 | L32: =Table101214[[#This Row],[Electrolyser Potential MW]] -> 500 | M32: =ROUND(Table101214[[#This Row],[Potential Peak hour production MWh]]*$B$13,0) -> 209
A33: 26 | B33: Dow | C33: Chemical industry | E33: 51.41207 | F33: 12.02761 | G33: DEE0B | H33: 0.0523 | I33: =ROUND(Table101214[[#This Row],[H2-Potential in TWh/a]]*1000000/(365*24),0) -> 6 | J33: =Table101214[[#This Row],[Potential demand MWh/h]]/SUM($I$23:$I$379) -> 0.00020510717 | K33: =MIN(IF(Table101214[[#This Row],[Potential demand MWh/h]]>=$B$11,ROUND(Table101214[[#This Row],[Potential demand MWh/h]],0),0),$B$10) -> 0 | L33: =Table101214[[#This Row],[Electrolyser Potential MW]] -> 0 | M33: =ROUND(Table101214[[#This Row],[Potential Peak hour production MWh]]*$B$13,0) -> 0
A34: 27 | B34: Nouryon (AkzoNobel) | C34: Chemical industry | E34: 51.63635 | F34: 12.29834 | G34: DEE05 | H34: 0.0207 | I34: =ROUND(Table101214[[#This Row],[H2-Potential in TWh/a]]*1000000/(365*24),0) -> 2 | J34: =Table101214[[#This Row],[Potential demand MWh/h]]/SUM($I$23:$I$379) -> 6.8369056e-05 | K34: =MIN(IF(Table101214[[#This Row],[Potential demand MWh/h]]>=$B$11,ROUND(Table101214[[#This Row],[Potential demand MWh/h]],0),0),$B$10) -> 0 | L34: =Table101214[[#This Row],[Electrolyser Potential MW]] -> 0 | M34: =ROUND(Table101214[[#This Row],[Potential Peak hour production MWh]]*$B$13,0) -> 0
... A122: 115 | B122: Holcim (Deutschland) | C122: Mineral Processing | E122: 53.874165 | F122: 9.5832686 | G122: DEF0E | H122: 1.3657 | I122: =ROUND(Table101214[[#This Row],[H2-Potential in TWh/a]]*1000000/(365*24),0) -> 156 | J122: =Table101214[[#This Row],[Potential demand MWh/h]]/SUM($I$23:$I$379) -> 0.0053327864 | K122: =MIN(IF(Table101214[[#This Row],[Potential demand MWh/h]]>=$B$11,ROUND(Table101214[[#This Row],[Potential demand MWh/h]],0),0),$B$10) -> 156 | L122: =Table101214[[#This Row],[Electrolyser Potential MW]] -> 156 | M122: =ROUND(Table101214[[#This Row],[Potential Peak hour production MWh]]*$B$13,0) -> 65
A123: 116 | B123: Zement- und Kalkwerke Otterbein GmbH & Co. KG | C123: Mineral Processing | E123: 50.58432 | F123: 9.509245 | H123: 0.0495 | I123: =ROUND(Table101214[[#This Row],[H2-Potential in TWh/a]]*1000000/(365*24),0) -> 6 | J123: =Table101214[[#This Row],[Potential demand MWh/h]]/SUM($I$23:$I$379) -> 0.00020510717 | K123: =MIN(IF(Table101214[[#This Row],[Potential demand MWh/h]]>=$B$11,ROUND(Table101214[[#This Row],[Potential demand MWh/h]],0),0),$B$10) -> 0 | L123: =Table101214[[#This Row],[Electrolyser Potential MW]] -> 0 | M123: =ROUND(Table101214[[#This Row],[Potential Peak hour production MWh]]*$B$13,0) -> 0
