Workbook

Sheet Document map
A1: Capacities for Transmission Capacity Map RTS008_NS - DWH.rdl
B2: Cross-border IP within EU and with non-EU (export)
C3: Zeebrugge IZT
C4: Hilvarenbeek
C5: Eynatten 1 (BE) // Lichtenbusch / Raeren (DE)
C6: Remich
C7: Blaregnies L (BE) / Taisnières B (FR)
C8: Bocholtz
C9: Zevenaar
C10: Winterswijk
C11: Vlieghuis
C12: Epe (DE) (Eneco) / Enschede (NL)
C13: Epe (DE) (Nuon) / Enschede (NL)
C14: Epe (DE) / Enschede (NL)
... C85: Rep. San Marino
B86: Intra-Balancing Zone Point
C87: Nybro
C88: Kienbaum
C89: Broichweiden Süd
C90: Lampertheim IV
C91: Bunder-Tief
C92: Emsbüren-Berge
C93: Steinitz
C94: Wardenburg RG
C95: Gernsheim
C96: Point of Interconnection (PWP) (PL)
C97: Zone GASCADE / OGE
C98: Transfer Point NGTN <-> GTNTT
... C101: Drohne NOWAL
B102: Cross-border IP with non-EU (import)
C103: St. Fergus
C104: Dornum (EPT1 & EPT2)
C105: Emden (EPT1)
C106: Emden (NPT)
C107: Zeebrugge ZPT
C108: Dunkerque
C109: Easington
C110: Tarifa
C111: Almería
C112: Mazara del Vallo
...

Sheet Capacity Map
G2: Transmission Capacity Map 2021 | N2: Generated by PDWS
H5: Legend
H8: Virtual points are indicated with a "V" mention. By default the map displays interconnections only when firm technical capacity is existing.
C12: Number | E12: Point | I12: Arc | J12: Technical physical capacity (GWh/d) | K12: From Identifier | L12: From Operator | O12: From CC | P12: From BZ | Q12: To Identifier | S12: To Operator | T12: To CC | U12: To BZ | V12: Available Flow Directions | X12: Min GCV | Y12: Max GCV
C13: Cross-border IP within EU and with non-EU (export)
C14: 1 | E14: Zeebrugge IZT | I14: >IB-BEhz | J14: 651.7 | K14: 21Z0000000000074 | L14: Interconnector | O14: UK | P14: IUK | Q14: 21Z0000000000074 | S14: Fluxys Belgium | T14: BE | U14: BeLux | V14: B | W14: B | X14: 11.5 | Y14: 11.63
I15: IB-BEhz> | J15: 803.4 | K15: 21Z0000000000074 | L15: Fluxys Belgium | O15: BE | P15: BeLux | Q15: 21Z0000000000074 | S15: Interconnector | T15: UK | U15: IUK | V15: B | W15: B | X15: 11.5 | Y15: 11.63
C17: 4 | E17: Hilvarenbeek | I17: NL>BEl | J17: 595.6 | K17: 21Z000000000243T | L17: GTS | O17: NL | P17: Netherlands | Q17: 21Z000000000243T | S17: Fluxys Belgium | T17: BE | U17: L-Zone | V17: Y | W17: Y | X17: 9.77 | Y17: 9.77
C19: 6 | E19: Eynatten 1 (BE) // Lichtenbusch / Raeren (DE) | I19: >IB-BEhe | J19: 127.8 | K19: 21Z0000000000155 | L19: GASCADE Gastransport | O19: DE | P19: GASPOOL | Q19: 21Z0000000000155 | S19: Fluxys Belgium | T19: BE | U19: BeLux | V19: B | W19: B | X19: 11.63 | Y19: 11.63
I20: IB-BEhe> | J20: 129.5 | K20: 21Z0000000000155 | L20: Fluxys Belgium | O20: BE | P20: BeLux | Q20: 21Z0000000000155 | S20: GASCADE Gastransport | T20: DE | U20: GASPOOL | V20: B | W20: B | X20: 11.63 | Y20: 11.63
C22: 8 | E22: Remich | I22: DEn>LU | J22: 26.71 | K22: 21Z0000000000406 | L22: Open Grid Europe | O22: DE | P22: NCG | Q22: 21Z0000000000406 | S22: Creos Luxembourg | T22: LU | U22: BeLux | V22: Y | W22: N | X22: 10.715 | Y22: 11.469
C25: 10 | E25: Blaregnies L (BE) / Taisnières B (FR) | I25: BEl>FRnL | J25: 230 | K25: 21Z000000000011D | L25: Fluxys Belgium | O25: BE | P25: L-Zone | Q25: 21Z000000000011D | S25: GRTgaz | T25: FR | U25: TRF | V25: Y | W25: N | X25: 9.77 | Y25: 10.3
C27: 11 | E27: Bocholtz | I27: IB-NLn> | J27: 16.665 | Q27: 21Z000000000071W | S27: Open Grid Europe | T27: DE | U27: NCG | W27: Y | X27: 11.245 | Y27: 11.702
J28: 14.2 | S28: Fluxys TENP | T28: DE | U28: NCG
C30: 12 | E30: Zevenaar | I30: IB-NLn> | J30: 150.24 | Q30: 21Y0000000001367 | S30: Open Grid Europe | T30: DE | U30: NCG | W30: Y | X30: 9.914 | Y30: 10.419
S31: Thyssengas | T31: De | U31: NCG | W31: Y
C33: 13 | E33: Winterswijk | I33: IB-NLn> | J33: 140.016 | Q33: 21Z000000000073S | S33: Open Grid Europe | T33: DE | U33: NCG | W33: Y | X33: 9.994 | Y33: 10.418
C35: 14 | E35: Vlieghuis | I35: IB-NLg> | J35: 100.8 | K35: 21Z000000000135W | L35: GTS | O35: NL | P35: Netherlands | S35: RWE | V35: Y
C37: 15 | E37: Epe (DE) (Eneco) / Enschede (NL) Interconnection points between German storages and GTS.The capacities indicated do not allow to enter the German transmission systems. | I37: >IB-NLu | J37: 93.6 | L37: Eneco Gasspeicher B.V | O37: DE | P37: Germany | Q37: 21W000000000012G | S37: GTS | T37: NL | U37: Netherlands | W37: B
I38: IB-NLu> | J38: 46.8 | K38: 21W000000000012G | L38: GTS | O38: NL | P38: Netherlands | S38: Eneco Gasspeicher B.V | T38: DE | U38: Germany | V38: B
E39: Epe (DE) (Nuon) / Enschede (NL) Interconnection points between German storages and GTS.The capacities indicated do not allow to enter the German transmission systems. | I39: IB-NLu> | J39: 70.3 | K39: 21Z000000000109X | L39: GTS | O39: NL | P39: Netherlands | S39: Nuon Epe Gasspeicher | T39: DE | U39: Germany | V39: B
I40: IB-STcDEmLmL> | J40: 117.2 | L40: Nuon Epe Gasspeicher | O40: DE | P40: Germany | Q40: 21Z000000000109X | S40: GTS | T40: NL | U40: Netherlands | W40: B
E41: Epe (DE) / Enschede (NL) Interconnection points between German storages and GTS.The capacities indicated do not allow to enter the German transmission systems. | I41: >IB-NLu | J41: 103.5 | L41: Innogy | O41: DE | P41: Germany | Q41: 21Z000000000108Z | S41: GTS | T41: NL | U41: Netherlands | W41: B
I42: IB-NLu> | J42: 47.73 | K42: 21Z000000000108Z | L42: GTS | O42: NL | P42: Netherlands | S42: Innogy | T42: DE | U42: Germany | V42: B
C44: 16 | E44: Bunde (DE) / Oude Statenzijl (H) (NL) (GASCADE) GTS entries at Emden EPT and Bunde/OSZ (OGE, GUD-H, GASCADE) are limited by a cluster capacity of 1.847,1 GWh/d, GTS exits at Bunde/OSZ (OGE, GUD-H, GASCADE) are limited to 504,0 GWh/d. | I44: >IB-NLg | J44: 190.7 | K44: 21Z000000000074Q | L44: GASCADE Gastransport | O44: DE | P44: GASPOOL | V44: B
I45: IB-NLg> | J45: 0 | Q45: 21Z000000000074Q | S45: GASCADE Gastransport | T45: DE | U45: GASPOOL | W45: B
E46: Bunde (DE) / Oude Statenzijl (H) (NL) I (OGE) GTS entries at Emden EPT and Bunde/OSZ (OGE, GUD-H, GASCADE) are limited by a cluster capacity of 1.847,1 GWh/d, GTS exits at Bunde/OSZ (OGE, GUD-H, GASCADE) are limited to 504,0 GWh/d. | I46: IB-NLn> | J46: 71.5 | Q46: 21Z000000000075O | S46: Open Grid Europe | T46: DE | U46: NCG | W46: B | X46: 11.199 | Y46: 11.624
E47: Bunde (DE) / Oude Statenzijl (L) (NL) (GUD) | I47: IB-NLg> | J47: 9.6 | Q47: 21Z000000000078I | S47: Gasunie Deutschland | T47: DE | U47: GASPOOL | W47: N
E48: Etzel (DE) (Crystal) / Oude Statenzijl (NL) Interconnection points between German storages and GTS.The capacities indicated do not allow to enter the German transmission systems. | I48: IB-NLu> | J48: 56.4 | K48: 21W000000000013E | L48: GTS | O48: NL | P48: Netherlands | S48: Crystal | T48: DE | V48: B
I49: IB-STcDEmm> | J49: 76.5 | L49: Crystal | O49: DE | Q49: 21W000000000013E | S49: GTS | T49: NL | U49: Netherlands | W49: B
E50: Etzel (DE) (EKB) / Oude Statenzijl Etzel (NL) Interconnection points between German storages and GTS.The capacities indicated do not allow to enter the German transmission systems. | I50: IB-NLu> | J50: 74.9 | K50: 21W0000000000095 | L50: GTS | O50: NL | P50: Netherlands | S50: EKB | T50: DE | V50: B
I51: IB-STcDEmm> | J51: 115.3 | L51: EKB | O51: DE | Q51: 21W0000000000095 | S51: GTS | T51: NL | U51: Netherlands | W51: B
E52: Etzel (DE) (OMV) Freya / Oude Statenzijl Etzel Interconnection points between German storages and GTS.The capacities indicated do not allow to enter the German transmission systems. | I52: IB-NLu> | J52: 80.9 | K52: 21W000000000014C | L52: GTS | O52: NL | P52: Netherlands | S52: OMV | T52: DE | V52: B
I53: IB-STcDEmm> | J53: 95.2 | L53: OMV | Q53: 21W000000000014C | S53: GTS | T53: NL | U53: Netherlands | W53: B
E54: Nüttermoor (DE) (EWE) H / Oude Statenzijl (H) (NL) Interconnection points between German storages and GTS.The capacities indicated do not allow to enter the German transmission systems. | I54: IB-NLu> | J54: 59 | K54: 21Z000000000250W | L54: GTS | O54: NL | P54: Netherlands | S54: EWE Gasspeicher | T54: DE | V54: B
I55: IB-STcDEmm> | J55: 55 | L55: EWE Gasspeicher | O55: DE | Q55: 21Z000000000250W | S55: GTS | T55: NL | U55: Netherlands | W55: B
E56: Nüttermoor H-1 (DE) (EWE) Renato / Oude Statenzijl (NL) Interconnection points between German storages and GTS.The capacities indicated do not allow to enter the German transmission systems. | I56: >IB-NLu | J56: 69.6 | L56: EWE Gasspeicher | O56: DE | Q56: 21Z000000000077K | S56: GTS | T56: NL | U56: Netherlands | W56: B
I57: IB-NLu> | J57: 48.72 | K57: 21Z000000000077K | L57: GTS | O57: NL | P57: Netherlands | S57: EWE Gasspeicher | T57: DE | V57: B
C59: 18 | E59: Bacton (IUK) | I59: >IB-UKb | J59: 651.7 | L59: National Grid Gas | O59: UK | Q59: 21Z000000000084N | S59: Interconnector | T59: UK | U59: IUK | W59: B | X59: 11.5 | Y59: 11.5
I60: IB-UKb> | J60: 803.4 | K60: 21Z000000000084N | L60: Interconnector | O60: UK | P60: IUK | S60: National Grid Gas | T60: UK | V60: B | X60: 11.5 | Y60: 11.5
...

Sheet Cross_table
B1: Column1 | C1: UK | D1: BE | E1: NL | F1: DE | G1: AT | H1: IT | I1: CH | J1: SI | K1: HR | L1: FR | M1: DK | N1: PL | O1: CZ | P1: SK | Q1: HU | R1: RS | S1: BG | T1: GR | U1: RO | V1: LT | W1: LV | X1: ES | Y1: PT | Z1: UA | AA1: MD | AB1: RU | AC1: AL | AD1: LU | AE1: IE | AF1: BA | AG1: MK | AH1: TR | AI1: SM | AJ1: NO | AK1: DZ | AL1: TN | AM1: LY | AN1: BY | AO1: EE | AP1: FI
B2: UK | C2: =SUMIFS('Capacity Map'!$J$14:$J$287,'Capacity Map'!$O$14:$O$287,Cross_table!$B2,'Capacity Map'!$T$14:$T$287,Cross_table!C$1)+SUMIFS('Capacity Map'!$J$335:$J$417,'Capacity Map'!$O$335:$O$417,Cross_table!$B2,'Capacity Map'!$T$335:$T$417,Cross_table!C$1) -> 1455.1 | D2: =SUMIFS('Capacity Map'!$J$14:$J$287,'Capacity Map'!$O$14:$O$287,Cross_table!$B2,'Capacity Map'!$T$14:$T$287,Cross_table!D$1)+SUMIFS('Capacity Map'!$J$335:$J$417,'Capacity Map'!$O$335:$O$417,Cross_table!$B2,'Capacity Map'!$T$335:$T$417,Cross_table!D$1) -> 651.7 | E2: =SUMIFS('Capacity Map'!$J$14:$J$287,'Capacity Map'!$O$14:$O$287,Cross_table!$B2,'Capacity Map'!$T$14:$T$287,Cross_table!E$1)+SUMIFS('Capacity Map'!$J$335:$J$417,'Capacity Map'!$O$335:$O$417,Cross_table!$B2,'Capacity Map'!$T$335:$T$417,Cross_table!E$1) -> 0 | F2: =SUMIFS('Capacity Map'!$J$14:$J$287,'Capacity Map'!$O$14:$O$287,Cross_table!$B2,'Capacity Map'!$T$14:$T$287,Cross_table!F$1)+SUMIFS('Capacity Map'!$J$335:$J$417,'Capacity Map'!$O$335:$O$417,Cross_table!$B2,'Capacity Map'!$T$335:$T$417,Cross_table!F$1) -> 0 | G2: =SUMIFS('Capacity Map'!$J$14:$J$287,'Capacity Map'!$O$14:$O$287,Cross_table!$B2,'Capacity Map'!$T$14:$T$287,Cross_table!G$1)+SUMIFS('Capacity Map'!$J$335:$J$417,'Capacity Map'!$O$335:$O$417,Cross_table!$B2,'Capacity Map'!$T$335:$T$417,Cross_table!G$1) -> 0 | H2: =SUMIFS('Capacity Map'!$J$14:$J$287,'Capacity Map'!$O$14:$O$287,Cross_table!$B2,'Capacity Map'!$T$14:$T$287,Cross_table!H$1)+SUMIFS('Capacity Map'!$J$335:$J$417,'Capacity Map'!$O$335:$O$417,Cross_table!$B2,'Capacity Map'!$T$335:$T$417,Cross_table!H$1) -> 0 | I2: =SUMIFS('Capacity Map'!$J$14:$J$287,'Capacity Map'!$O$14:$O$287,Cross_table!$B2,'Capacity Map'!$T$14:$T$287,Cross_table!I$1)+SUMIFS('Capacity Map'!$J$335:$J$417,'Capacity Map'!$O$335:$O$417,Cross_table!$B2,'Capacity Map'!$T$335:$T$417,Cross_table!I$1) -> 0 | J2: =SUMIFS('Capacity Map'!$J$14:$J$287,'Capacity Map'!$O$14:$O$287,Cross_table!$B2,'Capacity Map'!$T$14:$T$287,Cross_table!J$1)+SUMIFS('Capacity Map'!$J$335:$J$417,'Capacity Map'!$O$335:$O$417,Cross_table!$B2,'Capacity Map'!$T$335:$T$417,Cross_table!J$1) -> 0 | ... AP2: =SUMIFS('Capacity Map'!$J$14:$J$287,'Capacity Map'!$O$14:$O$287,Cross_table!$B2,'Capacity Map'!$T$14:$T$287,Cross_table!AP$1)+SUMIFS('Capacity Map'!$J$335:$J$417,'Capacity Map'!$O$335:$O$417,Cross_table!$B2,'Capacity Map'!$T$335:$T$417,Cross_table!AP$1) -> 0
B3: BE | C3: =SUMIFS('Capacity Map'!$J$14:$J$287,'Capacity Map'!$O$14:$O$287,Cross_table!$B3,'Capacity Map'!$T$14:$T$287,Cross_table!C$1)+SUMIFS('Capacity Map'!$J$335:$J$417,'Capacity Map'!$O$335:$O$417,Cross_table!$B3,'Capacity Map'!$T$335:$T$417,Cross_table!C$1) -> 803.4 | D3: =SUMIFS('Capacity Map'!$J$14:$J$287,'Capacity Map'!$O$14:$O$287,Cross_table!$B3,'Capacity Map'!$T$14:$T$287,Cross_table!D$1)+SUMIFS('Capacity Map'!$J$335:$J$417,'Capacity Map'!$O$335:$O$417,Cross_table!$B3,'Capacity Map'!$T$335:$T$417,Cross_table!D$1) -> 0 | E3: =SUMIFS('Capacity Map'!$J$14:$J$287,'Capacity Map'!$O$14:$O$287,Cross_table!$B3,'Capacity Map'!$T$14:$T$287,Cross_table!E$1)+SUMIFS('Capacity Map'!$J$335:$J$417,'Capacity Map'!$O$335:$O$417,Cross_table!$B3,'Capacity Map'!$T$335:$T$417,Cross_table!E$1) -> 331.2 | F3: =SUMIFS('Capacity Map'!$J$14:$J$287,'Capacity Map'!$O$14:$O$287,Cross_table!$B3,'Capacity Map'!$T$14:$T$287,Cross_table!F$1)+SUMIFS('Capacity Map'!$J$335:$J$417,'Capacity Map'!$O$335:$O$417,Cross_table!$B3,'Capacity Map'!$T$335:$T$417,Cross_table!F$1) -> 322.77 | G3: =SUMIFS('Capacity Map'!$J$14:$J$287,'Capacity Map'!$O$14:$O$287,Cross_table!$B3,'Capacity Map'!$T$14:$T$287,Cross_table!G$1)+SUMIFS('Capacity Map'!$J$335:$J$417,'Capacity Map'!$O$335:$O$417,Cross_table!$B3,'Capacity Map'!$T$335:$T$417,Cross_table!G$1) -> 0 | H3: =SUMIFS('Capacity Map'!$J$14:$J$287,'Capacity Map'!$O$14:$O$287,Cross_table!$B3,'Capacity Map'!$T$14:$T$287,Cross_table!H$1)+SUMIFS('Capacity Map'!$J$335:$J$417,'Capacity Map'!$O$335:$O$417,Cross_table!$B3,'Capacity Map'!$T$335:$T$417,Cross_table!H$1) -> 0 | I3: =SUMIFS('Capacity Map'!$J$14:$J$287,'Capacity Map'!$O$14:$O$287,Cross_table!$B3,'Capacity Map'!$T$14:$T$287,Cross_table!I$1)+SUMIFS('Capacity Map'!$J$335:$J$417,'Capacity Map'!$O$335:$O$417,Cross_table!$B3,'Capacity Map'!$T$335:$T$417,Cross_table!I$1) -> 0 | J3: =SUMIFS('Capacity Map'!$J$14:$J$287,'Capacity Map'!$O$14:$O$287,Cross_table!$B3,'Capacity Map'!$T$14:$T$287,Cross_table!J$1)+SUMIFS('Capacity Map'!$J$335:$J$417,'Capacity Map'!$O$335:$O$417,Cross_table!$B3,'Capacity Map'!$T$335:$T$417,Cross_table!J$1) -> 0 | ... AP3: =SUMIFS('Capacity Map'!$J$14:$J$287,'Capacity Map'!$O$14:$O$287,Cross_table!$B3,'Capacity Map'!$T$14:$T$287,Cross_table!AP$1)+SUMIFS('Capacity Map'!$J$335:$J$417,'Capacity Map'!$O$335:$O$417,Cross_table!$B3,'Capacity Map'!$T$335:$T$417,Cross_table!AP$1) -> 0
B4: NL | C4: =SUMIFS('Capacity Map'!$J$14:$J$287,'Capacity Map'!$O$14:$O$287,Cross_table!$B4,'Capacity Map'!$T$14:$T$287,Cross_table!C$1)+SUMIFS('Capacity Map'!$J$335:$J$417,'Capacity Map'!$O$335:$O$417,Cross_table!$B4,'Capacity Map'!$T$335:$T$417,Cross_table!C$1) -> 0 | D4: =SUMIFS('Capacity Map'!$J$14:$J$287,'Capacity Map'!$O$14:$O$287,Cross_table!$B4,'Capacity Map'!$T$14:$T$287,Cross_table!D$1)+SUMIFS('Capacity Map'!$J$335:$J$417,'Capacity Map'!$O$335:$O$417,Cross_table!$B4,'Capacity Map'!$T$335:$T$417,Cross_table!D$1) -> 1397.2 | E4: =SUMIFS('Capacity Map'!$J$14:$J$287,'Capacity Map'!$O$14:$O$287,Cross_table!$B4,'Capacity Map'!$T$14:$T$287,Cross_table!E$1)+SUMIFS('Capacity Map'!$J$335:$J$417,'Capacity Map'!$O$335:$O$417,Cross_table!$B4,'Capacity Map'!$T$335:$T$417,Cross_table!E$1) -> 0 | F4: =SUMIFS('Capacity Map'!$J$14:$J$287,'Capacity Map'!$O$14:$O$287,Cross_table!$B4,'Capacity Map'!$T$14:$T$287,Cross_table!F$1)+SUMIFS('Capacity Map'!$J$335:$J$417,'Capacity Map'!$O$335:$O$417,Cross_table!$B4,'Capacity Map'!$T$335:$T$417,Cross_table!F$1) -> 1925.773 | G4: =SUMIFS('Capacity Map'!$J$14:$J$287,'Capacity Map'!$O$14:$O$287,Cross_table!$B4,'Capacity Map'!$T$14:$T$287,Cross_table!G$1)+SUMIFS('Capacity Map'!$J$335:$J$417,'Capacity Map'!$O$335:$O$417,Cross_table!$B4,'Capacity Map'!$T$335:$T$417,Cross_table!G$1) -> 0 | H4: =SUMIFS('Capacity Map'!$J$14:$J$287,'Capacity Map'!$O$14:$O$287,Cross_table!$B4,'Capacity Map'!$T$14:$T$287,Cross_table!H$1)+SUMIFS('Capacity Map'!$J$335:$J$417,'Capacity Map'!$O$335:$O$417,Cross_table!$B4,'Capacity Map'!$T$335:$T$417,Cross_table!H$1) -> 0 | I4: =SUMIFS('Capacity Map'!$J$14:$J$287,'Capacity Map'!$O$14:$O$287,Cross_table!$B4,'Capacity Map'!$T$14:$T$287,Cross_table!I$1)+SUMIFS('Capacity Map'!$J$335:$J$417,'Capacity Map'!$O$335:$O$417,Cross_table!$B4,'Capacity Map'!$T$335:$T$417,Cross_table!I$1) -> 0 | J4: =SUMIFS('Capacity Map'!$J$14:$J$287,'Capacity Map'!$O$14:$O$287,Cross_table!$B4,'Capacity Map'!$T$14:$T$287,Cross_table!J$1)+SUMIFS('Capacity Map'!$J$335:$J$417,'Capacity Map'!$O$335:$O$417,Cross_table!$B4,'Capacity Map'!$T$335:$T$417,Cross_table!J$1) -> 0 | ... AP4: =SUMIFS('Capacity Map'!$J$14:$J$287,'Capacity Map'!$O$14:$O$287,Cross_table!$B4,'Capacity Map'!$T$14:$T$287,Cross_table!AP$1)+SUMIFS('Capacity Map'!$J$335:$J$417,'Capacity Map'!$O$335:$O$417,Cross_table!$B4,'Capacity Map'!$T$335:$T$417,Cross_table!AP$1) -> 0
B5: DE | C5: =SUMIFS('Capacity Map'!$J$14:$J$287,'Capacity Map'!$O$14:$O$287,Cross_table!$B5,'Capacity Map'!$T$14:$T$287,Cross_table!C$1)+SUMIFS('Capacity Map'!$J$335:$J$417,'Capacity Map'!$O$335:$O$417,Cross_table!$B5,'Capacity Map'!$T$335:$T$417,Cross_table!C$1) -> 0 | D5: =SUMIFS('Capacity Map'!$J$14:$J$287,'Capacity Map'!$O$14:$O$287,Cross_table!$B5,'Capacity Map'!$T$14:$T$287,Cross_table!D$1)+SUMIFS('Capacity Map'!$J$335:$J$417,'Capacity Map'!$O$335:$O$417,Cross_table!$B5,'Capacity Map'!$T$335:$T$417,Cross_table!D$1) -> 396.15 | E5: =SUMIFS('Capacity Map'!$J$14:$J$287,'Capacity Map'!$O$14:$O$287,Cross_table!$B5,'Capacity Map'!$T$14:$T$287,Cross_table!E$1)+SUMIFS('Capacity Map'!$J$335:$J$417,'Capacity Map'!$O$335:$O$417,Cross_table!$B5,'Capacity Map'!$T$335:$T$417,Cross_table!E$1) -> 1628.303 | F5: =SUMIFS('Capacity Map'!$J$14:$J$287,'Capacity Map'!$O$14:$O$287,Cross_table!$B5,'Capacity Map'!$T$14:$T$287,Cross_table!F$1)+SUMIFS('Capacity Map'!$J$335:$J$417,'Capacity Map'!$O$335:$O$417,Cross_table!$B5,'Capacity Map'!$T$335:$T$417,Cross_table!F$1) -> 669 | G5: =SUMIFS('Capacity Map'!$J$14:$J$287,'Capacity Map'!$O$14:$O$287,Cross_table!$B5,'Capacity Map'!$T$14:$T$287,Cross_table!G$1)+SUMIFS('Capacity Map'!$J$335:$J$417,'Capacity Map'!$O$335:$O$417,Cross_table!$B5,'Capacity Map'!$T$335:$T$417,Cross_table!G$1) -> 344.248 | H5: =SUMIFS('Capacity Map'!$J$14:$J$287,'Capacity Map'!$O$14:$O$287,Cross_table!$B5,'Capacity Map'!$T$14:$T$287,Cross_table!H$1)+SUMIFS('Capacity Map'!$J$335:$J$417,'Capacity Map'!$O$335:$O$417,Cross_table!$B5,'Capacity Map'!$T$335:$T$417,Cross_table!H$1) -> 0 | I5: =SUMIFS('Capacity Map'!$J$14:$J$287,'Capacity Map'!$O$14:$O$287,Cross_table!$B5,'Capacity Map'!$T$14:$T$287,Cross_table!I$1)+SUMIFS('Capacity Map'!$J$335:$J$417,'Capacity Map'!$O$335:$O$417,Cross_table!$B5,'Capacity Map'!$T$335:$T$417,Cross_table!I$1) -> 328 | J5: =SUMIFS('Capacity Map'!$J$14:$J$287,'Capacity Map'!$O$14:$O$287,Cross_table!$B5,'Capacity Map'!$T$14:$T$287,Cross_table!J$1)+SUMIFS('Capacity Map'!$J$335:$J$417,'Capacity Map'!$O$335:$O$417,Cross_table!$B5,'Capacity Map'!$T$335:$T$417,Cross_table!J$1) -> 0 | ... AP5: =SUMIFS('Capacity Map'!$J$14:$J$287,'Capacity Map'!$O$14:$O$287,Cross_table!$B5,'Capacity Map'!$T$14:$T$287,Cross_table!AP$1)+SUMIFS('Capacity Map'!$J$335:$J$417,'Capacity Map'!$O$335:$O$417,Cross_table!$B5,'Capacity Map'!$T$335:$T$417,Cross_table!AP$1) -> 0
B6: AT | C6: =SUMIFS('Capacity Map'!$J$14:$J$287,'Capacity Map'!$O$14:$O$287,Cross_table!$B6,'Capacity Map'!$T$14:$T$287,Cross_table!C$1)+SUMIFS('Capacity Map'!$J$335:$J$417,'Capacity Map'!$O$335:$O$417,Cross_table!$B6,'Capacity Map'!$T$335:$T$417,Cross_table!C$1) -> 0 | D6: =SUMIFS('Capacity Map'!$J$14:$J$287,'Capacity Map'!$O$14:$O$287,Cross_table!$B6,'Capacity Map'!$T$14:$T$287,Cross_table!D$1)+SUMIFS('Capacity Map'!$J$335:$J$417,'Capacity Map'!$O$335:$O$417,Cross_table!$B6,'Capacity Map'!$T$335:$T$417,Cross_table!D$1) -> 0 | E6: =SUMIFS('Capacity Map'!$J$14:$J$287,'Capacity Map'!$O$14:$O$287,Cross_table!$B6,'Capacity Map'!$T$14:$T$287,Cross_table!E$1)+SUMIFS('Capacity Map'!$J$335:$J$417,'Capacity Map'!$O$335:$O$417,Cross_table!$B6,'Capacity Map'!$T$335:$T$417,Cross_table!E$1) -> 0 | F6: =SUMIFS('Capacity Map'!$J$14:$J$287,'Capacity Map'!$O$14:$O$287,Cross_table!$B6,'Capacity Map'!$T$14:$T$287,Cross_table!F$1)+SUMIFS('Capacity Map'!$J$335:$J$417,'Capacity Map'!$O$335:$O$417,Cross_table!$B6,'Capacity Map'!$T$335:$T$417,Cross_table!F$1) -> 339.968 | G6: =SUMIFS('Capacity Map'!$J$14:$J$287,'Capacity Map'!$O$14:$O$287,Cross_table!$B6,'Capacity Map'!$T$14:$T$287,Cross_table!G$1)+SUMIFS('Capacity Map'!$J$335:$J$417,'Capacity Map'!$O$335:$O$417,Cross_table!$B6,'Capacity Map'!$T$335:$T$417,Cross_table!G$1) -> 0 | H6: =SUMIFS('Capacity Map'!$J$14:$J$287,'Capacity Map'!$O$14:$O$287,Cross_table!$B6,'Capacity Map'!$T$14:$T$287,Cross_table!H$1)+SUMIFS('Capacity Map'!$J$335:$J$417,'Capacity Map'!$O$335:$O$417,Cross_table!$B6,'Capacity Map'!$T$335:$T$417,Cross_table!H$1) -> 1150 | I6: =SUMIFS('Capacity Map'!$J$14:$J$287,'Capacity Map'!$O$14:$O$287,Cross_table!$B6,'Capacity Map'!$T$14:$T$287,Cross_table!I$1)+SUMIFS('Capacity Map'!$J$335:$J$417,'Capacity Map'!$O$335:$O$417,Cross_table!$B6,'Capacity Map'!$T$335:$T$417,Cross_table!I$1) -> 0 | J6: =SUMIFS('Capacity Map'!$J$14:$J$287,'Capacity Map'!$O$14:$O$287,Cross_table!$B6,'Capacity Map'!$T$14:$T$287,Cross_table!J$1)+SUMIFS('Capacity Map'!$J$335:$J$417,'Capacity Map'!$O$335:$O$417,Cross_table!$B6,'Capacity Map'!$T$335:$T$417,Cross_table!J$1) -> 112.5 | ... AP6: =SUMIFS('Capacity Map'!$J$14:$J$287,'Capacity Map'!$O$14:$O$287,Cross_table!$B6,'Capacity Map'!$T$14:$T$287,Cross_table!AP$1)+SUMIFS('Capacity Map'!$J$335:$J$417,'Capacity Map'!$O$335:$O$417,Cross_table!$B6,'Capacity Map'!$T$335:$T$417,Cross_table!AP$1) -> 0
B7: IT | C7: =SUMIFS('Capacity Map'!$J$14:$J$287,'Capacity Map'!$O$14:$O$287,Cross_table!$B7,'Capacity Map'!$T$14:$T$287,Cross_table!C$1)+SUMIFS('Capacity Map'!$J$335:$J$417,'Capacity Map'!$O$335:$O$417,Cross_table!$B7,'Capacity Map'!$T$335:$T$417,Cross_table!C$1) -> 0 | D7: =SUMIFS('Capacity Map'!$J$14:$J$287,'Capacity Map'!$O$14:$O$287,Cross_table!$B7,'Capacity Map'!$T$14:$T$287,Cross_table!D$1)+SUMIFS('Capacity Map'!$J$335:$J$417,'Capacity Map'!$O$335:$O$417,Cross_table!$B7,'Capacity Map'!$T$335:$T$417,Cross_table!D$1) -> 0 | E7: =SUMIFS('Capacity Map'!$J$14:$J$287,'Capacity Map'!$O$14:$O$287,Cross_table!$B7,'Capacity Map'!$T$14:$T$287,Cross_table!E$1)+SUMIFS('Capacity Map'!$J$335:$J$417,'Capacity Map'!$O$335:$O$417,Cross_table!$B7,'Capacity Map'!$T$335:$T$417,Cross_table!E$1) -> 0 | F7: =SUMIFS('Capacity Map'!$J$14:$J$287,'Capacity Map'!$O$14:$O$287,Cross_table!$B7,'Capacity Map'!$T$14:$T$287,Cross_table!F$1)+SUMIFS('Capacity Map'!$J$335:$J$417,'Capacity Map'!$O$335:$O$417,Cross_table!$B7,'Capacity Map'!$T$335:$T$417,Cross_table!F$1) -> 0 | G7: =SUMIFS('Capacity Map'!$J$14:$J$287,'Capacity Map'!$O$14:$O$287,Cross_table!$B7,'Capacity Map'!$T$14:$T$287,Cross_table!G$1)+SUMIFS('Capacity Map'!$J$335:$J$417,'Capacity Map'!$O$335:$O$417,Cross_table!$B7,'Capacity Map'!$T$335:$T$417,Cross_table!G$1) -> 193.5 | H7: =SUMIFS('Capacity Map'!$J$14:$J$287,'Capacity Map'!$O$14:$O$287,Cross_table!$B7,'Capacity Map'!$T$14:$T$287,Cross_table!H$1)+SUMIFS('Capacity Map'!$J$335:$J$417,'Capacity Map'!$O$335:$O$417,Cross_table!$B7,'Capacity Map'!$T$335:$T$417,Cross_table!H$1) -> 0 | I7: =SUMIFS('Capacity Map'!$J$14:$J$287,'Capacity Map'!$O$14:$O$287,Cross_table!$B7,'Capacity Map'!$T$14:$T$287,Cross_table!I$1)+SUMIFS('Capacity Map'!$J$335:$J$417,'Capacity Map'!$O$335:$O$417,Cross_table!$B7,'Capacity Map'!$T$335:$T$417,Cross_table!I$1) -> 431.4 | J7: =SUMIFS('Capacity Map'!$J$14:$J$287,'Capacity Map'!$O$14:$O$287,Cross_table!$B7,'Capacity Map'!$T$14:$T$287,Cross_table!J$1)+SUMIFS('Capacity Map'!$J$335:$J$417,'Capacity Map'!$O$335:$O$417,Cross_table!$B7,'Capacity Map'!$T$335:$T$417,Cross_table!J$1) -> 28.5 | ... AP7: =SUMIFS('Capacity Map'!$J$14:$J$287,'Capacity Map'!$O$14:$O$287,Cross_table!$B7,'Capacity Map'!$T$14:$T$287,Cross_table!AP$1)+SUMIFS('Capacity Map'!$J$335:$J$417,'Capacity Map'!$O$335:$O$417,Cross_table!$B7,'Capacity Map'!$T$335:$T$417,Cross_table!AP$1) -> 0
B8: CH | C8: =SUMIFS('Capacity Map'!$J$14:$J$287,'Capacity Map'!$O$14:$O$287,Cross_table!$B8,'Capacity Map'!$T$14:$T$287,Cross_table!C$1)+SUMIFS('Capacity Map'!$J$335:$J$417,'Capacity Map'!$O$335:$O$417,Cross_table!$B8,'Capacity Map'!$T$335:$T$417,Cross_table!C$1) -> 0 | D8: =SUMIFS('Capacity Map'!$J$14:$J$287,'Capacity Map'!$O$14:$O$287,Cross_table!$B8,'Capacity Map'!$T$14:$T$287,Cross_table!D$1)+SUMIFS('Capacity Map'!$J$335:$J$417,'Capacity Map'!$O$335:$O$417,Cross_table!$B8,'Capacity Map'!$T$335:$T$417,Cross_table!D$1) -> 0 | E8: =SUMIFS('Capacity Map'!$J$14:$J$287,'Capacity Map'!$O$14:$O$287,Cross_table!$B8,'Capacity Map'!$T$14:$T$287,Cross_table!E$1)+SUMIFS('Capacity Map'!$J$335:$J$417,'Capacity Map'!$O$335:$O$417,Cross_table!$B8,'Capacity Map'!$T$335:$T$417,Cross_table!E$1) -> 0 | F8: =SUMIFS('Capacity Map'!$J$14:$J$287,'Capacity Map'!$O$14:$O$287,Cross_table!$B8,'Capacity Map'!$T$14:$T$287,Cross_table!F$1)+SUMIFS('Capacity Map'!$J$335:$J$417,'Capacity Map'!$O$335:$O$417,Cross_table!$B8,'Capacity Map'!$T$335:$T$417,Cross_table!F$1) -> 172.8 | G8: =SUMIFS('Capacity Map'!$J$14:$J$287,'Capacity Map'!$O$14:$O$287,Cross_table!$B8,'Capacity Map'!$T$14:$T$287,Cross_table!G$1)+SUMIFS('Capacity Map'!$J$335:$J$417,'Capacity Map'!$O$335:$O$417,Cross_table!$B8,'Capacity Map'!$T$335:$T$417,Cross_table!G$1) -> 0 | H8: =SUMIFS('Capacity Map'!$J$14:$J$287,'Capacity Map'!$O$14:$O$287,Cross_table!$B8,'Capacity Map'!$T$14:$T$287,Cross_table!H$1)+SUMIFS('Capacity Map'!$J$335:$J$417,'Capacity Map'!$O$335:$O$417,Cross_table!$B8,'Capacity Map'!$T$335:$T$417,Cross_table!H$1) -> 640.4 | I8: =SUMIFS('Capacity Map'!$J$14:$J$287,'Capacity Map'!$O$14:$O$287,Cross_table!$B8,'Capacity Map'!$T$14:$T$287,Cross_table!I$1)+SUMIFS('Capacity Map'!$J$335:$J$417,'Capacity Map'!$O$335:$O$417,Cross_table!$B8,'Capacity Map'!$T$335:$T$417,Cross_table!I$1) -> 0 | J8: =SUMIFS('Capacity Map'!$J$14:$J$287,'Capacity Map'!$O$14:$O$287,Cross_table!$B8,'Capacity Map'!$T$14:$T$287,Cross_table!J$1)+SUMIFS('Capacity Map'!$J$335:$J$417,'Capacity Map'!$O$335:$O$417,Cross_table!$B8,'Capacity Map'!$T$335:$T$417,Cross_table!J$1) -> 0 | ... AP8: =SUMIFS('Capacity Map'!$J$14:$J$287,'Capacity Map'!$O$14:$O$287,Cross_table!$B8,'Capacity Map'!$T$14:$T$287,Cross_table!AP$1)+SUMIFS('Capacity Map'!$J$335:$J$417,'Capacity Map'!$O$335:$O$417,Cross_table!$B8,'Capacity Map'!$T$335:$T$417,Cross_table!AP$1) -> 0
B9: SI | C9: =SUMIFS('Capacity Map'!$J$14:$J$287,'Capacity Map'!$O$14:$O$287,Cross_table!$B9,'Capacity Map'!$T$14:$T$287,Cross_table!C$1)+SUMIFS('Capacity Map'!$J$335:$J$417,'Capacity Map'!$O$335:$O$417,Cross_table!$B9,'Capacity Map'!$T$335:$T$417,Cross_table!C$1) -> 0 | D9: =SUMIFS('Capacity Map'!$J$14:$J$287,'Capacity Map'!$O$14:$O$287,Cross_table!$B9,'Capacity Map'!$T$14:$T$287,Cross_table!D$1)+SUMIFS('Capacity Map'!$J$335:$J$417,'Capacity Map'!$O$335:$O$417,Cross_table!$B9,'Capacity Map'!$T$335:$T$417,Cross_table!D$1) -> 0 | E9: =SUMIFS('Capacity Map'!$J$14:$J$287,'Capacity Map'!$O$14:$O$287,Cross_table!$B9,'Capacity Map'!$T$14:$T$287,Cross_table!E$1)+SUMIFS('Capacity Map'!$J$335:$J$417,'Capacity Map'!$O$335:$O$417,Cross_table!$B9,'Capacity Map'!$T$335:$T$417,Cross_table!E$1) -> 0 | F9: =SUMIFS('Capacity Map'!$J$14:$J$287,'Capacity Map'!$O$14:$O$287,Cross_table!$B9,'Capacity Map'!$T$14:$T$287,Cross_table!F$1)+SUMIFS('Capacity Map'!$J$335:$J$417,'Capacity Map'!$O$335:$O$417,Cross_table!$B9,'Capacity Map'!$T$335:$T$417,Cross_table!F$1) -> 0 | G9: =SUMIFS('Capacity Map'!$J$14:$J$287,'Capacity Map'!$O$14:$O$287,Cross_table!$B9,'Capacity Map'!$T$14:$T$287,Cross_table!G$1)+SUMIFS('Capacity Map'!$J$335:$J$417,'Capacity Map'!$O$335:$O$417,Cross_table!$B9,'Capacity Map'!$T$335:$T$417,Cross_table!G$1) -> 0 | H9: =SUMIFS('Capacity Map'!$J$14:$J$287,'Capacity Map'!$O$14:$O$287,Cross_table!$B9,'Capacity Map'!$T$14:$T$287,Cross_table!H$1)+SUMIFS('Capacity Map'!$J$335:$J$417,'Capacity Map'!$O$335:$O$417,Cross_table!$B9,'Capacity Map'!$T$335:$T$417,Cross_table!H$1) -> 21.5 | I9: =SUMIFS('Capacity Map'!$J$14:$J$287,'Capacity Map'!$O$14:$O$287,Cross_table!$B9,'Capacity Map'!$T$14:$T$287,Cross_table!I$1)+SUMIFS('Capacity Map'!$J$335:$J$417,'Capacity Map'!$O$335:$O$417,Cross_table!$B9,'Capacity Map'!$T$335:$T$417,Cross_table!I$1) -> 0 | J9: =SUMIFS('Capacity Map'!$J$14:$J$287,'Capacity Map'!$O$14:$O$287,Cross_table!$B9,'Capacity Map'!$T$14:$T$287,Cross_table!J$1)+SUMIFS('Capacity Map'!$J$335:$J$417,'Capacity Map'!$O$335:$O$417,Cross_table!$B9,'Capacity Map'!$T$335:$T$417,Cross_table!J$1) -> 0 | ... AP9: =SUMIFS('Capacity Map'!$J$14:$J$287,'Capacity Map'!$O$14:$O$287,Cross_table!$B9,'Capacity Map'!$T$14:$T$287,Cross_table!AP$1)+SUMIFS('Capacity Map'!$J$335:$J$417,'Capacity Map'!$O$335:$O$417,Cross_table!$B9,'Capacity Map'!$T$335:$T$417,Cross_table!AP$1) -> 0
B10: HR | C10: =SUMIFS('Capacity Map'!$J$14:$J$287,'Capacity Map'!$O$14:$O$287,Cross_table!$B10,'Capacity Map'!$T$14:$T$287,Cross_table!C$1)+SUMIFS('Capacity Map'!$J$335:$J$417,'Capacity Map'!$O$335:$O$417,Cross_table!$B10,'Capacity Map'!$T$335:$T$417,Cross_table!C$1) -> 0 | D10: =SUMIFS('Capacity Map'!$J$14:$J$287,'Capacity Map'!$O$14:$O$287,Cross_table!$B10,'Capacity Map'!$T$14:$T$287,Cross_table!D$1)+SUMIFS('Capacity Map'!$J$335:$J$417,'Capacity Map'!$O$335:$O$417,Cross_table!$B10,'Capacity Map'!$T$335:$T$417,Cross_table!D$1) -> 0 | E10: =SUMIFS('Capacity Map'!$J$14:$J$287,'Capacity Map'!$O$14:$O$287,Cross_table!$B10,'Capacity Map'!$T$14:$T$287,Cross_table!E$1)+SUMIFS('Capacity Map'!$J$335:$J$417,'Capacity Map'!$O$335:$O$417,Cross_table!$B10,'Capacity Map'!$T$335:$T$417,Cross_table!E$1) -> 0 | F10: =SUMIFS('Capacity Map'!$J$14:$J$287,'Capacity Map'!$O$14:$O$287,Cross_table!$B10,'Capacity Map'!$T$14:$T$287,Cross_table!F$1)+SUMIFS('Capacity Map'!$J$335:$J$417,'Capacity Map'!$O$335:$O$417,Cross_table!$B10,'Capacity Map'!$T$335:$T$417,Cross_table!F$1) -> 0 | G10: =SUMIFS('Capacity Map'!$J$14:$J$287,'Capacity Map'!$O$14:$O$287,Cross_table!$B10,'Capacity Map'!$T$14:$T$287,Cross_table!G$1)+SUMIFS('Capacity Map'!$J$335:$J$417,'Capacity Map'!$O$335:$O$417,Cross_table!$B10,'Capacity Map'!$T$335:$T$417,Cross_table!G$1) -> 0 | H10: =SUMIFS('Capacity Map'!$J$14:$J$287,'Capacity Map'!$O$14:$O$287,Cross_table!$B10,'Capacity Map'!$T$14:$T$287,Cross_table!H$1)+SUMIFS('Capacity Map'!$J$335:$J$417,'Capacity Map'!$O$335:$O$417,Cross_table!$B10,'Capacity Map'!$T$335:$T$417,Cross_table!H$1) -> 0 | I10: =SUMIFS('Capacity Map'!$J$14:$J$287,'Capacity Map'!$O$14:$O$287,Cross_table!$B10,'Capacity Map'!$T$14:$T$287,Cross_table!I$1)+SUMIFS('Capacity Map'!$J$335:$J$417,'Capacity Map'!$O$335:$O$417,Cross_table!$B10,'Capacity Map'!$T$335:$T$417,Cross_table!I$1) -> 0 | J10: =SUMIFS('Capacity Map'!$J$14:$J$287,'Capacity Map'!$O$14:$O$287,Cross_table!$B10,'Capacity Map'!$T$14:$T$287,Cross_table!J$1)+SUMIFS('Capacity Map'!$J$335:$J$417,'Capacity Map'!$O$335:$O$417,Cross_table!$B10,'Capacity Map'!$T$335:$T$417,Cross_table!J$1) -> 7.7 | ... AP10: =SUMIFS('Capacity Map'!$J$14:$J$287,'Capacity Map'!$O$14:$O$287,Cross_table!$B10,'Capacity Map'!$T$14:$T$287,Cross_table!AP$1)+SUMIFS('Capacity Map'!$J$335:$J$417,'Capacity Map'!$O$335:$O$417,Cross_table!$B10,'Capacity Map'!$T$335:$T$417,Cross_table!AP$1) -> 0
B11: FR | C11: =SUMIFS('Capacity Map'!$J$14:$J$287,'Capacity Map'!$O$14:$O$287,Cross_table!$B11,'Capacity Map'!$T$14:$T$287,Cross_table!C$1)+SUMIFS('Capacity Map'!$J$335:$J$417,'Capacity Map'!$O$335:$O$417,Cross_table!$B11,'Capacity Map'!$T$335:$T$417,Cross_table!C$1) -> 0 | D11: =SUMIFS('Capacity Map'!$J$14:$J$287,'Capacity Map'!$O$14:$O$287,Cross_table!$B11,'Capacity Map'!$T$14:$T$287,Cross_table!D$1)+SUMIFS('Capacity Map'!$J$335:$J$417,'Capacity Map'!$O$335:$O$417,Cross_table!$B11,'Capacity Map'!$T$335:$T$417,Cross_table!D$1) -> 270 | E11: =SUMIFS('Capacity Map'!$J$14:$J$287,'Capacity Map'!$O$14:$O$287,Cross_table!$B11,'Capacity Map'!$T$14:$T$287,Cross_table!E$1)+SUMIFS('Capacity Map'!$J$335:$J$417,'Capacity Map'!$O$335:$O$417,Cross_table!$B11,'Capacity Map'!$T$335:$T$417,Cross_table!E$1) -> 0 | F11: =SUMIFS('Capacity Map'!$J$14:$J$287,'Capacity Map'!$O$14:$O$287,Cross_table!$B11,'Capacity Map'!$T$14:$T$287,Cross_table!F$1)+SUMIFS('Capacity Map'!$J$335:$J$417,'Capacity Map'!$O$335:$O$417,Cross_table!$B11,'Capacity Map'!$T$335:$T$417,Cross_table!F$1) -> 0 | G11: =SUMIFS('Capacity Map'!$J$14:$J$287,'Capacity Map'!$O$14:$O$287,Cross_table!$B11,'Capacity Map'!$T$14:$T$287,Cross_table!G$1)+SUMIFS('Capacity Map'!$J$335:$J$417,'Capacity Map'!$O$335:$O$417,Cross_table!$B11,'Capacity Map'!$T$335:$T$417,Cross_table!G$1) -> 0 | H11: =SUMIFS('Capacity Map'!$J$14:$J$287,'Capacity Map'!$O$14:$O$287,Cross_table!$B11,'Capacity Map'!$T$14:$T$287,Cross_table!H$1)+SUMIFS('Capacity Map'!$J$335:$J$417,'Capacity Map'!$O$335:$O$417,Cross_table!$B11,'Capacity Map'!$T$335:$T$417,Cross_table!H$1) -> 0 | I11: =SUMIFS('Capacity Map'!$J$14:$J$287,'Capacity Map'!$O$14:$O$287,Cross_table!$B11,'Capacity Map'!$T$14:$T$287,Cross_table!I$1)+SUMIFS('Capacity Map'!$J$335:$J$417,'Capacity Map'!$O$335:$O$417,Cross_table!$B11,'Capacity Map'!$T$335:$T$417,Cross_table!I$1) -> 223 | J11: =SUMIFS('Capacity Map'!$J$14:$J$287,'Capacity Map'!$O$14:$O$287,Cross_table!$B11,'Capacity Map'!$T$14:$T$287,Cross_table!J$1)+SUMIFS('Capacity Map'!$J$335:$J$417,'Capacity Map'!$O$335:$O$417,Cross_table!$B11,'Capacity Map'!$T$335:$T$417,Cross_table!J$1) -> 0 | ... AP11: =SUMIFS('Capacity Map'!$J$14:$J$287,'Capacity Map'!$O$14:$O$287,Cross_table!$B11,'Capacity Map'!$T$14:$T$287,Cross_table!AP$1)+SUMIFS('Capacity Map'!$J$335:$J$417,'Capacity Map'!$O$335:$O$417,Cross_table!$B11,'Capacity Map'!$T$335:$T$417,Cross_table!AP$1) -> 0
B12: DK | C12: =SUMIFS('Capacity Map'!$J$14:$J$287,'Capacity Map'!$O$14:$O$287,Cross_table!$B12,'Capacity Map'!$T$14:$T$287,Cross_table!C$1)+SUMIFS('Capacity Map'!$J$335:$J$417,'Capacity Map'!$O$335:$O$417,Cross_table!$B12,'Capacity Map'!$T$335:$T$417,Cross_table!C$1) -> 0 | D12: =SUMIFS('Capacity Map'!$J$14:$J$287,'Capacity Map'!$O$14:$O$287,Cross_table!$B12,'Capacity Map'!$T$14:$T$287,Cross_table!D$1)+SUMIFS('Capacity Map'!$J$335:$J$417,'Capacity Map'!$O$335:$O$417,Cross_table!$B12,'Capacity Map'!$T$335:$T$417,Cross_table!D$1) -> 0 | E12: =SUMIFS('Capacity Map'!$J$14:$J$287,'Capacity Map'!$O$14:$O$287,Cross_table!$B12,'Capacity Map'!$T$14:$T$287,Cross_table!E$1)+SUMIFS('Capacity Map'!$J$335:$J$417,'Capacity Map'!$O$335:$O$417,Cross_table!$B12,'Capacity Map'!$T$335:$T$417,Cross_table!E$1) -> 0 | F12: =SUMIFS('Capacity Map'!$J$14:$J$287,'Capacity Map'!$O$14:$O$287,Cross_table!$B12,'Capacity Map'!$T$14:$T$287,Cross_table!F$1)+SUMIFS('Capacity Map'!$J$335:$J$417,'Capacity Map'!$O$335:$O$417,Cross_table!$B12,'Capacity Map'!$T$335:$T$417,Cross_table!F$1) -> 4.119 | G12: =SUMIFS('Capacity Map'!$J$14:$J$287,'Capacity Map'!$O$14:$O$287,Cross_table!$B12,'Capacity Map'!$T$14:$T$287,Cross_table!G$1)+SUMIFS('Capacity Map'!$J$335:$J$417,'Capacity Map'!$O$335:$O$417,Cross_table!$B12,'Capacity Map'!$T$335:$T$417,Cross_table!G$1) -> 0 | H12: =SUMIFS('Capacity Map'!$J$14:$J$287,'Capacity Map'!$O$14:$O$287,Cross_table!$B12,'Capacity Map'!$T$14:$T$287,Cross_table!H$1)+SUMIFS('Capacity Map'!$J$335:$J$417,'Capacity Map'!$O$335:$O$417,Cross_table!$B12,'Capacity Map'!$T$335:$T$417,Cross_table!H$1) -> 0 | I12: =SUMIFS('Capacity Map'!$J$14:$J$287,'Capacity Map'!$O$14:$O$287,Cross_table!$B12,'Capacity Map'!$T$14:$T$287,Cross_table!I$1)+SUMIFS('Capacity Map'!$J$335:$J$417,'Capacity Map'!$O$335:$O$417,Cross_table!$B12,'Capacity Map'!$T$335:$T$417,Cross_table!I$1) -> 0 | J12: =SUMIFS('Capacity Map'!$J$14:$J$287,'Capacity Map'!$O$14:$O$287,Cross_table!$B12,'Capacity Map'!$T$14:$T$287,Cross_table!J$1)+SUMIFS('Capacity Map'!$J$335:$J$417,'Capacity Map'!$O$335:$O$417,Cross_table!$B12,'Capacity Map'!$T$335:$T$417,Cross_table!J$1) -> 0 | ... AP12: =SUMIFS('Capacity Map'!$J$14:$J$287,'Capacity Map'!$O$14:$O$287,Cross_table!$B12,'Capacity Map'!$T$14:$T$287,Cross_table!AP$1)+SUMIFS('Capacity Map'!$J$335:$J$417,'Capacity Map'!$O$335:$O$417,Cross_table!$B12,'Capacity Map'!$T$335:$T$417,Cross_table!AP$1) -> 0
B13: PL | C13: =SUMIFS('Capacity Map'!$J$14:$J$287,'Capacity Map'!$O$14:$O$287,Cross_table!$B13,'Capacity Map'!$T$14:$T$287,Cross_table!C$1)+SUMIFS('Capacity Map'!$J$335:$J$417,'Capacity Map'!$O$335:$O$417,Cross_table!$B13,'Capacity Map'!$T$335:$T$417,Cross_table!C$1) -> 0 | D13: =SUMIFS('Capacity Map'!$J$14:$J$287,'Capacity Map'!$O$14:$O$287,Cross_table!$B13,'Capacity Map'!$T$14:$T$287,Cross_table!D$1)+SUMIFS('Capacity Map'!$J$335:$J$417,'Capacity Map'!$O$335:$O$417,Cross_table!$B13,'Capacity Map'!$T$335:$T$417,Cross_table!D$1) -> 0 | E13: =SUMIFS('Capacity Map'!$J$14:$J$287,'Capacity Map'!$O$14:$O$287,Cross_table!$B13,'Capacity Map'!$T$14:$T$287,Cross_table!E$1)+SUMIFS('Capacity Map'!$J$335:$J$417,'Capacity Map'!$O$335:$O$417,Cross_table!$B13,'Capacity Map'!$T$335:$T$417,Cross_table!E$1) -> 0 | F13: =SUMIFS('Capacity Map'!$J$14:$J$287,'Capacity Map'!$O$14:$O$287,Cross_table!$B13,'Capacity Map'!$T$14:$T$287,Cross_table!F$1)+SUMIFS('Capacity Map'!$J$335:$J$417,'Capacity Map'!$O$335:$O$417,Cross_table!$B13,'Capacity Map'!$T$335:$T$417,Cross_table!F$1) -> 931.6 | G13: =SUMIFS('Capacity Map'!$J$14:$J$287,'Capacity Map'!$O$14:$O$287,Cross_table!$B13,'Capacity Map'!$T$14:$T$287,Cross_table!G$1)+SUMIFS('Capacity Map'!$J$335:$J$417,'Capacity Map'!$O$335:$O$417,Cross_table!$B13,'Capacity Map'!$T$335:$T$417,Cross_table!G$1) -> 0 | H13: =SUMIFS('Capacity Map'!$J$14:$J$287,'Capacity Map'!$O$14:$O$287,Cross_table!$B13,'Capacity Map'!$T$14:$T$287,Cross_table!H$1)+SUMIFS('Capacity Map'!$J$335:$J$417,'Capacity Map'!$O$335:$O$417,Cross_table!$B13,'Capacity Map'!$T$335:$T$417,Cross_table!H$1) -> 0 | I13: =SUMIFS('Capacity Map'!$J$14:$J$287,'Capacity Map'!$O$14:$O$287,Cross_table!$B13,'Capacity Map'!$T$14:$T$287,Cross_table!I$1)+SUMIFS('Capacity Map'!$J$335:$J$417,'Capacity Map'!$O$335:$O$417,Cross_table!$B13,'Capacity Map'!$T$335:$T$417,Cross_table!I$1) -> 0 | J13: =SUMIFS('Capacity Map'!$J$14:$J$287,'Capacity Map'!$O$14:$O$287,Cross_table!$B13,'Capacity Map'!$T$14:$T$287,Cross_table!J$1)+SUMIFS('Capacity Map'!$J$335:$J$417,'Capacity Map'!$O$335:$O$417,Cross_table!$B13,'Capacity Map'!$T$335:$T$417,Cross_table!J$1) -> 0 | ... AP13: =SUMIFS('Capacity Map'!$J$14:$J$287,'Capacity Map'!$O$14:$O$287,Cross_table!$B13,'Capacity Map'!$T$14:$T$287,Cross_table!AP$1)+SUMIFS('Capacity Map'!$J$335:$J$417,'Capacity Map'!$O$335:$O$417,Cross_table!$B13,'Capacity Map'!$T$335:$T$417,Cross_table!AP$1) -> 0
... B41: FI | C41: =SUMIFS('Capacity Map'!$J$14:$J$287,'Capacity Map'!$O$14:$O$287,Cross_table!$B41,'Capacity Map'!$T$14:$T$287,Cross_table!C$1)+SUMIFS('Capacity Map'!$J$335:$J$417,'Capacity Map'!$O$335:$O$417,Cross_table!$B41,'Capacity Map'!$T$335:$T$417,Cross_table!C$1) -> 0 | D41: =SUMIFS('Capacity Map'!$J$14:$J$287,'Capacity Map'!$O$14:$O$287,Cross_table!$B41,'Capacity Map'!$T$14:$T$287,Cross_table!D$1)+SUMIFS('Capacity Map'!$J$335:$J$417,'Capacity Map'!$O$335:$O$417,Cross_table!$B41,'Capacity Map'!$T$335:$T$417,Cross_table!D$1) -> 0 | E41: =SUMIFS('Capacity Map'!$J$14:$J$287,'Capacity Map'!$O$14:$O$287,Cross_table!$B41,'Capacity Map'!$T$14:$T$287,Cross_table!E$1)+SUMIFS('Capacity Map'!$J$335:$J$417,'Capacity Map'!$O$335:$O$417,Cross_table!$B41,'Capacity Map'!$T$335:$T$417,Cross_table!E$1) -> 0 | F41: =SUMIFS('Capacity Map'!$J$14:$J$287,'Capacity Map'!$O$14:$O$287,Cross_table!$B41,'Capacity Map'!$T$14:$T$287,Cross_table!F$1)+SUMIFS('Capacity Map'!$J$335:$J$417,'Capacity Map'!$O$335:$O$417,Cross_table!$B41,'Capacity Map'!$T$335:$T$417,Cross_table!F$1) -> 0 | G41: =SUMIFS('Capacity Map'!$J$14:$J$287,'Capacity Map'!$O$14:$O$287,Cross_table!$B41,'Capacity Map'!$T$14:$T$287,Cross_table!G$1)+SUMIFS('Capacity Map'!$J$335:$J$417,'Capacity Map'!$O$335:$O$417,Cross_table!$B41,'Capacity Map'!$T$335:$T$417,Cross_table!G$1) -> 0 | H41: =SUMIFS('Capacity Map'!$J$14:$J$287,'Capacity Map'!$O$14:$O$287,Cross_table!$B41,'Capacity Map'!$T$14:$T$287,Cross_table!H$1)+SUMIFS('Capacity Map'!$J$335:$J$417,'Capacity Map'!$O$335:$O$417,Cross_table!$B41,'Capacity Map'!$T$335:$T$417,Cross_table!H$1) -> 0 | I41: =SUMIFS('Capacity Map'!$J$14:$J$287,'Capacity Map'!$O$14:$O$287,Cross_table!$B41,'Capacity Map'!$T$14:$T$287,Cross_table!I$1)+SUMIFS('Capacity Map'!$J$335:$J$417,'Capacity Map'!$O$335:$O$417,Cross_table!$B41,'Capacity Map'!$T$335:$T$417,Cross_table!I$1) -> 0 | J41: =SUMIFS('Capacity Map'!$J$14:$J$287,'Capacity Map'!$O$14:$O$287,Cross_table!$B41,'Capacity Map'!$T$14:$T$287,Cross_table!J$1)+SUMIFS('Capacity Map'!$J$335:$J$417,'Capacity Map'!$O$335:$O$417,Cross_table!$B41,'Capacity Map'!$T$335:$T$417,Cross_table!J$1) -> 0 | ... AP41: =SUMIFS('Capacity Map'!$J$14:$J$287,'Capacity Map'!$O$14:$O$287,Cross_table!$B41,'Capacity Map'!$T$14:$T$287,Cross_table!AP$1)+SUMIFS('Capacity Map'!$J$335:$J$417,'Capacity Map'!$O$335:$O$417,Cross_table!$B41,'Capacity Map'!$T$335:$T$417,Cross_table!AP$1) -> 0

Sheet Connections_cross_table
A1: From | B1: To | C1: Value
A2: UK | B2: UK | C2: 1455.1
A3: UK | B3: BE | C3: 651.7
A4: UK | B4: NL | C4: 0
A5: UK | B5: DE | C5: 0
A6: UK | B6: AT | C6: 0
A7: UK | B7: IT | C7: 0
A8: UK | B8: CH | C8: 0
A9: UK | B9: SI | C9: 0
A10: UK | B10: HR | C10: 0
A11: UK | B11: FR | C11: 0
A12: UK | B12: DK | C12: 0
A13: UK | B13: PL | C13: 0
... A1601: FI | B1601: FI | C1601: 0
