Workbook
Name ch: #REF!
Name Codes: #REF!
Name date: '[1]PTC creator'!$B$13
Name date2: #REF!
Name MS_cell: #REF!
Name One_in_hundred: #REF!
Name One_in_twenty: #REF!
Name percentile_all_MS: '[1]rearranged data step2_3'!$A$7:$A$1490
Name probability_list: '[1]probability list'!$A$3:$A$30
Name probability_threshold: '[1]PTC creator'!$B$16
Name t_at: '[1]rearranged data step1'!$F$3:$F$13729
Name t_be: '[1]rearranged data step1'!$F$13730:$F$27456
Name t_bg: '[1]rearranged data step1'!$F$27457:$F$41183
Name t_cy: '[1]rearranged data step1'!$F$41184:$F$54910
Name t_cz: '[1]rearranged data step1'!#REF!
Name t_de: '[1]rearranged data step1'!#REF!
Name t_dk: '[1]rearranged data step1'!#REF!
Name t_ee: '[1]rearranged data step1'!#REF!
Name t_es: '[1]rearranged data step1'!#REF!
Name t_eu27: '[1]rearranged data step1'!#REF!
Name t_fi: '[1]rearranged data step1'!#REF!
Name t_fr: '[1]rearranged data step1'!#REF!
Name t_gr: '[1]rearranged data step1'!#REF!
Name t_hu: '[1]rearranged data step1'!#REF!
Name t_ie: '[1]rearranged data step1'!#REF!
Name t_it: '[1]rearranged data step1'!#REF!
Name t_lt: '[1]rearranged data step1'!#REF!
Name t_lu: '[1]rearranged data step1'!#REF!
Name t_lv: '[1]rearranged data step1'!#REF!
Name t_mt: '[1]rearranged data step1'!#REF!
Name t_nl: '[1]rearranged data step1'!#REF!
Name t_pl: '[1]rearranged data step1'!#REF!
Name t_pt: '[1]rearranged data step1'!#REF!
Name t_ro: '[1]rearranged data step1'!#REF!
Name t_se: '[1]rearranged data step1'!#REF!
Name t_si: '[1]rearranged data step1'!#REF!
Name t_sk: '[1]rearranged data step1'!#REF!
Name t_uk: '[1]rearranged data step1'!#REF!
Name temperature_input: #REF!
Name week_number_cell: #REF!

Sheet Capacities
F2: System Capacity Map 2024
G5: Legend
G8: Virtual points are indicated with a "V" mention. By default the map displays interconnections only when firm technical capacity is existing.
B12: Number | D12: Point | H12: Technical physical capacity (GWh/d) | I12: From Operator | J12: From CC | K12: From BZ | L12: To Operator | M12: To CC | N12: To BZ
B15: Cross-border IP within EU and with non-EU (export)
B16: 1 | D16: Zeebrugge IZT | H16: 651.7 | I16: Interconnector | J16: UK | K16: IUK | L16: Fluxys Belgium | M16: BE | N16: BeLux
H17: 803.4 | I17: Fluxys Belgium | J17: BE | K17: BeLux | L17: Interconnector | M17: UK | N17: IUK
B19: 2 | C19: V | D19: VIRTUALYS Virtualys is virtualising 'Alveringem' and 'Taisnieres H/Blaregnies Segeo/Troll' since 1 Dec 2017 | H19: 360 | I19: Fluxys Belgium | J19: BE | K19: BeLux | L19: GRTgaz | M19: FR | N19: TRF
H20: 270 | I20: GRTgaz | J20: FR | K20: TRF | L20: Fluxys Belgium | M20: BE | N20: BeLux
B22: 3 | D22: Blaregnies L (BE) / Taisnières B (FR) | H22: 170 | I22: Fluxys Belgium | J22: BE | K22: L-Zone | L22: GRTgaz | M22: FR | N22: TRF
B24: 4 | C24: V | D24: VIP BENE L | H24: 595.56346 | I24: GTS | J24: NL | K24: Netherlands | L24: Fluxys Belgium | M24: BE | N24: BeLux
B26: 5 | C26: V | D26: VIP BENE | H26: 428 | I26: Fluxys Belgium | J26: BE | K26: BeLux | L26: GTS | M26: NL | N26: Netherlands
H27: 792 | I27: GTS | J27: NL | K27: Netherlands | L27: Fluxys Belgium | M27: BE | N27: BeLux
B29: 6 | C29: V | D29: VIP THE-ZTP | H29: 356 | I29: Open Grid Europe | J29: DE | K29: DE THE BZ | L29: Fluxys Belgium | M29: BE | N29: BeLux
I30: Thyssengas | J30: DE | K30: DE THE BZ | L30: Fluxys Belgium | M30: BE | N30: BeLux
I31: Fluxys TENP | J31: DE | K31: DE THE BZ | L31: Fluxys Belgium | M31: BE | N31: BeLux
I32: GASCADE Gastransport | J32: DE | K32: DE THE BZ | L32: Fluxys Belgium | M32: BE | N32: BeLux
H33: 542 | I33: Fluxys Belgium | J33: BE | K33: BeLux | L33: Open Grid Europe | M33: DE | N33: DE THE BZ
I34: Fluxys Belgium | J34: BE | K34: BeLux | L34: Thyssengas | M34: DE | N34: DE THE BZ
I35: Fluxys Belgium | J35: BE | K35: BeLux | L35: Fluxys TENP | M35: DE | N35: DE THE BZ
I36: Fluxys Belgium | J36: BE | K36: BeLux | L36: GASCADE Gastransport | M36: DE | N36: DE THE BZ
B38: 8 | D38: Remich | H38: 24 | I38: Open Grid Europe | J38: DE | K38: DE THE BZ | L38: Creos Luxembourg | M38: LU | N38: BeLux
B40: 9 | C40: V | D40: VIP THE - PEG | H40: 613.74174 | I40: GRTgaz Deutschland | J40: DE | K40: DE THE BZ | L40: GRTgaz | M40: FR | N40: TRF
H41: 100 | I41: GRTgaz | J41: FR | K41: TRF | L41: GRTgaz Deutschland | M41: DE | N41: DE THE BZ
B43: 10 | D43: Oltingue (FR) / Rodersdorf (CH) | H43: 100 | I43: FluxSwiss | J43: CH | K43: Switzerland | L43: GRTgaz | M43: FR | N43: TRF
I44: Swissgas | J44: CH | K44: Switzerland | L44: GRTgaz | M44: FR | N44: TRF
H45: 259.02 | I45: GRTgaz | J45: FR | K45: TRF | L45: FluxSwiss | M45: CH | N45: Switzerland
I46: GRTgaz | J46: FR | K46: TRF | L46: Swissgas | M46: CH | N46: Switzerland
B48: 11 | D48: RC Basel | H48: 8.83 | I48: terranets bw | J48: DE | K48: DE THE BZ | L48: GVM | M48: CH | N48: Switzerland
B50: 12 | D50: VIP THE - CH | H50: 240 | I50: FluxSwiss | J50: CH | K50: Switzerland | L50: Fluxys TENP | M50: DE | N50: DE THE BZ
I51: FluxSwiss | J51: CH | K51: Switzerland | L51: Open Grid Europe | M51: DE | N51: DE THE BZ
I52: Swissgas | J52: CH | K52: Switzerland | L52: Open Grid Europe | M52: DE | N52: DE THE BZ
H53: 345 | I53: Fluxys TENP | J53: DE | K53: DE THE BZ | L53: FluxSwiss | M53: CH | N53: Switzerland
I54: Fluxys TENP | J54: DE | K54: DE THE BZ | L54: Swissgas | M54: CH | N54: Switzerland
I55: Open Grid Europe | J55: DE | K55: DE THE BZ | L55: FluxSwiss | M55: CH | N55: Switzerland
I56: Open Grid Europe | J56: DE | K56: DE THE BZ | L56: Swissgas | M56: CH | N56: Switzerland
B58: 13 | C58: V | D58: VIP TTF-THE H | H58: 422 | I58: GTS | J58: NL | K58: Netherlands | L58: Gasunie Deutschland | M58: DE | N58: GASPOOL
I59: GTS | J59: NL | K59: Netherlands | L59: Thyssengas | M59: DE | N59: DE THE BZ
I60: GTS | J60: NL | K60: Netherlands | L60: GASCADE Gastransport | M60: DE | N60: DE THE BZ
I61: GTS | J61: NL | K61: Netherlands | L61: Open Grid Europe | M61: DE | N61: DE THE BZ
...

Sheet Cross_table
B1: Column1 | C1: UK | D1: BE | E1: NL | F1: DE | G1: AT | H1: IT | I1: CH | J1: SI | K1: HR | L1: FR | M1: DK | N1: PL | O1: CZ | P1: SK | Q1: HU | R1: RS | S1: BG | T1: GR | U1: RO | V1: LT | W1: LV | X1: ES | Y1: PT | Z1: UA | AA1: MD | AB1: RU | AC1: AL | AD1: LU | AE1: IE | AF1: BA | AG1: MK | AH1: TR | AI1: SM | AJ1: NO | AK1: DZ | AL1: TN | AM1: LY | AN1: BY | AO1: EE | AP1: FI
B2: UK | C2: =SUMIFS(Capacities!$H$14:$H$287,Capacities!$J$14:$J$287,Cross_table!$B2,Capacities!$M$14:$M$287,Cross_table!C$1)+SUMIFS(Capacities!$H$335:$H$417,Capacities!$J$335:$J$417,Cross_table!$B2,Capacities!$M$335:$M$417,Cross_table!C$1) -> 1455 | D2: =SUMIFS(Capacities!$H$14:$H$303,Capacities!$J$14:$J$303,Cross_table!$B2,Capacities!$M$14:$M$303,Cross_table!D$1)+SUMIFS(Capacities!$H$335:$H$417,Capacities!$J$335:$J$417,Cross_table!$B2,Capacities!$M$335:$M$417,Cross_table!D$1) -> 651.7 | E2: =SUMIFS(Capacities!$H$14:$H$303,Capacities!$J$14:$J$303,Cross_table!$B2,Capacities!$M$14:$M$303,Cross_table!E$1)+SUMIFS(Capacities!$H$335:$H$417,Capacities!$J$335:$J$417,Cross_table!$B2,Capacities!$M$335:$M$417,Cross_table!E$1) -> 168 | F2: =SUMIFS(Capacities!$H$14:$H$303,Capacities!$J$14:$J$303,Cross_table!$B2,Capacities!$M$14:$M$303,Cross_table!F$1)+SUMIFS(Capacities!$H$335:$H$417,Capacities!$J$335:$J$417,Cross_table!$B2,Capacities!$M$335:$M$417,Cross_table!F$1) -> 0 | G2: =SUMIFS(Capacities!$H$14:$H$303,Capacities!$J$14:$J$303,Cross_table!$B2,Capacities!$M$14:$M$303,Cross_table!G$1)+SUMIFS(Capacities!$H$335:$H$417,Capacities!$J$335:$J$417,Cross_table!$B2,Capacities!$M$335:$M$417,Cross_table!G$1) -> 0 | H2: =SUMIFS(Capacities!$H$14:$H$303,Capacities!$J$14:$J$303,Cross_table!$B2,Capacities!$M$14:$M$303,Cross_table!H$1)+SUMIFS(Capacities!$H$335:$H$417,Capacities!$J$335:$J$417,Cross_table!$B2,Capacities!$M$335:$M$417,Cross_table!H$1) -> 0 | I2: =SUMIFS(Capacities!$H$14:$H$303,Capacities!$J$14:$J$303,Cross_table!$B2,Capacities!$M$14:$M$303,Cross_table!I$1)+SUMIFS(Capacities!$H$335:$H$417,Capacities!$J$335:$J$417,Cross_table!$B2,Capacities!$M$335:$M$417,Cross_table!I$1) -> 0 | J2: =SUMIFS(Capacities!$H$14:$H$303,Capacities!$J$14:$J$303,Cross_table!$B2,Capacities!$M$14:$M$303,Cross_table!J$1)+SUMIFS(Capacities!$H$335:$H$417,Capacities!$J$335:$J$417,Cross_table!$B2,Capacities!$M$335:$M$417,Cross_table!J$1) -> 0 | K2: =SUMIFS(Capacities!$H$14:$H$303,Capacities!$J$14:$J$303,Cross_table!$B2,Capacities!$M$14:$M$303,Cross_table!K$1)+SUMIFS(Capacities!$H$335:$H$417,Capacities!$J$335:$J$417,Cross_table!$B2,Capacities!$M$335:$M$417,Cross_table!K$1) -> 0 | ... AP2: =SUMIFS(Capacities!$H$14:$H$303,Capacities!$J$14:$J$303,Cross_table!$B2,Capacities!$M$14:$M$303,Cross_table!AP$1)+SUMIFS(Capacities!$H$335:$H$417,Capacities!$J$335:$J$417,Cross_table!$B2,Capacities!$M$335:$M$417,Cross_table!AP$1) -> 0
B3: BE | C3: =SUMIFS(Capacities!$H$14:$H$287,Capacities!$J$14:$J$287,Cross_table!$B3,Capacities!$M$14:$M$287,Cross_table!C$1)+SUMIFS(Capacities!$H$335:$H$417,Capacities!$J$335:$J$417,Cross_table!$B3,Capacities!$M$335:$M$417,Cross_table!C$1) -> 803.4 | D3: =SUMIFS(Capacities!$H$14:$H$303,Capacities!$J$14:$J$303,Cross_table!$B3,Capacities!$M$14:$M$303,Cross_table!D$1)+SUMIFS(Capacities!$H$335:$H$417,Capacities!$J$335:$J$417,Cross_table!$B3,Capacities!$M$335:$M$417,Cross_table!D$1) -> 0 | E3: =SUMIFS(Capacities!$H$14:$H$303,Capacities!$J$14:$J$303,Cross_table!$B3,Capacities!$M$14:$M$303,Cross_table!E$1)+SUMIFS(Capacities!$H$335:$H$417,Capacities!$J$335:$J$417,Cross_table!$B3,Capacities!$M$335:$M$417,Cross_table!E$1) -> 428 | F3: =SUMIFS(Capacities!$H$14:$H$303,Capacities!$J$14:$J$303,Cross_table!$B3,Capacities!$M$14:$M$303,Cross_table!F$1)+SUMIFS(Capacities!$H$335:$H$417,Capacities!$J$335:$J$417,Cross_table!$B3,Capacities!$M$335:$M$417,Cross_table!F$1) -> 542 | G3: =SUMIFS(Capacities!$H$14:$H$303,Capacities!$J$14:$J$303,Cross_table!$B3,Capacities!$M$14:$M$303,Cross_table!G$1)+SUMIFS(Capacities!$H$335:$H$417,Capacities!$J$335:$J$417,Cross_table!$B3,Capacities!$M$335:$M$417,Cross_table!G$1) -> 0 | H3: =SUMIFS(Capacities!$H$14:$H$303,Capacities!$J$14:$J$303,Cross_table!$B3,Capacities!$M$14:$M$303,Cross_table!H$1)+SUMIFS(Capacities!$H$335:$H$417,Capacities!$J$335:$J$417,Cross_table!$B3,Capacities!$M$335:$M$417,Cross_table!H$1) -> 0 | I3: =SUMIFS(Capacities!$H$14:$H$303,Capacities!$J$14:$J$303,Cross_table!$B3,Capacities!$M$14:$M$303,Cross_table!I$1)+SUMIFS(Capacities!$H$335:$H$417,Capacities!$J$335:$J$417,Cross_table!$B3,Capacities!$M$335:$M$417,Cross_table!I$1) -> 0 | J3: =SUMIFS(Capacities!$H$14:$H$303,Capacities!$J$14:$J$303,Cross_table!$B3,Capacities!$M$14:$M$303,Cross_table!J$1)+SUMIFS(Capacities!$H$335:$H$417,Capacities!$J$335:$J$417,Cross_table!$B3,Capacities!$M$335:$M$417,Cross_table!J$1) -> 0 | K3: =SUMIFS(Capacities!$H$14:$H$303,Capacities!$J$14:$J$303,Cross_table!$B3,Capacities!$M$14:$M$303,Cross_table!K$1)+SUMIFS(Capacities!$H$335:$H$417,Capacities!$J$335:$J$417,Cross_table!$B3,Capacities!$M$335:$M$417,Cross_table!K$1) -> 0 | ... AP3: =SUMIFS(Capacities!$H$14:$H$303,Capacities!$J$14:$J$303,Cross_table!$B3,Capacities!$M$14:$M$303,Cross_table!AP$1)+SUMIFS(Capacities!$H$335:$H$417,Capacities!$J$335:$J$417,Cross_table!$B3,Capacities!$M$335:$M$417,Cross_table!AP$1) -> 0
B4: NL | C4: =SUMIFS(Capacities!$H$14:$H$287,Capacities!$J$14:$J$287,Cross_table!$B4,Capacities!$M$14:$M$287,Cross_table!C$1)+SUMIFS(Capacities!$H$335:$H$417,Capacities!$J$335:$J$417,Cross_table!$B4,Capacities!$M$335:$M$417,Cross_table!C$1) -> 494.4 | D4: =SUMIFS(Capacities!$H$14:$H$303,Capacities!$J$14:$J$303,Cross_table!$B4,Capacities!$M$14:$M$303,Cross_table!D$1)+SUMIFS(Capacities!$H$335:$H$417,Capacities!$J$335:$J$417,Cross_table!$B4,Capacities!$M$335:$M$417,Cross_table!D$1) -> 1387.5635 | E4: =SUMIFS(Capacities!$H$14:$H$303,Capacities!$J$14:$J$303,Cross_table!$B4,Capacities!$M$14:$M$303,Cross_table!E$1)+SUMIFS(Capacities!$H$335:$H$417,Capacities!$J$335:$J$417,Cross_table!$B4,Capacities!$M$335:$M$417,Cross_table!E$1) -> 0 | F4: =SUMIFS(Capacities!$H$14:$H$303,Capacities!$J$14:$J$303,Cross_table!$B4,Capacities!$M$14:$M$303,Cross_table!F$1)+SUMIFS(Capacities!$H$335:$H$417,Capacities!$J$335:$J$417,Cross_table!$B4,Capacities!$M$335:$M$417,Cross_table!F$1) -> 1849.15 | G4: =SUMIFS(Capacities!$H$14:$H$303,Capacities!$J$14:$J$303,Cross_table!$B4,Capacities!$M$14:$M$303,Cross_table!G$1)+SUMIFS(Capacities!$H$335:$H$417,Capacities!$J$335:$J$417,Cross_table!$B4,Capacities!$M$335:$M$417,Cross_table!G$1) -> 0 | H4: =SUMIFS(Capacities!$H$14:$H$303,Capacities!$J$14:$J$303,Cross_table!$B4,Capacities!$M$14:$M$303,Cross_table!H$1)+SUMIFS(Capacities!$H$335:$H$417,Capacities!$J$335:$J$417,Cross_table!$B4,Capacities!$M$335:$M$417,Cross_table!H$1) -> 0 | I4: =SUMIFS(Capacities!$H$14:$H$303,Capacities!$J$14:$J$303,Cross_table!$B4,Capacities!$M$14:$M$303,Cross_table!I$1)+SUMIFS(Capacities!$H$335:$H$417,Capacities!$J$335:$J$417,Cross_table!$B4,Capacities!$M$335:$M$417,Cross_table!I$1) -> 0 | J4: =SUMIFS(Capacities!$H$14:$H$303,Capacities!$J$14:$J$303,Cross_table!$B4,Capacities!$M$14:$M$303,Cross_table!J$1)+SUMIFS(Capacities!$H$335:$H$417,Capacities!$J$335:$J$417,Cross_table!$B4,Capacities!$M$335:$M$417,Cross_table!J$1) -> 0 | K4: =SUMIFS(Capacities!$H$14:$H$303,Capacities!$J$14:$J$303,Cross_table!$B4,Capacities!$M$14:$M$303,Cross_table!K$1)+SUMIFS(Capacities!$H$335:$H$417,Capacities!$J$335:$J$417,Cross_table!$B4,Capacities!$M$335:$M$417,Cross_table!K$1) -> 0 | ... AP4: =SUMIFS(Capacities!$H$14:$H$303,Capacities!$J$14:$J$303,Cross_table!$B4,Capacities!$M$14:$M$303,Cross_table!AP$1)+SUMIFS(Capacities!$H$335:$H$417,Capacities!$J$335:$J$417,Cross_table!$B4,Capacities!$M$335:$M$417,Cross_table!AP$1) -> 0
B5: DE | C5: =SUMIFS(Capacities!$H$14:$H$287,Capacities!$J$14:$J$287,Cross_table!$B5,Capacities!$M$14:$M$287,Cross_table!C$1)+SUMIFS(Capacities!$H$335:$H$417,Capacities!$J$335:$J$417,Cross_table!$B5,Capacities!$M$335:$M$417,Cross_table!C$1) -> 0 | D5: =SUMIFS(Capacities!$H$14:$H$303,Capacities!$J$14:$J$303,Cross_table!$B5,Capacities!$M$14:$M$303,Cross_table!D$1)+SUMIFS(Capacities!$H$335:$H$417,Capacities!$J$335:$J$417,Cross_table!$B5,Capacities!$M$335:$M$417,Cross_table!D$1) -> 356 | E5: =SUMIFS(Capacities!$H$14:$H$303,Capacities!$J$14:$J$303,Cross_table!$B5,Capacities!$M$14:$M$303,Cross_table!E$1)+SUMIFS(Capacities!$H$335:$H$417,Capacities!$J$335:$J$417,Cross_table!$B5,Capacities!$M$335:$M$417,Cross_table!E$1) -> 1513.9 | F5: =SUMIFS(Capacities!$H$14:$H$303,Capacities!$J$14:$J$303,Cross_table!$B5,Capacities!$M$14:$M$303,Cross_table!F$1)+SUMIFS(Capacities!$H$335:$H$417,Capacities!$J$335:$J$417,Cross_table!$B5,Capacities!$M$335:$M$417,Cross_table!F$1) -> 0 | G5: =SUMIFS(Capacities!$H$14:$H$303,Capacities!$J$14:$J$303,Cross_table!$B5,Capacities!$M$14:$M$303,Cross_table!G$1)+SUMIFS(Capacities!$H$335:$H$417,Capacities!$J$335:$J$417,Cross_table!$B5,Capacities!$M$335:$M$417,Cross_table!G$1) -> 710.94037 | H5: =SUMIFS(Capacities!$H$14:$H$303,Capacities!$J$14:$J$303,Cross_table!$B5,Capacities!$M$14:$M$303,Cross_table!H$1)+SUMIFS(Capacities!$H$335:$H$417,Capacities!$J$335:$J$417,Cross_table!$B5,Capacities!$M$335:$M$417,Cross_table!H$1) -> 0 | I5: =SUMIFS(Capacities!$H$14:$H$303,Capacities!$J$14:$J$303,Cross_table!$B5,Capacities!$M$14:$M$303,Cross_table!I$1)+SUMIFS(Capacities!$H$335:$H$417,Capacities!$J$335:$J$417,Cross_table!$B5,Capacities!$M$335:$M$417,Cross_table!I$1) -> 353.83 | J5: =SUMIFS(Capacities!$H$14:$H$303,Capacities!$J$14:$J$303,Cross_table!$B5,Capacities!$M$14:$M$303,Cross_table!J$1)+SUMIFS(Capacities!$H$335:$H$417,Capacities!$J$335:$J$417,Cross_table!$B5,Capacities!$M$335:$M$417,Cross_table!J$1) -> 0 | K5: =SUMIFS(Capacities!$H$14:$H$303,Capacities!$J$14:$J$303,Cross_table!$B5,Capacities!$M$14:$M$303,Cross_table!K$1)+SUMIFS(Capacities!$H$335:$H$417,Capacities!$J$335:$J$417,Cross_table!$B5,Capacities!$M$335:$M$417,Cross_table!K$1) -> 0 | ... AP5: =SUMIFS(Capacities!$H$14:$H$303,Capacities!$J$14:$J$303,Cross_table!$B5,Capacities!$M$14:$M$303,Cross_table!AP$1)+SUMIFS(Capacities!$H$335:$H$417,Capacities!$J$335:$J$417,Cross_table!$B5,Capacities!$M$335:$M$417,Cross_table!AP$1) -> 0
B6: AT | C6: =SUMIFS(Capacities!$H$14:$H$287,Capacities!$J$14:$J$287,Cross_table!$B6,Capacities!$M$14:$M$287,Cross_table!C$1)+SUMIFS(Capacities!$H$335:$H$417,Capacities!$J$335:$J$417,Cross_table!$B6,Capacities!$M$335:$M$417,Cross_table!C$1) -> 0 | D6: =SUMIFS(Capacities!$H$14:$H$303,Capacities!$J$14:$J$303,Cross_table!$B6,Capacities!$M$14:$M$303,Cross_table!D$1)+SUMIFS(Capacities!$H$335:$H$417,Capacities!$J$335:$J$417,Cross_table!$B6,Capacities!$M$335:$M$417,Cross_table!D$1) -> 0 | E6: =SUMIFS(Capacities!$H$14:$H$303,Capacities!$J$14:$J$303,Cross_table!$B6,Capacities!$M$14:$M$303,Cross_table!E$1)+SUMIFS(Capacities!$H$335:$H$417,Capacities!$J$335:$J$417,Cross_table!$B6,Capacities!$M$335:$M$417,Cross_table!E$1) -> 0 | F6: =SUMIFS(Capacities!$H$14:$H$303,Capacities!$J$14:$J$303,Cross_table!$B6,Capacities!$M$14:$M$303,Cross_table!F$1)+SUMIFS(Capacities!$H$335:$H$417,Capacities!$J$335:$J$417,Cross_table!$B6,Capacities!$M$335:$M$417,Cross_table!F$1) -> 797.936 | G6: =SUMIFS(Capacities!$H$14:$H$303,Capacities!$J$14:$J$303,Cross_table!$B6,Capacities!$M$14:$M$303,Cross_table!G$1)+SUMIFS(Capacities!$H$335:$H$417,Capacities!$J$335:$J$417,Cross_table!$B6,Capacities!$M$335:$M$417,Cross_table!G$1) -> 0 | H6: =SUMIFS(Capacities!$H$14:$H$303,Capacities!$J$14:$J$303,Cross_table!$B6,Capacities!$M$14:$M$303,Cross_table!H$1)+SUMIFS(Capacities!$H$335:$H$417,Capacities!$J$335:$J$417,Cross_table!$B6,Capacities!$M$335:$M$417,Cross_table!H$1) -> 1176.11 | I6: =SUMIFS(Capacities!$H$14:$H$303,Capacities!$J$14:$J$303,Cross_table!$B6,Capacities!$M$14:$M$303,Cross_table!I$1)+SUMIFS(Capacities!$H$335:$H$417,Capacities!$J$335:$J$417,Cross_table!$B6,Capacities!$M$335:$M$417,Cross_table!I$1) -> 0 | J6: =SUMIFS(Capacities!$H$14:$H$303,Capacities!$J$14:$J$303,Cross_table!$B6,Capacities!$M$14:$M$303,Cross_table!J$1)+SUMIFS(Capacities!$H$335:$H$417,Capacities!$J$335:$J$417,Cross_table!$B6,Capacities!$M$335:$M$417,Cross_table!J$1) -> 112.5 | K6: =SUMIFS(Capacities!$H$14:$H$303,Capacities!$J$14:$J$303,Cross_table!$B6,Capacities!$M$14:$M$303,Cross_table!K$1)+SUMIFS(Capacities!$H$335:$H$417,Capacities!$J$335:$J$417,Cross_table!$B6,Capacities!$M$335:$M$417,Cross_table!K$1) -> 0 | ... AP6: =SUMIFS(Capacities!$H$14:$H$303,Capacities!$J$14:$J$303,Cross_table!$B6,Capacities!$M$14:$M$303,Cross_table!AP$1)+SUMIFS(Capacities!$H$335:$H$417,Capacities!$J$335:$J$417,Cross_table!$B6,Capacities!$M$335:$M$417,Cross_table!AP$1) -> 0
B7: IT | C7: =SUMIFS(Capacities!$H$14:$H$287,Capacities!$J$14:$J$287,Cross_table!$B7,Capacities!$M$14:$M$287,Cross_table!C$1)+SUMIFS(Capacities!$H$335:$H$417,Capacities!$J$335:$J$417,Cross_table!$B7,Capacities!$M$335:$M$417,Cross_table!C$1) -> 0 | D7: =SUMIFS(Capacities!$H$14:$H$303,Capacities!$J$14:$J$303,Cross_table!$B7,Capacities!$M$14:$M$303,Cross_table!D$1)+SUMIFS(Capacities!$H$335:$H$417,Capacities!$J$335:$J$417,Cross_table!$B7,Capacities!$M$335:$M$417,Cross_table!D$1) -> 0 | E7: =SUMIFS(Capacities!$H$14:$H$303,Capacities!$J$14:$J$303,Cross_table!$B7,Capacities!$M$14:$M$303,Cross_table!E$1)+SUMIFS(Capacities!$H$335:$H$417,Capacities!$J$335:$J$417,Cross_table!$B7,Capacities!$M$335:$M$417,Cross_table!E$1) -> 0 | F7: =SUMIFS(Capacities!$H$14:$H$303,Capacities!$J$14:$J$303,Cross_table!$B7,Capacities!$M$14:$M$303,Cross_table!F$1)+SUMIFS(Capacities!$H$335:$H$417,Capacities!$J$335:$J$417,Cross_table!$B7,Capacities!$M$335:$M$417,Cross_table!F$1) -> 0 | G7: =SUMIFS(Capacities!$H$14:$H$303,Capacities!$J$14:$J$303,Cross_table!$B7,Capacities!$M$14:$M$303,Cross_table!G$1)+SUMIFS(Capacities!$H$335:$H$417,Capacities!$J$335:$J$417,Cross_table!$B7,Capacities!$M$335:$M$417,Cross_table!G$1) -> 194.05 | H7: =SUMIFS(Capacities!$H$14:$H$303,Capacities!$J$14:$J$303,Cross_table!$B7,Capacities!$M$14:$M$303,Cross_table!H$1)+SUMIFS(Capacities!$H$335:$H$417,Capacities!$J$335:$J$417,Cross_table!$B7,Capacities!$M$335:$M$417,Cross_table!H$1) -> 0 | I7: =SUMIFS(Capacities!$H$14:$H$303,Capacities!$J$14:$J$303,Cross_table!$B7,Capacities!$M$14:$M$303,Cross_table!I$1)+SUMIFS(Capacities!$H$335:$H$417,Capacities!$J$335:$J$417,Cross_table!$B7,Capacities!$M$335:$M$417,Cross_table!I$1) -> 387.85 | J7: =SUMIFS(Capacities!$H$14:$H$303,Capacities!$J$14:$J$303,Cross_table!$B7,Capacities!$M$14:$M$303,Cross_table!J$1)+SUMIFS(Capacities!$H$335:$H$417,Capacities!$J$335:$J$417,Cross_table!$B7,Capacities!$M$335:$M$417,Cross_table!J$1) -> 38.99 | K7: =SUMIFS(Capacities!$H$14:$H$303,Capacities!$J$14:$J$303,Cross_table!$B7,Capacities!$M$14:$M$303,Cross_table!K$1)+SUMIFS(Capacities!$H$335:$H$417,Capacities!$J$335:$J$417,Cross_table!$B7,Capacities!$M$335:$M$417,Cross_table!K$1) -> 0 | ... AP7: =SUMIFS(Capacities!$H$14:$H$303,Capacities!$J$14:$J$303,Cross_table!$B7,Capacities!$M$14:$M$303,Cross_table!AP$1)+SUMIFS(Capacities!$H$335:$H$417,Capacities!$J$335:$J$417,Cross_table!$B7,Capacities!$M$335:$M$417,Cross_table!AP$1) -> 0
B8: CH | C8: =SUMIFS(Capacities!$H$14:$H$287,Capacities!$J$14:$J$287,Cross_table!$B8,Capacities!$M$14:$M$287,Cross_table!C$1)+SUMIFS(Capacities!$H$335:$H$417,Capacities!$J$335:$J$417,Cross_table!$B8,Capacities!$M$335:$M$417,Cross_table!C$1) -> 0 | D8: =SUMIFS(Capacities!$H$14:$H$303,Capacities!$J$14:$J$303,Cross_table!$B8,Capacities!$M$14:$M$303,Cross_table!D$1)+SUMIFS(Capacities!$H$335:$H$417,Capacities!$J$335:$J$417,Cross_table!$B8,Capacities!$M$335:$M$417,Cross_table!D$1) -> 0 | E8: =SUMIFS(Capacities!$H$14:$H$303,Capacities!$J$14:$J$303,Cross_table!$B8,Capacities!$M$14:$M$303,Cross_table!E$1)+SUMIFS(Capacities!$H$335:$H$417,Capacities!$J$335:$J$417,Cross_table!$B8,Capacities!$M$335:$M$417,Cross_table!E$1) -> 0 | F8: =SUMIFS(Capacities!$H$14:$H$303,Capacities!$J$14:$J$303,Cross_table!$B8,Capacities!$M$14:$M$303,Cross_table!F$1)+SUMIFS(Capacities!$H$335:$H$417,Capacities!$J$335:$J$417,Cross_table!$B8,Capacities!$M$335:$M$417,Cross_table!F$1) -> 240 | G8: =SUMIFS(Capacities!$H$14:$H$303,Capacities!$J$14:$J$303,Cross_table!$B8,Capacities!$M$14:$M$303,Cross_table!G$1)+SUMIFS(Capacities!$H$335:$H$417,Capacities!$J$335:$J$417,Cross_table!$B8,Capacities!$M$335:$M$417,Cross_table!G$1) -> 0 | H8: =SUMIFS(Capacities!$H$14:$H$303,Capacities!$J$14:$J$303,Cross_table!$B8,Capacities!$M$14:$M$303,Cross_table!H$1)+SUMIFS(Capacities!$H$335:$H$417,Capacities!$J$335:$J$417,Cross_table!$B8,Capacities!$M$335:$M$417,Cross_table!H$1) -> 640.48 | I8: =SUMIFS(Capacities!$H$14:$H$303,Capacities!$J$14:$J$303,Cross_table!$B8,Capacities!$M$14:$M$303,Cross_table!I$1)+SUMIFS(Capacities!$H$335:$H$417,Capacities!$J$335:$J$417,Cross_table!$B8,Capacities!$M$335:$M$417,Cross_table!I$1) -> 0 | J8: =SUMIFS(Capacities!$H$14:$H$303,Capacities!$J$14:$J$303,Cross_table!$B8,Capacities!$M$14:$M$303,Cross_table!J$1)+SUMIFS(Capacities!$H$335:$H$417,Capacities!$J$335:$J$417,Cross_table!$B8,Capacities!$M$335:$M$417,Cross_table!J$1) -> 0 | K8: =SUMIFS(Capacities!$H$14:$H$303,Capacities!$J$14:$J$303,Cross_table!$B8,Capacities!$M$14:$M$303,Cross_table!K$1)+SUMIFS(Capacities!$H$335:$H$417,Capacities!$J$335:$J$417,Cross_table!$B8,Capacities!$M$335:$M$417,Cross_table!K$1) -> 0 | ... AP8: =SUMIFS(Capacities!$H$14:$H$303,Capacities!$J$14:$J$303,Cross_table!$B8,Capacities!$M$14:$M$303,Cross_table!AP$1)+SUMIFS(Capacities!$H$335:$H$417,Capacities!$J$335:$J$417,Cross_table!$B8,Capacities!$M$335:$M$417,Cross_table!AP$1) -> 0
B9: SI | C9: =SUMIFS(Capacities!$H$14:$H$287,Capacities!$J$14:$J$287,Cross_table!$B9,Capacities!$M$14:$M$287,Cross_table!C$1)+SUMIFS(Capacities!$H$335:$H$417,Capacities!$J$335:$J$417,Cross_table!$B9,Capacities!$M$335:$M$417,Cross_table!C$1) -> 0 | D9: =SUMIFS(Capacities!$H$14:$H$303,Capacities!$J$14:$J$303,Cross_table!$B9,Capacities!$M$14:$M$303,Cross_table!D$1)+SUMIFS(Capacities!$H$335:$H$417,Capacities!$J$335:$J$417,Cross_table!$B9,Capacities!$M$335:$M$417,Cross_table!D$1) -> 0 | E9: =SUMIFS(Capacities!$H$14:$H$303,Capacities!$J$14:$J$303,Cross_table!$B9,Capacities!$M$14:$M$303,Cross_table!E$1)+SUMIFS(Capacities!$H$335:$H$417,Capacities!$J$335:$J$417,Cross_table!$B9,Capacities!$M$335:$M$417,Cross_table!E$1) -> 0 | F9: =SUMIFS(Capacities!$H$14:$H$303,Capacities!$J$14:$J$303,Cross_table!$B9,Capacities!$M$14:$M$303,Cross_table!F$1)+SUMIFS(Capacities!$H$335:$H$417,Capacities!$J$335:$J$417,Cross_table!$B9,Capacities!$M$335:$M$417,Cross_table!F$1) -> 0 | G9: =SUMIFS(Capacities!$H$14:$H$303,Capacities!$J$14:$J$303,Cross_table!$B9,Capacities!$M$14:$M$303,Cross_table!G$1)+SUMIFS(Capacities!$H$335:$H$417,Capacities!$J$335:$J$417,Cross_table!$B9,Capacities!$M$335:$M$417,Cross_table!G$1) -> 0 | H9: =SUMIFS(Capacities!$H$14:$H$303,Capacities!$J$14:$J$303,Cross_table!$B9,Capacities!$M$14:$M$303,Cross_table!H$1)+SUMIFS(Capacities!$H$335:$H$417,Capacities!$J$335:$J$417,Cross_table!$B9,Capacities!$M$335:$M$417,Cross_table!H$1) -> 25.77 | I9: =SUMIFS(Capacities!$H$14:$H$303,Capacities!$J$14:$J$303,Cross_table!$B9,Capacities!$M$14:$M$303,Cross_table!I$1)+SUMIFS(Capacities!$H$335:$H$417,Capacities!$J$335:$J$417,Cross_table!$B9,Capacities!$M$335:$M$417,Cross_table!I$1) -> 0 | J9: =SUMIFS(Capacities!$H$14:$H$303,Capacities!$J$14:$J$303,Cross_table!$B9,Capacities!$M$14:$M$303,Cross_table!J$1)+SUMIFS(Capacities!$H$335:$H$417,Capacities!$J$335:$J$417,Cross_table!$B9,Capacities!$M$335:$M$417,Cross_table!J$1) -> 0 | K9: =SUMIFS(Capacities!$H$14:$H$303,Capacities!$J$14:$J$303,Cross_table!$B9,Capacities!$M$14:$M$303,Cross_table!K$1)+SUMIFS(Capacities!$H$335:$H$417,Capacities!$J$335:$J$417,Cross_table!$B9,Capacities!$M$335:$M$417,Cross_table!K$1) -> 53.7 | ... AP9: =SUMIFS(Capacities!$H$14:$H$303,Capacities!$J$14:$J$303,Cross_table!$B9,Capacities!$M$14:$M$303,Cross_table!AP$1)+SUMIFS(Capacities!$H$335:$H$417,Capacities!$J$335:$J$417,Cross_table!$B9,Capacities!$M$335:$M$417,Cross_table!AP$1) -> 0
B10: HR | C10: =SUMIFS(Capacities!$H$14:$H$287,Capacities!$J$14:$J$287,Cross_table!$B10,Capacities!$M$14:$M$287,Cross_table!C$1)+SUMIFS(Capacities!$H$335:$H$417,Capacities!$J$335:$J$417,Cross_table!$B10,Capacities!$M$335:$M$417,Cross_table!C$1) -> 0 | D10: =SUMIFS(Capacities!$H$14:$H$303,Capacities!$J$14:$J$303,Cross_table!$B10,Capacities!$M$14:$M$303,Cross_table!D$1)+SUMIFS(Capacities!$H$335:$H$417,Capacities!$J$335:$J$417,Cross_table!$B10,Capacities!$M$335:$M$417,Cross_table!D$1) -> 0 | E10: =SUMIFS(Capacities!$H$14:$H$303,Capacities!$J$14:$J$303,Cross_table!$B10,Capacities!$M$14:$M$303,Cross_table!E$1)+SUMIFS(Capacities!$H$335:$H$417,Capacities!$J$335:$J$417,Cross_table!$B10,Capacities!$M$335:$M$417,Cross_table!E$1) -> 0 | F10: =SUMIFS(Capacities!$H$14:$H$303,Capacities!$J$14:$J$303,Cross_table!$B10,Capacities!$M$14:$M$303,Cross_table!F$1)+SUMIFS(Capacities!$H$335:$H$417,Capacities!$J$335:$J$417,Cross_table!$B10,Capacities!$M$335:$M$417,Cross_table!F$1) -> 0 | G10: =SUMIFS(Capacities!$H$14:$H$303,Capacities!$J$14:$J$303,Cross_table!$B10,Capacities!$M$14:$M$303,Cross_table!G$1)+SUMIFS(Capacities!$H$335:$H$417,Capacities!$J$335:$J$417,Cross_table!$B10,Capacities!$M$335:$M$417,Cross_table!G$1) -> 0 | H10: =SUMIFS(Capacities!$H$14:$H$303,Capacities!$J$14:$J$303,Cross_table!$B10,Capacities!$M$14:$M$303,Cross_table!H$1)+SUMIFS(Capacities!$H$335:$H$417,Capacities!$J$335:$J$417,Cross_table!$B10,Capacities!$M$335:$M$417,Cross_table!H$1) -> 0 | I10: =SUMIFS(Capacities!$H$14:$H$303,Capacities!$J$14:$J$303,Cross_table!$B10,Capacities!$M$14:$M$303,Cross_table!I$1)+SUMIFS(Capacities!$H$335:$H$417,Capacities!$J$335:$J$417,Cross_table!$B10,Capacities!$M$335:$M$417,Cross_table!I$1) -> 0 | J10: =SUMIFS(Capacities!$H$14:$H$303,Capacities!$J$14:$J$303,Cross_table!$B10,Capacities!$M$14:$M$303,Cross_table!J$1)+SUMIFS(Capacities!$H$335:$H$417,Capacities!$J$335:$J$417,Cross_table!$B10,Capacities!$M$335:$M$417,Cross_table!J$1) -> 7.7 | K10: =SUMIFS(Capacities!$H$14:$H$303,Capacities!$J$14:$J$303,Cross_table!$B10,Capacities!$M$14:$M$303,Cross_table!K$1)+SUMIFS(Capacities!$H$335:$H$417,Capacities!$J$335:$J$417,Cross_table!$B10,Capacities!$M$335:$M$417,Cross_table!K$1) -> 0 | ... AP10: =SUMIFS(Capacities!$H$14:$H$303,Capacities!$J$14:$J$303,Cross_table!$B10,Capacities!$M$14:$M$303,Cross_table!AP$1)+SUMIFS(Capacities!$H$335:$H$417,Capacities!$J$335:$J$417,Cross_table!$B10,Capacities!$M$335:$M$417,Cross_table!AP$1) -> 0
B11: FR | C11: =SUMIFS(Capacities!$H$14:$H$287,Capacities!$J$14:$J$287,Cross_table!$B11,Capacities!$M$14:$M$287,Cross_table!C$1)+SUMIFS(Capacities!$H$335:$H$417,Capacities!$J$335:$J$417,Cross_table!$B11,Capacities!$M$335:$M$417,Cross_table!C$1) -> 0 | D11: =SUMIFS(Capacities!$H$14:$H$303,Capacities!$J$14:$J$303,Cross_table!$B11,Capacities!$M$14:$M$303,Cross_table!D$1)+SUMIFS(Capacities!$H$335:$H$417,Capacities!$J$335:$J$417,Cross_table!$B11,Capacities!$M$335:$M$417,Cross_table!D$1) -> 270 | E11: =SUMIFS(Capacities!$H$14:$H$303,Capacities!$J$14:$J$303,Cross_table!$B11,Capacities!$M$14:$M$303,Cross_table!E$1)+SUMIFS(Capacities!$H$335:$H$417,Capacities!$J$335:$J$417,Cross_table!$B11,Capacities!$M$335:$M$417,Cross_table!E$1) -> 0 | F11: =SUMIFS(Capacities!$H$14:$H$303,Capacities!$J$14:$J$303,Cross_table!$B11,Capacities!$M$14:$M$303,Cross_table!F$1)+SUMIFS(Capacities!$H$335:$H$417,Capacities!$J$335:$J$417,Cross_table!$B11,Capacities!$M$335:$M$417,Cross_table!F$1) -> 100 | G11: =SUMIFS(Capacities!$H$14:$H$303,Capacities!$J$14:$J$303,Cross_table!$B11,Capacities!$M$14:$M$303,Cross_table!G$1)+SUMIFS(Capacities!$H$335:$H$417,Capacities!$J$335:$J$417,Cross_table!$B11,Capacities!$M$335:$M$417,Cross_table!G$1) -> 0 | H11: =SUMIFS(Capacities!$H$14:$H$303,Capacities!$J$14:$J$303,Cross_table!$B11,Capacities!$M$14:$M$303,Cross_table!H$1)+SUMIFS(Capacities!$H$335:$H$417,Capacities!$J$335:$J$417,Cross_table!$B11,Capacities!$M$335:$M$417,Cross_table!H$1) -> 0 | I11: =SUMIFS(Capacities!$H$14:$H$303,Capacities!$J$14:$J$303,Cross_table!$B11,Capacities!$M$14:$M$303,Cross_table!I$1)+SUMIFS(Capacities!$H$335:$H$417,Capacities!$J$335:$J$417,Cross_table!$B11,Capacities!$M$335:$M$417,Cross_table!I$1) -> 259.02 | J11: =SUMIFS(Capacities!$H$14:$H$303,Capacities!$J$14:$J$303,Cross_table!$B11,Capacities!$M$14:$M$303,Cross_table!J$1)+SUMIFS(Capacities!$H$335:$H$417,Capacities!$J$335:$J$417,Cross_table!$B11,Capacities!$M$335:$M$417,Cross_table!J$1) -> 0 | K11: =SUMIFS(Capacities!$H$14:$H$303,Capacities!$J$14:$J$303,Cross_table!$B11,Capacities!$M$14:$M$303,Cross_table!K$1)+SUMIFS(Capacities!$H$335:$H$417,Capacities!$J$335:$J$417,Cross_table!$B11,Capacities!$M$335:$M$417,Cross_table!K$1) -> 0 | ... AP11: =SUMIFS(Capacities!$H$14:$H$303,Capacities!$J$14:$J$303,Cross_table!$B11,Capacities!$M$14:$M$303,Cross_table!AP$1)+SUMIFS(Capacities!$H$335:$H$417,Capacities!$J$335:$J$417,Cross_table!$B11,Capacities!$M$335:$M$417,Cross_table!AP$1) -> 0
B12: DK | C12: =SUMIFS(Capacities!$H$14:$H$287,Capacities!$J$14:$J$287,Cross_table!$B12,Capacities!$M$14:$M$287,Cross_table!C$1)+SUMIFS(Capacities!$H$335:$H$417,Capacities!$J$335:$J$417,Cross_table!$B12,Capacities!$M$335:$M$417,Cross_table!C$1) -> 0 | D12: =SUMIFS(Capacities!$H$14:$H$303,Capacities!$J$14:$J$303,Cross_table!$B12,Capacities!$M$14:$M$303,Cross_table!D$1)+SUMIFS(Capacities!$H$335:$H$417,Capacities!$J$335:$J$417,Cross_table!$B12,Capacities!$M$335:$M$417,Cross_table!D$1) -> 0 | E12: =SUMIFS(Capacities!$H$14:$H$303,Capacities!$J$14:$J$303,Cross_table!$B12,Capacities!$M$14:$M$303,Cross_table!E$1)+SUMIFS(Capacities!$H$335:$H$417,Capacities!$J$335:$J$417,Cross_table!$B12,Capacities!$M$335:$M$417,Cross_table!E$1) -> 0 | F12: =SUMIFS(Capacities!$H$14:$H$303,Capacities!$J$14:$J$303,Cross_table!$B12,Capacities!$M$14:$M$303,Cross_table!F$1)+SUMIFS(Capacities!$H$335:$H$417,Capacities!$J$335:$J$417,Cross_table!$B12,Capacities!$M$335:$M$417,Cross_table!F$1) -> 15.7 | G12: =SUMIFS(Capacities!$H$14:$H$303,Capacities!$J$14:$J$303,Cross_table!$B12,Capacities!$M$14:$M$303,Cross_table!G$1)+SUMIFS(Capacities!$H$335:$H$417,Capacities!$J$335:$J$417,Cross_table!$B12,Capacities!$M$335:$M$417,Cross_table!G$1) -> 0 | H12: =SUMIFS(Capacities!$H$14:$H$303,Capacities!$J$14:$J$303,Cross_table!$B12,Capacities!$M$14:$M$303,Cross_table!H$1)+SUMIFS(Capacities!$H$335:$H$417,Capacities!$J$335:$J$417,Cross_table!$B12,Capacities!$M$335:$M$417,Cross_table!H$1) -> 0 | I12: =SUMIFS(Capacities!$H$14:$H$303,Capacities!$J$14:$J$303,Cross_table!$B12,Capacities!$M$14:$M$303,Cross_table!I$1)+SUMIFS(Capacities!$H$335:$H$417,Capacities!$J$335:$J$417,Cross_table!$B12,Capacities!$M$335:$M$417,Cross_table!I$1) -> 0 | J12: =SUMIFS(Capacities!$H$14:$H$303,Capacities!$J$14:$J$303,Cross_table!$B12,Capacities!$M$14:$M$303,Cross_table!J$1)+SUMIFS(Capacities!$H$335:$H$417,Capacities!$J$335:$J$417,Cross_table!$B12,Capacities!$M$335:$M$417,Cross_table!J$1) -> 0 | K12: =SUMIFS(Capacities!$H$14:$H$303,Capacities!$J$14:$J$303,Cross_table!$B12,Capacities!$M$14:$M$303,Cross_table!K$1)+SUMIFS(Capacities!$H$335:$H$417,Capacities!$J$335:$J$417,Cross_table!$B12,Capacities!$M$335:$M$417,Cross_table!K$1) -> 0 | ... AP12: =SUMIFS(Capacities!$H$14:$H$303,Capacities!$J$14:$J$303,Cross_table!$B12,Capacities!$M$14:$M$303,Cross_table!AP$1)+SUMIFS(Capacities!$H$335:$H$417,Capacities!$J$335:$J$417,Cross_table!$B12,Capacities!$M$335:$M$417,Cross_table!AP$1) -> 0
B13: PL | C13: =SUMIFS(Capacities!$H$14:$H$287,Capacities!$J$14:$J$287,Cross_table!$B13,Capacities!$M$14:$M$287,Cross_table!C$1)+SUMIFS(Capacities!$H$335:$H$417,Capacities!$J$335:$J$417,Cross_table!$B13,Capacities!$M$335:$M$417,Cross_table!C$1) -> 0 | D13: =SUMIFS(Capacities!$H$14:$H$303,Capacities!$J$14:$J$303,Cross_table!$B13,Capacities!$M$14:$M$303,Cross_table!D$1)+SUMIFS(Capacities!$H$335:$H$417,Capacities!$J$335:$J$417,Cross_table!$B13,Capacities!$M$335:$M$417,Cross_table!D$1) -> 0 | E13: =SUMIFS(Capacities!$H$14:$H$303,Capacities!$J$14:$J$303,Cross_table!$B13,Capacities!$M$14:$M$303,Cross_table!E$1)+SUMIFS(Capacities!$H$335:$H$417,Capacities!$J$335:$J$417,Cross_table!$B13,Capacities!$M$335:$M$417,Cross_table!E$1) -> 0 | F13: =SUMIFS(Capacities!$H$14:$H$303,Capacities!$J$14:$J$303,Cross_table!$B13,Capacities!$M$14:$M$303,Cross_table!F$1)+SUMIFS(Capacities!$H$335:$H$417,Capacities!$J$335:$J$417,Cross_table!$B13,Capacities!$M$335:$M$417,Cross_table!F$1) -> 0.09 | G13: =SUMIFS(Capacities!$H$14:$H$303,Capacities!$J$14:$J$303,Cross_table!$B13,Capacities!$M$14:$M$303,Cross_table!G$1)+SUMIFS(Capacities!$H$335:$H$417,Capacities!$J$335:$J$417,Cross_table!$B13,Capacities!$M$335:$M$417,Cross_table!G$1) -> 0 | H13: =SUMIFS(Capacities!$H$14:$H$303,Capacities!$J$14:$J$303,Cross_table!$B13,Capacities!$M$14:$M$303,Cross_table!H$1)+SUMIFS(Capacities!$H$335:$H$417,Capacities!$J$335:$J$417,Cross_table!$B13,Capacities!$M$335:$M$417,Cross_table!H$1) -> 0 | I13: =SUMIFS(Capacities!$H$14:$H$303,Capacities!$J$14:$J$303,Cross_table!$B13,Capacities!$M$14:$M$303,Cross_table!I$1)+SUMIFS(Capacities!$H$335:$H$417,Capacities!$J$335:$J$417,Cross_table!$B13,Capacities!$M$335:$M$417,Cross_table!I$1) -> 0 | J13: =SUMIFS(Capacities!$H$14:$H$303,Capacities!$J$14:$J$303,Cross_table!$B13,Capacities!$M$14:$M$303,Cross_table!J$1)+SUMIFS(Capacities!$H$335:$H$417,Capacities!$J$335:$J$417,Cross_table!$B13,Capacities!$M$335:$M$417,Cross_table!J$1) -> 0 | K13: =SUMIFS(Capacities!$H$14:$H$303,Capacities!$J$14:$J$303,Cross_table!$B13,Capacities!$M$14:$M$303,Cross_table!K$1)+SUMIFS(Capacities!$H$335:$H$417,Capacities!$J$335:$J$417,Cross_table!$B13,Capacities!$M$335:$M$417,Cross_table!K$1) -> 0 | ... AP13: =SUMIFS(Capacities!$H$14:$H$303,Capacities!$J$14:$J$303,Cross_table!$B13,Capacities!$M$14:$M$303,Cross_table!AP$1)+SUMIFS(Capacities!$H$335:$H$417,Capacities!$J$335:$J$417,Cross_table!$B13,Capacities!$M$335:$M$417,Cross_table!AP$1) -> 0
... B41: FI | C41: =SUMIFS(Capacities!$H$14:$H$287,Capacities!$J$14:$J$287,Cross_table!$B41,Capacities!$M$14:$M$287,Cross_table!C$1)+SUMIFS(Capacities!$H$335:$H$417,Capacities!$J$335:$J$417,Cross_table!$B41,Capacities!$M$335:$M$417,Cross_table!C$1) -> 0 | D41: =SUMIFS(Capacities!$H$14:$H$303,Capacities!$J$14:$J$303,Cross_table!$B41,Capacities!$M$14:$M$303,Cross_table!D$1)+SUMIFS(Capacities!$H$335:$H$417,Capacities!$J$335:$J$417,Cross_table!$B41,Capacities!$M$335:$M$417,Cross_table!D$1) -> 0 | E41: =SUMIFS(Capacities!$H$14:$H$303,Capacities!$J$14:$J$303,Cross_table!$B41,Capacities!$M$14:$M$303,Cross_table!E$1)+SUMIFS(Capacities!$H$335:$H$417,Capacities!$J$335:$J$417,Cross_table!$B41,Capacities!$M$335:$M$417,Cross_table!E$1) -> 0 | F41: =SUMIFS(Capacities!$H$14:$H$303,Capacities!$J$14:$J$303,Cross_table!$B41,Capacities!$M$14:$M$303,Cross_table!F$1)+SUMIFS(Capacities!$H$335:$H$417,Capacities!$J$335:$J$417,Cross_table!$B41,Capacities!$M$335:$M$417,Cross_table!F$1) -> 0 | G41: =SUMIFS(Capacities!$H$14:$H$303,Capacities!$J$14:$J$303,Cross_table!$B41,Capacities!$M$14:$M$303,Cross_table!G$1)+SUMIFS(Capacities!$H$335:$H$417,Capacities!$J$335:$J$417,Cross_table!$B41,Capacities!$M$335:$M$417,Cross_table!G$1) -> 0 | H41: =SUMIFS(Capacities!$H$14:$H$303,Capacities!$J$14:$J$303,Cross_table!$B41,Capacities!$M$14:$M$303,Cross_table!H$1)+SUMIFS(Capacities!$H$335:$H$417,Capacities!$J$335:$J$417,Cross_table!$B41,Capacities!$M$335:$M$417,Cross_table!H$1) -> 0 | I41: =SUMIFS(Capacities!$H$14:$H$303,Capacities!$J$14:$J$303,Cross_table!$B41,Capacities!$M$14:$M$303,Cross_table!I$1)+SUMIFS(Capacities!$H$335:$H$417,Capacities!$J$335:$J$417,Cross_table!$B41,Capacities!$M$335:$M$417,Cross_table!I$1) -> 0 | J41: =SUMIFS(Capacities!$H$14:$H$303,Capacities!$J$14:$J$303,Cross_table!$B41,Capacities!$M$14:$M$303,Cross_table!J$1)+SUMIFS(Capacities!$H$335:$H$417,Capacities!$J$335:$J$417,Cross_table!$B41,Capacities!$M$335:$M$417,Cross_table!J$1) -> 0 | K41: =SUMIFS(Capacities!$H$14:$H$303,Capacities!$J$14:$J$303,Cross_table!$B41,Capacities!$M$14:$M$303,Cross_table!K$1)+SUMIFS(Capacities!$H$335:$H$417,Capacities!$J$335:$J$417,Cross_table!$B41,Capacities!$M$335:$M$417,Cross_table!K$1) -> 0 | ... AP41: =SUMIFS(Capacities!$H$14:$H$303,Capacities!$J$14:$J$303,Cross_table!$B41,Capacities!$M$14:$M$303,Cross_table!AP$1)+SUMIFS(Capacities!$H$335:$H$417,Capacities!$J$335:$J$417,Cross_table!$B41,Capacities!$M$335:$M$417,Cross_table!AP$1) -> 0

Sheet Connections_cross_table
A1: From | B1: To | C1: Value
A2: UK | B2: UK | C2: 1455
A3: UK | B3: BE | C3: 651.7
A4: UK | B4: NL | C4: 168
A5: UK | B5: DE | C5: 0
A6: UK | B6: AT | C6: 0
A7: UK | B7: IT | C7: 0
A8: UK | B8: CH | C8: 0
A9: UK | B9: SI | C9: 0
A10: UK | B10: HR | C10: 0
A11: UK | B11: FR | C11: 0
A12: UK | B12: DK | C12: 0
A13: UK | B13: PL | C13: 0
... A1601: FI | B1601: FI | C1601: 0
